Workbook

Sheet 읽어보기
B2: 실전 모의고사 제1회 — 설비 보전
B3: 컴활 2급 실기와 같은 시트 이름 · 같은 배점입니다. 시간 40분, 70점 이상이면 합격.
B4: 순서
B5: ① [문제지] 시트에서 문제를 읽고 → 각 작업 시트(기본작업-1 …)에서 풉니다.
B6: ② 계산작업의 노란 칸에는 0 이 들어 있습니다. 0 을 지우고 첫 칸에 수식 → 끝까지 끌어내리기.
B7: ③ 다 풀었으면 [채점표] — 자동 칸은 저절로 점수가 나오고, '스스로' 칸은 [확인 방법] 을 보고 O / X 를 고릅니다.
B8: ④ 틀린 것은 [정답·해설] 에서 확인합니다.
B9: 매크로를 만들면 '다른 이름으로 저장' 에서 파일 형식을 Excel 매크로 사용 통합 문서(*.xlsm) 로 바꿔야 매크로가 남습니다.
B10: 값이 0 으로만 보이면 Ctrl + Alt + F9. 자동 채점 칸이 안 바뀌어 보일 때도 같습니다.

Sheet 문제지
A1: 컴퓨터활용능력 2급 실기 · 실전 모의고사 제1회 (설비 보전)
A2: 시험 시간 40분 · 100점 만점 · 70점 이상 합격. 시작 시각을 적어 두고 시작하세요 → 시작 [ : ] 끝 [ : ] 다 풀면 [채점표] 시트에서 점수를 확인합니다.
A4: 기본작업-1 · 5점
C5: [기본작업-1] 시트에 다음 자료를 [A4] 부터 그대로 입력하시오. (날짜는 2026-03-02 처럼)
C6: 설비코드 | 설비명 | 설치일 | 점검주기(일) | 담당자 | 비고
C7: PR-01 | 유압프레스 | 2019-03-04 | 30 | 김도윤 | 금형 교체
C8: WD-02 | 스폿용접기 | 2021-07-12 | 14 | 이서연 | (비움)
C9: CN-03 | CNC선반 | 2018-11-20 | 60 | 박지훈 | 주축 점검
C10: RB-04 | 조립로봇 | 2023-02-01 | 90 | 최하은 | (비움)
C11: CV-05 | 벨트컨베이어 | 2020-05-15 | 7 | 정민재 | 벨트 장력
C12: AC-06 | 공기압축기 | 2017-09-08 | 30 | 한수아 | 드레인
C13: MC-07 | 머시닝센터 | 2022-10-03 | 45 | 오지성 | (비움)
A14: ↑ (비움) 칸은 아무것도 입력하지 않습니다.
A16: 기본작업-2 · 10점
B17: 1) | C17: [A1:G1] 셀을 병합하여 가운데 맞춤, 글꼴 '굴림' · 16pt · 굵게
B18: 2) | C18: [A3:G3] 영역은 가운데 맞춤, 채우기 색 '노랑'
B19: 3) | C19: [D4:D12] 영역에 사용자 지정 서식으로 천 단위 쉼표와 "원" 표시 (예: 4,200원)
B20: 4) | C20: [G4:G12] 영역의 이름을 '재고금액' 으로 정의
B21: 5) | C21: [A3:G12] 영역에 '모든 테두리'
A22: 기본작업-3 · 5점
C23: [A3:G12] 영역에서 분류가 '베어링' 이면서 재고가 50 이하인 행만 고급 필터로 추출하시오. · 조건은 [A15] 부터 입력 · 결과는 [A19] 부터 표시
A24: 계산작업 · 40점 (각 8점)
B25: 1. | C25: [표1]에서 가동률[E3:E10]이 90% 이상이면 "우수", 80% 이상이면 "보통", 그 외는 "점검" 을 판정[F3:F10]에 표시하시오. → [F3:F10] (IF 함수 사용)
B26: 2. | C26: [표2]에서 부서[A15:A22]별 수리비[C15:C22]의 합계를 수리비 합계[F15:F17]에 구하시오. (부서 이름은 E열) → [F15:F17] (SUMIF 함수 사용)
B27: 3. | C27: [표3]에서 설비코드[A27:A32]의 앞 두 글자와 코드표[E27:F30]를 이용하여 공정[C27:C32]에 공정명을 표시하시오. → [C27:C32] (VLOOKUP, LEFT 함수 사용)
B28: 4. | C28: [표4]에서 점검일[B37:B42]의 요일을 "월"~"일" 로 요일[C37:C42]에 표시하시오. (WEEKDAY 함수는 월요일이 1 이 되는 유형 2) → [C37:C42] (CHOOSE, WEEKDAY 함수 사용)
B29: 5. | C29: [표5]에서 불량률[D47:D52]이 낮을수록 1위가 되도록 순위를 구하여 "1위" 형태로 순위[E47:E52]에 표시하시오. → [E47:E52] (RANK.EQ 함수, & 연산자 사용)
A30: 분석작업-1 · 10점
C31: [분석작업-1] 시트의 표에서 공정별 수리비의 합계를 계산한 뒤, 같은 공정별 작업시간의 평균을 계산하시오. · 정렬은 '공정' 기준 오름차순 · 합계와 평균은 위에서 아래 순서로 표시 (평균은 새로운 값으로 대치하지 않음)
A32: 분석작업-2 · 10점
C33: [분석작업-2] 시트에서 '목표값 찾기' 로 이익[B7]이 1,000,000 이 되려면 생산량[B4]이 얼마여야 하는지 구하시오.
A34: 기타작업-1 · 10점
C35: [기타작업-1] 시트에서 다음 두 매크로를 만들고 단추에 연결하시오. (저장은 .xlsm 형식)
B36: 1) | C36: [F4:F10] 에 가동률(가동시간÷계획시간)을 구하는 '가동률' 매크로를 만들고, [H3] 위치의 단추(텍스트 '가동률')에 연결
B37: 2) | C37: [A3:F3] 영역에 채우기 색 '주황' 을 적용하는 '서식' 매크로를 만들고, [H6] 위치의 단추(텍스트 '서식')에 연결
A38: 기타작업-2 · 10점 (각 2점)
C39: [기타작업-2] 시트의 차트(묶은 세로 막대 · 생산량만)를 다음과 같이 고치시오.
B40: 1) | C40: 차트에 불량수 계열을 추가하시오
B41: 2) | C41: 불량수 계열을 '표식이 있는 꺾은선형' 으로 바꾸고 보조 축에 표시하시오
B42: 3) | C42: 차트 제목을 '하반기 생산 실적' 으로 입력하시오
...

Sheet 기본작업-1
A1: 설비 점검 대장
A3: 설비코드 | B3: 설비명 | C3: 설치일 | D3: 점검주기(일) | E3: 담당자 | F3: 비고

Sheet 기본작업-2
A1: 부품 재고 현황
A3: 부품코드 | B3: 부품명 | C3: 분류 | D3: 단가 | E3: 재고 | F3: 안전재고 | G3: 재고금액
A4: B-101 | B4: 볼베어링 6205 | C4: 베어링 | D4: 4200 | E4: 120 | F4: 50 | G4: =D4*E4
A5: B-102 | B5: 볼베어링 6305 | C5: 베어링 | D5: 5600 | E5: 35 | F5: 40 | G5: =D5*E5
A6: S-201 | B6: 오일실 35x52 | C6: 실링 | D6: 1800 | E6: 210 | F6: 100 | G6: =D6*E6
A7: V-301 | B7: V벨트 A-42 | C7: 벨트 | D7: 9500 | E7: 18 | F7: 20 | G7: =D7*E7
A8: B-103 | B8: 니들베어링 HK20 | C8: 베어링 | D8: 3100 | E8: 48 | F8: 30 | G8: =D8*E8
A9: S-202 | B9: O링 P-40 | C9: 실링 | D9: 350 | E9: 900 | F9: 300 | G9: =D9*E9
A10: V-302 | B10: 타이밍벨트 450L | C10: 벨트 | D10: 21000 | E10: 12 | F10: 10 | G10: =D10*E10
A11: B-104 | B11: 테이퍼베어링 30205 | C11: 베어링 | D11: 8800 | E11: 26 | F11: 20 | G11: =D11*E11
A12: F-401 | B12: 필터 카트리지 | C12: 필터 | D12: 15000 | E12: 40 | F12: 15 | G12: =D12*E12

Sheet 기본작업-3
A1: 고급 필터
A3: 부품코드 | B3: 부품명 | C3: 분류 | D3: 단가 | E3: 재고 | F3: 안전재고 | G3: 재고금액
A4: B-101 | B4: 볼베어링 6205 | C4: 베어링 | D4: 4200 | E4: 120 | F4: 50 | G4: 504000
A5: B-102 | B5: 볼베어링 6305 | C5: 베어링 | D5: 5600 | E5: 35 | F5: 40 | G5: 196000
A6: S-201 | B6: 오일실 35x52 | C6: 실링 | D6: 1800 | E6: 210 | F6: 100 | G6: 378000
A7: V-301 | B7: V벨트 A-42 | C7: 벨트 | D7: 9500 | E7: 18 | F7: 20 | G7: 171000
A8: B-103 | B8: 니들베어링 HK20 | C8: 베어링 | D8: 3100 | E8: 48 | F8: 30 | G8: 148800
A9: S-202 | B9: O링 P-40 | C9: 실링 | D9: 350 | E9: 900 | F9: 300 | G9: 315000
A10: V-302 | B10: 타이밍벨트 450L | C10: 벨트 | D10: 21000 | E10: 12 | F10: 10 | G10: 252000
A11: B-104 | B11: 테이퍼베어링 30205 | C11: 베어링 | D11: 8800 | E11: 26 | F11: 20 | G11: 228800
A12: F-401 | B12: 필터 카트리지 | C12: 필터 | D12: 15000 | E12: 40 | F12: 15 | G12: 600000

Sheet 계산작업
A1: [표1] 설비 가동 현황
A2: 설비코드 | B2: 설비명 | C2: 가동시간 | D2: 계획시간 | E2: 가동률 | F2: 판정
A3: PR-01 | B3: 유압프레스 | C3: 186 | D3: 200 | E3: 0.93 | F3: 0 | AA3: =IF(E3>=90%,"우수",IF(E3>=80%,"보통","점검")) | AB3: =AND(_xlfn.ISFORMULA(F3),IFERROR(ROUND(F3,4)=ROUND(AA3,4),EXACT(F3,AA3)))
A4: PR-02 | B4: 단동프레스 | C4: 180 | D4: 200 | E4: 0.9 | F4: 0 | AA4: =IF(E4>=90%,"우수",IF(E4>=80%,"보통","점검")) | AB4: =AND(_xlfn.ISFORMULA(F4),IFERROR(ROUND(F4,4)=ROUND(AA4,4),EXACT(F4,AA4)))
A5: WD-01 | B5: 스폿용접기 | C5: 170 | D5: 200 | E5: 0.85 | F5: 0 | AA5: =IF(E5>=90%,"우수",IF(E5>=80%,"보통","점검")) | AB5: =AND(_xlfn.ISFORMULA(F5),IFERROR(ROUND(F5,4)=ROUND(AA5,4),EXACT(F5,AA5)))
A6: WD-02 | B6: 아크용접기 | C6: 158 | D6: 200 | E6: 0.79 | F6: 0 | AA6: =IF(E6>=90%,"우수",IF(E6>=80%,"보통","점검")) | AB6: =AND(_xlfn.ISFORMULA(F6),IFERROR(ROUND(F6,4)=ROUND(AA6,4),EXACT(F6,AA6)))
A7: CN-01 | B7: CNC선반 | C7: 160 | D7: 200 | E7: 0.8 | F7: 0 | AA7: =IF(E7>=90%,"우수",IF(E7>=80%,"보통","점검")) | AB7: =AND(_xlfn.ISFORMULA(F7),IFERROR(ROUND(F7,4)=ROUND(AA7,4),EXACT(F7,AA7)))
A8: CN-02 | B8: 머시닝센터 | C8: 194 | D8: 200 | E8: 0.97 | F8: 0 | AA8: =IF(E8>=90%,"우수",IF(E8>=80%,"보통","점검")) | AB8: =AND(_xlfn.ISFORMULA(F8),IFERROR(ROUND(F8,4)=ROUND(AA8,4),EXACT(F8,AA8)))
A9: RB-01 | B9: 조립로봇 | C9: 176 | D9: 200 | E9: 0.88 | F9: 0 | AA9: =IF(E9>=90%,"우수",IF(E9>=80%,"보통","점검")) | AB9: =AND(_xlfn.ISFORMULA(F9),IFERROR(ROUND(F9,4)=ROUND(AA9,4),EXACT(F9,AA9)))
A10: CV-01 | B10: 컨베이어 | C10: 124 | D10: 200 | E10: 0.62 | F10: 0 | AA10: =IF(E10>=90%,"우수",IF(E10>=80%,"보통","점검")) | AB10: =AND(_xlfn.ISFORMULA(F10),IFERROR(ROUND(F10,4)=ROUND(AA10,4),EXACT(F10,AA10)))
A13: [표2] 부서별 수리비
A14: 부서 | B14: 설비 | C14: 수리비 | E14: 부서 | F14: 수리비 합계
A15: 생산2팀 | B15: 용접기 | C15: 85000 | E15: 생산1팀 | F15: 0 | AA15: =SUMIF($A$15:$A$22,E15,$C$15:$C$22) | AB15: =AND(_xlfn.ISFORMULA(F15),IFERROR(ROUND(F15,4)=ROUND(AA15,4),EXACT(F15,AA15)))
A16: 보전팀 | B16: 로봇 | C16: 60000 | E16: 생산2팀 | F16: 0 | AA16: =SUMIF($A$15:$A$22,E16,$C$15:$C$22) | AB16: =AND(_xlfn.ISFORMULA(F16),IFERROR(ROUND(F16,4)=ROUND(AA16,4),EXACT(F16,AA16)))
A17: 생산1팀 | B17: 프레스 | C17: 120000 | E17: 보전팀 | F17: 0 | AA17: =SUMIF($A$15:$A$22,E17,$C$15:$C$22) | AB17: =AND(_xlfn.ISFORMULA(F17),IFERROR(ROUND(F17,4)=ROUND(AA17,4),EXACT(F17,AA17)))
A18: 생산1팀 | B18: CNC | C18: 240000
A19: 생산2팀 | B19: 컨베이어 | C19: 45000
A20: 보전팀 | B20: 공조기 | C20: 150000
A21: 생산1팀 | B21: 용접기 | C21: 30000
A22: 생산2팀 | B22: 프레스 | C22: 90000
A25: [표3] 설비 공정 구분
A26: 설비코드 | B26: 설비명 | C26: 공정 | E26: 코드 | F26: 공정명
A27: PR-11 | B27: 프레스3 | C27: 0 | E27: PR | F27: 프레스공정 | AA27: =VLOOKUP(LEFT(A27,2),$E$27:$F$30,2,FALSE) | AB27: =AND(_xlfn.ISFORMULA(C27),IFERROR(ROUND(C27,4)=ROUND(AA27,4),EXACT(C27,AA27)))
A28: WD-07 | B28: 용접기7 | C28: 0 | E28: WD | F28: 용접공정 | AA28: =VLOOKUP(LEFT(A28,2),$E$27:$F$30,2,FALSE) | AB28: =AND(_xlfn.ISFORMULA(C28),IFERROR(ROUND(C28,4)=ROUND(AA28,4),EXACT(C28,AA28)))
A29: CN-03 | B29: CNC3 | C29: 0 | E29: CN | F29: 가공공정 | AA29: =VLOOKUP(LEFT(A29,2),$E$27:$F$30,2,FALSE) | AB29: =AND(_xlfn.ISFORMULA(C29),IFERROR(ROUND(C29,4)=ROUND(AA29,4),EXACT(C29,AA29)))
A30: RB-02 | B30: 로봇2 | C30: 0 | E30: RB | F30: 조립공정 | AA30: =VLOOKUP(LEFT(A30,2),$E$27:$F$30,2,FALSE) | AB30: =AND(_xlfn.ISFORMULA(C30),IFERROR(ROUND(C30,4)=ROUND(AA30,4),EXACT(C30,AA30)))
A31: PR-05 | B31: 프레스5 | C31: 0 | AA31: =VLOOKUP(LEFT(A31,2),$E$27:$F$30,2,FALSE) | AB31: =AND(_xlfn.ISFORMULA(C31),IFERROR(ROUND(C31,4)=ROUND(AA31,4),EXACT(C31,AA31)))
A32: CN-09 | B32: CNC9 | C32: 0 | AA32: =VLOOKUP(LEFT(A32,2),$E$27:$F$30,2,FALSE) | AB32: =AND(_xlfn.ISFORMULA(C32),IFERROR(ROUND(C32,4)=ROUND(AA32,4),EXACT(C32,AA32)))
A35: [표4] 점검 일정
A36: 설비명 | B36: 점검일 | C36: 요일
A37: 프레스1 | B37: 46300 | C37: 0 | AA37: =CHOOSE(WEEKDAY(B37,2),"월","화","수","목","금","토","일") | AB37: =AND(_xlfn.ISFORMULA(C37),IFERROR(ROUND(C37,4)=ROUND(AA37,4),EXACT(C37,AA37)))
A38: 용접기2 | B38: 46305 | C38: 0 | AA38: =CHOOSE(WEEKDAY(B38,2),"월","화","수","목","금","토","일") | AB38: =AND(_xlfn.ISFORMULA(C38),IFERROR(ROUND(C38,4)=ROUND(AA38,4),EXACT(C38,AA38)))
A39: CNC3 | B39: 46309 | C39: 0 | AA39: =CHOOSE(WEEKDAY(B39,2),"월","화","수","목","금","토","일") | AB39: =AND(_xlfn.ISFORMULA(C39),IFERROR(ROUND(C39,4)=ROUND(AA39,4),EXACT(C39,AA39)))
A40: 로봇4 | B40: 46313 | C40: 0 | AA40: =CHOOSE(WEEKDAY(B40,2),"월","화","수","목","금","토","일") | AB40: =AND(_xlfn.ISFORMULA(C40),IFERROR(ROUND(C40,4)=ROUND(AA40,4),EXACT(C40,AA40)))
A41: 컨베이어5 | B41: 46317 | C41: 0 | AA41: =CHOOSE(WEEKDAY(B41,2),"월","화","수","목","금","토","일") | AB41: =AND(_xlfn.ISFORMULA(C41),IFERROR(ROUND(C41,4)=ROUND(AA41,4),EXACT(C41,AA41)))
A42: 압축기6 | B42: 46325 | C42: 0 | AA42: =CHOOSE(WEEKDAY(B42,2),"월","화","수","목","금","토","일") | AB42: =AND(_xlfn.ISFORMULA(C42),IFERROR(ROUND(C42,4)=ROUND(AA42,4),EXACT(C42,AA42)))
A45: [표5] 라인별 불량률
A46: 라인 | B46: 생산량 | C46: 불량수 | D46: 불량률 | E46: 순위
A47: A라인 | B47: 2500 | C47: 30 | D47: 0.012 | E47: 0 | AA47: =_xlfn.RANK.EQ(D47,$D$47:$D$52,1)&"위" | AB47: =AND(_xlfn.ISFORMULA(E47),IFERROR(ROUND(E47,4)=ROUND(AA47,4),EXACT(E47,AA47)))
A48: B라인 | B48: 2000 | C48: 50 | D48: 0.025 | E48: 0 | AA48: =_xlfn.RANK.EQ(D48,$D$47:$D$52,1)&"위" | AB48: =AND(_xlfn.ISFORMULA(E48),IFERROR(ROUND(E48,4)=ROUND(AA48,4),EXACT(E48,AA48)))
...

Sheet 분석작업-1
A1: 분석작업-1
A3: 점검일 | B3: 공정 | C3: 설비 | D3: 점검구분 | E3: 작업시간 | F3: 수리비
A4: 46266 | B4: 프레스 | C4: PR-01 | D4: 정기 | E4: 2 | F4: 120000
A5: 46267 | B5: 용접 | C5: WD-02 | D5: 고장 | E5: 3.5 | F5: 85000
A6: 46268 | B6: 가공 | C6: CN-03 | D6: 정기 | E6: 1.5 | F6: 60000
A7: 46269 | B7: 프레스 | C7: PR-02 | D7: 고장 | E7: 4 | F7: 210000
A8: 46272 | B8: 가공 | C8: CN-04 | D8: 고장 | E8: 5 | F8: 240000
A9: 46273 | B9: 용접 | C9: WD-01 | D9: 정기 | E9: 1 | F9: 30000
A10: 46274 | B10: 프레스 | C10: PR-03 | D10: 정기 | E10: 1.5 | F10: 45000
A11: 46275 | B11: 가공 | C11: MC-07 | D11: 정기 | E11: 2.5 | F11: 90000
A12: 46276 | B12: 용접 | C12: WD-03 | D12: 고장 | E12: 2 | F12: 70000
A13: 46279 | B13: 프레스 | C13: PR-01 | D13: 고장 | E13: 3 | F13: 150000

Sheet 분석작업-2
A1: 원가 모형
A3: 판매단가 | B3: 12000
A4: 생산량 | B4: 500
A5: 개당 변동비 | B5: 7000
A6: 고정비 | B6: 3000000
A7: 이익 | B7: =B3*B4-(B5*B4+B6)

Sheet 기타작업-1
A1: 매크로
A3: 설비코드 | B3: 설비명 | C3: 라인 | D3: 가동시간 | E3: 계획시간 | F3: 가동률
A4: PR-01 | B4: 유압프레스 | C4: A | D4: 186 | E4: 200
A5: WD-02 | B5: 스폿용접기 | C5: A | D5: 170 | E5: 200
A6: CN-03 | B6: CNC선반 | C6: B | D6: 160 | E6: 200
A7: RB-04 | B7: 조립로봇 | C7: B | D7: 176 | E7: 200
A8: CV-05 | B8: 컨베이어 | C8: C | D8: 124 | E8: 200
A9: AC-06 | B9: 공기압축기 | C9: C | D9: 190 | E9: 200
A10: MC-07 | B10: 머시닝센터 | C10: B | D10: 194 | E10: 200

Sheet 기타작업-2
A1: 하반기 생산 실적
A3: 월 | B3: 생산량 | C3: 불량수
A4: 7월 | B4: 5200 | C4: 104
A5: 8월 | B5: 4800 | C5: 120
A6: 9월 | B6: 5600 | C6: 84
A7: 10월 | B7: 6100 | C7: 92
A8: 11월 | B8: 5900 | C8: 71
A9: 12월 | B9: 6400 | C9: 64

Sheet 채점표
A1: 채점표 — 제1회 (자동 칸은 저절로, '스스로' 칸은 O / X 를 고르세요)
A3: 작업 | B3: 문항 | C3: 배점 | D3: 방식 | E3: 점수 | F3: 확인 방법 | G3: O / X
A4: 기본작업-1 | B4: 자료 입력 (42칸 모두 정확히) | C4: 5 | D4: 자동 | E4: =IF(SUMPRODUCT(--EXACT('기본작업-1'!$A$4:$F$10&"",'채점표'!$AA$4:$AF$10&""))=42,5,0) | F4: 자동 — 한 칸이라도 다르면 0점 (실제 시험과 같음) | AA4: PR-01 | AB4: 유압프레스 | AC4: 43528 | AD4: 30 | AE4: 김도윤 | AF4: 금형 교체
A5: 기본작업-2 | B5: 1) [A1:G1] 셀을 병합하여 가운데 맞춤, 글꼴 '굴림' · 16pt · 굵게 | C5: 2 | D5: 스스로 | E5: =IF(G5="O",C5,0) | F5: 제목 칸을 누르면 A1:G1 이 하나로 합쳐져 있고, 글꼴 상자에 굴림·16 | AA5: WD-02 | AB5: 스폿용접기 | AC5: 44389 | AD5: 14 | AE5: 이서연
A6: 기본작업-2 | B6: 2) [A3:G3] 영역은 가운데 맞춤, 채우기 색 '노랑' | C6: 2 | D6: 스스로 | E6: =IF(G6="O",C6,0) | F6: 머리글 줄이 노랗고 글자가 가운데 | AA6: CN-03 | AB6: CNC선반 | AC6: 43424 | AD6: 60 | AE6: 박지훈 | AF6: 주축 점검
A7: 기본작업-2 | B7: 3) [D4:D12] 영역에 사용자 지정 서식으로 천 단위 쉼표와 "원" 표시 (예: 4,200원) | C7: 2 | D7: 스스로 | E7: =IF(G7="O",C7,0) | F7: D4 를 누르고 Ctrl+1 → 사용자 지정에 #,##0"원" | AA7: RB-04 | AB7: 조립로봇 | AC7: 44958 | AD7: 90 | AE7: 최하은
A8: 기본작업-2 | B8: 4) [G4:G12] 영역의 이름을 '재고금액' 으로 정의 | C8: 2 | D8: 자동 | E8: =IF(ISREF(재고금액),2,0) | F8: 자동 채점 — 이름 상자에서 '재고금액' 을 고르면 G4:G12 가 선택됨 | AA8: CV-05 | AB8: 벨트컨베이어 | AC8: 43966 | AD8: 7 | AE8: 정민재 | AF8: 벨트 장력
A9: 기본작업-2 | B9: 5) [A3:G12] 영역에 '모든 테두리' | C9: 2 | D9: 스스로 | E9: =IF(G9="O",C9,0) | F9: 표 전체에 가는 선이 칸마다 있음 | AA9: AC-06 | AB9: 공기압축기 | AC9: 42986 | AD9: 30 | AE9: 한수아 | AF9: 드레인
A10: 기본작업-3 | B10: 고급 필터 (조건 · 결과 3행) | C10: 5 | D10: 자동 | E10: =IF(AND(SUMPRODUCT(--('기본작업-3'!$A$19:$G$22&""='채점표'!$AA$12:$AG$15&""))=28,COUNTA('기본작업-3'!$A$23:$G$23)=0),5,0) | F10: 자동 — 결과가 A19 부터 정확히 3행 | AA10: MC-07 | AB10: 머시닝센터 | AC10: 44837 | AD10: 45 | AE10: 오지성
A11: 계산작업 | B11: 1. [표1] 설비 가동 현황 [F3:F10] | C11: 8 | D11: 자동 | E11: =IF(COUNTIF('계산작업'!$AB$3:$AB$10,TRUE)=8,8,0) | F11: 자동 — 8칸 모두 맞아야 8점
A12: 계산작업 | B12: 2. [표2] 부서별 수리비 [F15:F17] | C12: 8 | D12: 자동 | E12: =IF(COUNTIF('계산작업'!$AB$15:$AB$17,TRUE)=3,8,0) | F12: 자동 — 3칸 모두 맞아야 8점 | AA12: 부품코드 | AB12: 부품명 | AC12: 분류 | AD12: 단가 | AE12: 재고 | AF12: 안전재고 | AG12: 재고금액
A13: 계산작업 | B13: 3. [표3] 설비 공정 구분 [C27:C32] | C13: 8 | D13: 자동 | E13: =IF(COUNTIF('계산작업'!$AB$27:$AB$32,TRUE)=6,8,0) | F13: 자동 — 6칸 모두 맞아야 8점 | AA13: B-102 | AB13: 볼베어링 6305 | AC13: 베어링 | AD13: 5600 | AE13: 35 | AF13: 40 | AG13: 196000
A14: 계산작업 | B14: 4. [표4] 점검 일정 [C37:C42] | C14: 8 | D14: 자동 | E14: =IF(COUNTIF('계산작업'!$AB$37:$AB$42,TRUE)=6,8,0) | F14: 자동 — 6칸 모두 맞아야 8점 | AA14: B-103 | AB14: 니들베어링 HK20 | AC14: 베어링 | AD14: 3100 | AE14: 48 | AF14: 30 | AG14: 148800
A15: 계산작업 | B15: 5. [표5] 라인별 불량률 [E47:E52] | C15: 8 | D15: 자동 | E15: =IF(COUNTIF('계산작업'!$AB$47:$AB$52,TRUE)=6,8,0) | F15: 자동 — 6칸 모두 맞아야 8점 | AA15: B-104 | AB15: 테이퍼베어링 30205 | AC15: 베어링 | AD15: 8800 | AE15: 26 | AF15: 20 | AG15: 228800
A16: 분석작업-1 | B16: 부분합 1) 공정 '가공 → 용접 → 프레스' 순서로 정렬되어 있다 | C16: 4 | D16: 스스로 | E16: =IF(G16="O",C16,0) | F16: 가공이 맨 위
A17: 분석작업-1 | B17: 부분합 2) 공정별 [수리비] 합계 줄: 가공 390,000 · 용접 185,000 · 프레스 525,000 | C17: 3 | D17: 스스로 | E17: =IF(G17="O",C17,0) | F17: 각 공정 끝의 '요약' 줄
A18: 분석작업-1 | B18: 부분합 3) 공정별 [작업시간] 평균 줄: 가공 3 · 용접 2.166… · 프레스 2.625 | C18: 3 | D18: 스스로 | E18: =IF(G18="O",C18,0) | F18: 합계 줄 아래에 평균 줄이 따로
A19: 분석작업-2 | B19: 목표값 찾기 — 생산량 B4 = 800 | C19: 10 | D19: 자동 | E19: =IF(AND(_xlfn.ISFORMULA('분석작업-2'!B7),ROUND('분석작업-2'!B4,0)=800),10,0) | F19: 자동
A20: 기타작업-1 | B20: 매크로 1) [F4:F10] 에 가동률(가동시간÷계획시간)을 구하는 '가동률' 매크로를 만들고, [H3] 위치의 단추(텍스트 '가동률')에 연결 | C20: 5 | D20: 스스로 | E20: =IF(G20="O",C20,0) | F20: F4 에 =D4/E4 가 들어가고 단추를 누르면 다시 채워짐
A21: 기타작업-1 | B21: 매크로 2) [A3:F3] 영역에 채우기 색 '주황' 을 적용하는 '서식' 매크로를 만들고, [H6] 위치의 단추(텍스트 '서식')에 연결 | C21: 5 | D21: 스스로 | E21: =IF(G21="O",C21,0) | F21: 단추를 누르면 머리글이 주황
A22: 기타작업-2 | B22: 차트 1) 차트에 불량수 계열을 추가하시오 | C22: 2 | D22: 스스로 | E22: =IF(G22="O",C22,0) | F22: 범례에 '불량수' 가 보임
A23: 기타작업-2 | B23: 차트 2) 불량수 계열을 '표식이 있는 꺾은선형' 으로 바꾸고 보조 축에 표시하시오 | C23: 2 | D23: 스스로 | E23: =IF(G23="O",C23,0) | F23: 오른쪽에 두 번째 세로축
A24: 기타작업-2 | B24: 차트 3) 차트 제목을 '하반기 생산 실적' 으로 입력하시오 | C24: 2 | D24: 스스로 | E24: =IF(G24="O",C24,0) | F24: 위쪽 제목
A25: 기타작업-2 | B25: 차트 4) 생산량 계열에 데이터 레이블 '값' 을 표시하시오 | C25: 2 | D25: 스스로 | E25: =IF(G25="O",C25,0) | F25: 막대 위에 숫자
A26: 기타작업-2 | B26: 차트 5) 범례를 '아래쪽' 에 표시하시오 | C26: 2 | D26: 스스로 | E26: =IF(G26="O",C26,0) | F26: 범례가 차트 아래
B28: 합계 (100점 만점 · 70점 이상 합격) | E28: =SUM(E4:E26) | F28: =IF(E28>=70,"🎉 합격","불합격 — 틀린 작업의 [정답·해설]을 보세요")
A30: '스스로' 문항은 [확인 방법] 을 보고 실제로 그렇게 되어 있으면 O. 한 군데라도 다르면 X (실제 시험은 부분 점수 없음).

Sheet 정답·해설
A1: 정답·해설 — 제1회 (먼저 스스로 끝까지 풀고 보세요)
A3: 작업 | B3: 무엇을 | C3: 어떻게 · 정답
A4: 기본작업-1 | B4: 자료 입력 | C4: 문제지의 자료를 A4 부터 한 칸씩. 날짜는 2026-03-02 처럼 - 로 입력하면 날짜로 들어갑니다.
A5: 기본작업-2 | B5: 1) [A1:G1] 셀을 병합하여 가운데 맞춤, 글꼴 '굴림' · 16pt · 굵게 | C5: 제목 칸을 누르면 A1:G1 이 하나로 합쳐져 있고, 글꼴 상자에 굴림·16
A6: 기본작업-2 | B6: 2) [A3:G3] 영역은 가운데 맞춤, 채우기 색 '노랑' | C6: 머리글 줄이 노랗고 글자가 가운데
A7: 기본작업-2 | B7: 3) [D4:D12] 영역에 사용자 지정 서식으로 천 단위 쉼표와 "원" 표시 (예: 4,200원) | C7: D4 를 누르고 Ctrl+1 → 사용자 지정에 #,##0"원"
A8: 기본작업-2 | B8: 4) [G4:G12] 영역의 이름을 '재고금액' 으로 정의 | C8: 자동 채점 — 이름 상자에서 '재고금액' 을 고르면 G4:G12 가 선택됨
A9: 기본작업-2 | B9: 5) [A3:G12] 영역에 '모든 테두리' | C9: 표 전체에 가는 선이 칸마다 있음
A10: 기본작업-3 | B10: 고급 필터 | C10: 조건: A15 '분류' · B15 '재고' / A16 '베어링' · B16 '<=50' (같은 줄 = 그리고) [데이터] → [고급] → '다른 장소에 복사' · 목록 범위 A3:G12 · 조건 범위 · 복사 위치 A19
A11: 계산작업 | B11: 1. [표1] 설비 가동 현황 → [F3:F10] | C11: =IF(E3>=90%,"우수",IF(E3>=80%,"보통","점검")) (첫 칸에 넣고 끝까지 끌어내리기)
A12: 계산작업 | B12: 2. [표2] 부서별 수리비 → [F15:F17] | C12: =SUMIF($A$15:$A$22,E15,$C$15:$C$22) (첫 칸에 넣고 끝까지 끌어내리기)
A13: 계산작업 | B13: 3. [표3] 설비 공정 구분 → [C27:C32] | C13: =VLOOKUP(LEFT(A27,2),$E$27:$F$30,2,FALSE) (첫 칸에 넣고 끝까지 끌어내리기)
A14: 계산작업 | B14: 4. [표4] 점검 일정 → [C37:C42] | C14: =CHOOSE(WEEKDAY(B37,2),"월","화","수","목","금","토","일") (첫 칸에 넣고 끝까지 끌어내리기)
... A23: 기타작업-2 | B23: 5) 범례를 '아래쪽' 에 표시하시오 | C23: 범례가 차트 아래
