Workbook

Sheet 읽어보기
B2: 실전 모의고사 제3회 — 자재 창고
B3: 컴활 2급 실기와 같은 시트 이름 · 같은 배점입니다. 시간 40분, 70점 이상이면 합격.
B4: 순서
B5: ① [문제지] 시트에서 문제를 읽고 → 각 작업 시트(기본작업-1 …)에서 풉니다.
B6: ② 계산작업의 노란 칸에는 0 이 들어 있습니다. 0 을 지우고 첫 칸에 수식 → 끝까지 끌어내리기.
B7: ③ 다 풀었으면 [채점표] — 자동 칸은 저절로 점수가 나오고, '스스로' 칸은 [확인 방법] 을 보고 O / X 를 고릅니다.
B8: ④ 틀린 것은 [정답·해설] 에서 확인합니다.
B9: 매크로를 만들면 '다른 이름으로 저장' 에서 파일 형식을 Excel 매크로 사용 통합 문서(*.xlsm) 로 바꿔야 매크로가 남습니다.
B10: 값이 0 으로만 보이면 Ctrl + Alt + F9. 자동 채점 칸이 안 바뀌어 보일 때도 같습니다.

Sheet 문제지
A1: 컴퓨터활용능력 2급 실기 · 실전 모의고사 제3회 (자재 창고)
A2: 시험 시간 40분 · 100점 만점 · 70점 이상 합격. 시작 시각을 적어 두고 시작하세요 → 시작 [ : ] 끝 [ : ] 다 풀면 [채점표] 시트에서 점수를 확인합니다.
A4: 기본작업-1 · 5점
C5: [기본작업-1] 시트에 다음 자료를 [A4] 부터 그대로 입력하시오. (날짜는 2026-03-02 처럼)
C6: 입고일 | 자재코드 | 자재명 | 창고 | 수량 | 단가
C7: 2026-09-01 | MT-101 | SS400 평철 | 1창고 | 120 | 3400
C8: 2026-09-01 | EL-205 | 근접센서 | 2창고 | 40 | 18500
C9: 2026-09-02 | PN-310 | 공압실린더 | 2창고 | 16 | 42000
C10: 2026-09-03 | MT-102 | SM45C 환봉 | 1창고 | 80 | 5200
C11: 2026-09-04 | EL-206 | 릴레이 24V | 3창고 | 150 | 2100
C12: 2026-09-07 | BL-401 | 육각볼트 M10 | 3창고 | 900 | 120
C13: 2026-09-08 | PN-311 | 솔레노이드밸브 | 2창고 | 24 | 35000
A14: ↑ (비움) 칸은 아무것도 입력하지 않습니다.
A16: 기본작업-2 · 10점
B17: 1) | C17: [A1:G1] 셀을 병합하여 가운데 맞춤, 글꼴 '궁서체' · 18pt · 굵게
B18: 2) | C18: [A3:G3] 영역은 가운데 맞춤, 글꼴 색 '흰색', 채우기 색 '진한 파랑'
B19: 3) | C19: [E4:E10] 영역에 사용자 지정 서식으로 숫자 뒤에 "EA" 표시 (예: 30EA, 0 이면 0EA)
B20: 4) | C20: [B4:B10] 영역의 이름을 '자재코드' 로 정의
B21: 5) | C21: [A3:G10] 영역에 '모든 테두리', [A10:G10] 아래쪽은 '굵은 아래쪽 테두리'
A22: 기본작업-3 · 5점
C23: [A3:G12] 영역에서 창고가 '2창고' 이거나 금액이 500,000 이상인 행만 고급 필터로 추출하시오. · 조건은 [A15] 부터 입력 · 결과는 [A19] 부터 표시
A24: 계산작업 · 40점 (각 8점)
B25: 1. | C25: [표1]에서 재고[C3:C10]가 안전재고[D3:D10] 미만이면 "발주", 안전재고의 1.5배 미만이면 "주의", 그 외는 "정상" 을 상태[E3:E10]에 표시하시오. → [E3:E10] (IF 함수 사용)
B26: 2. | C26: [표2]에서 자재코드[B15:B20]로 단가표[F15:G18]에서 단가를 찾아 수량[C15:C20]을 곱한 금액[D15:D20]을 구하시오. (INDEX 와 MATCH 사용) → [D15:D20] (INDEX, MATCH 함수 사용)
B27: 3. | C27: [표3]에서 분류[B25:B34]별 품목 수가 전체 품목 수에서 차지하는 비율을 비율[E25:E27]에 구하시오. (분류 이름은 D열, 전체는 COUNTA 로) → [E25:E27] (COUNTIF, COUNTA 함수 사용)
B28: 4. | C28: [표4]에서 기준일(E열 첫 칸)의 연도에서 도입일[B39:B44]의 연도를 빼고 뒤에 "년" 을 붙여 사용 연수[C39:C44]에 표시하시오. (예: 14년) → [C39:C44] (YEAR 함수, & 연산자 사용)
B29: 5. | C29: [표5]에서 창고가 "2창고" 이면서 수량이 20 이상인 자재의 수량 합계를 오른쪽 조건표(E·F열)를 이용하여 구하시오. → [G49] (DSUM 함수 사용)
A30: 분석작업-1 · 10점
C31: [분석작업-1] 시트에서 할인율[B4]에 따른 이익[B8]의 변화를 시나리오로 만드시오. · 셀 이름: B4 '할인율', B8 '이익' · 시나리오 '할인확대' 할인율 15% / '할인축소' 할인율 5% · 시나리오 요약 보고서는 '분석작업-1' 시트 바로 앞에 만든다
A32: 분석작업-2 · 10점
C33: [분석작업-2] 시트의 [A3:F15] 표를 창고의 오름차순으로, 창고가 같으면 수량의 내림차순으로 정렬하시오.
A34: 기타작업-1 · 10점
C35: [기타작업-1] 시트에서 다음 두 매크로를 만들고 단추에 연결하시오. (저장은 .xlsm 형식)
B36: 1) | C36: [F4:F10] 에 금액(수량×단가)을 구하는 '금액' 매크로 — [H3] 위치 단추(텍스트 '금액')에 연결
B37: 2) | C37: [F4:F10] 에 쉼표 스타일(,)을 적용하는 '쉼표' 매크로 — [H6] 위치 단추(텍스트 '쉼표')에 연결
A38: 기타작업-2 · 10점 (각 2점)
C39: [기타작업-2] 시트의 차트(묶은 세로 막대 · 입고·출고·재고)를 다음과 같이 고치시오.
B40: 1) | C40: '3창고' 데이터를 차트에서 제외하시오
B41: 2) | C41: '재고' 계열을 삭제하시오
B42: 3) | C42: 차트 제목 '창고별 입출고' · 글꼴 크기 14 · 굵게
...

Sheet 기본작업-1
A1: 자재 입고 대장
A3: 입고일 | B3: 자재코드 | C3: 자재명 | D3: 창고 | E3: 수량 | F3: 단가

Sheet 기본작업-2
A1: 자재 출고 현황
A3: 출고일 | B3: 자재코드 | C3: 자재명 | D3: 창고 | E3: 수량 | F3: 단가 | G3: 금액
A4: 46275 | B4: MT-101 | C4: SS400 평철 | D4: 1창고 | E4: 30 | F4: 3400 | G4: =E4*F4
A5: 46275 | B5: EL-205 | C5: 근접센서 | D5: 2창고 | E5: 8 | F5: 18500 | G5: =E5*F5
A6: 46276 | B6: BL-401 | C6: 육각볼트 M10 | D6: 3창고 | E6: 200 | F6: 120 | G6: =E6*F6
A7: 46277 | B7: PN-310 | C7: 공압실린더 | D7: 2창고 | E7: 4 | F7: 42000 | G7: =E7*F7
A8: 46279 | B8: MT-102 | C8: SM45C 환봉 | D8: 1창고 | E8: 25 | F8: 5200 | G8: =E8*F8
A9: 46280 | B9: EL-206 | C9: 릴레이 24V | D9: 3창고 | E9: 60 | F9: 2100 | G9: =E9*F9
A10: 46281 | B10: PN-311 | C10: 솔레노이드밸브 | D10: 2창고 | E10: 6 | F10: 35000 | G10: =E10*F10

Sheet 기본작업-3
A1: 고급 필터
A3: 출고일 | B3: 자재코드 | C3: 자재명 | D3: 창고 | E3: 수량 | F3: 단가 | G3: 금액
A4: 46275 | B4: MT-101 | C4: SS400 평철 | D4: 1창고 | E4: 30 | F4: 3400 | G4: 102000
A5: 46275 | B5: EL-205 | C5: 근접센서 | D5: 2창고 | E5: 8 | F5: 18500 | G5: 148000
A6: 46276 | B6: BL-401 | C6: 육각볼트 M10 | D6: 3창고 | E6: 200 | F6: 120 | G6: 24000
A7: 46277 | B7: PN-310 | C7: 공압실린더 | D7: 2창고 | E7: 4 | F7: 42000 | G7: 168000
A8: 46279 | B8: MT-102 | C8: SM45C 환봉 | D8: 1창고 | E8: 120 | F8: 5200 | G8: 624000
A9: 46280 | B9: EL-206 | C9: 릴레이 24V | D9: 3창고 | E9: 60 | F9: 2100 | G9: 126000
A10: 46281 | B10: PN-311 | C10: 솔레노이드밸브 | D10: 2창고 | E10: 6 | F10: 35000 | G10: 210000
A11: 46282 | B11: MT-103 | C11: 알루미늄 판재 | D11: 1창고 | E11: 45 | F11: 9800 | G11: 441000
A12: 46283 | B12: EL-207 | C12: 서보모터 | D12: 3창고 | E12: 3 | F12: 185000 | G12: 555000

Sheet 계산작업
A1: [표1] 재고 상태
A2: 자재코드 | B2: 자재명 | C2: 재고 | D2: 안전재고 | E2: 상태
A3: MT-101 | B3: SS400 평철 | C3: 90 | D3: 60 | E3: 0 | AA3: =IF(C3<D3,"발주",IF(C3<D3*1.5,"주의","정상")) | AB3: =AND(_xlfn.ISFORMULA(E3),IFERROR(ROUND(E3,4)=ROUND(AA3,4),EXACT(E3,AA3)))
A4: EL-205 | B4: 근접센서 | C4: 30 | D4: 20 | E4: 0 | AA4: =IF(C4<D4,"발주",IF(C4<D4*1.5,"주의","정상")) | AB4: =AND(_xlfn.ISFORMULA(E4),IFERROR(ROUND(E4,4)=ROUND(AA4,4),EXACT(E4,AA4)))
A5: PN-310 | B5: 공압실린더 | C5: 12 | D5: 10 | E5: 0 | AA5: =IF(C5<D5,"발주",IF(C5<D5*1.5,"주의","정상")) | AB5: =AND(_xlfn.ISFORMULA(E5),IFERROR(ROUND(E5,4)=ROUND(AA5,4),EXACT(E5,AA5)))
A6: MT-102 | B6: SM45C 환봉 | C6: 55 | D6: 60 | E6: 0 | AA6: =IF(C6<D6,"발주",IF(C6<D6*1.5,"주의","정상")) | AB6: =AND(_xlfn.ISFORMULA(E6),IFERROR(ROUND(E6,4)=ROUND(AA6,4),EXACT(E6,AA6)))
A7: EL-206 | B7: 릴레이 24V | C7: 150 | D7: 100 | E7: 0 | AA7: =IF(C7<D7,"발주",IF(C7<D7*1.5,"주의","정상")) | AB7: =AND(_xlfn.ISFORMULA(E7),IFERROR(ROUND(E7,4)=ROUND(AA7,4),EXACT(E7,AA7)))
A8: BL-401 | B8: 육각볼트 | C8: 700 | D8: 500 | E8: 0 | AA8: =IF(C8<D8,"발주",IF(C8<D8*1.5,"주의","정상")) | AB8: =AND(_xlfn.ISFORMULA(E8),IFERROR(ROUND(E8,4)=ROUND(AA8,4),EXACT(E8,AA8)))
A9: PN-311 | B9: 솔레노이드밸브 | C9: 18 | D9: 12 | E9: 0 | AA9: =IF(C9<D9,"발주",IF(C9<D9*1.5,"주의","정상")) | AB9: =AND(_xlfn.ISFORMULA(E9),IFERROR(ROUND(E9,4)=ROUND(AA9,4),EXACT(E9,AA9)))
A10: MT-103 | B10: 알루미늄 판재 | C10: 9 | D10: 10 | E10: 0 | AA10: =IF(C10<D10,"발주",IF(C10<D10*1.5,"주의","정상")) | AB10: =AND(_xlfn.ISFORMULA(E10),IFERROR(ROUND(E10,4)=ROUND(AA10,4),EXACT(E10,AA10)))
A13: [표2] 출고 금액
A14: 출고번호 | B14: 자재코드 | C14: 수량 | D14: 금액 | F14: 자재코드 | G14: 단가
A15: OUT-01 | B15: EL-205 | C15: 8 | D15: 0 | F15: MT-101 | G15: 3400 | AA15: =INDEX($G$15:$G$18,MATCH(B15,$F$15:$F$18,0))*C15 | AB15: =AND(_xlfn.ISFORMULA(D15),IFERROR(ROUND(D15,4)=ROUND(AA15,4),EXACT(D15,AA15)))
A16: OUT-02 | B16: MT-101 | C16: 30 | D16: 0 | F16: EL-205 | G16: 18500 | AA16: =INDEX($G$15:$G$18,MATCH(B16,$F$15:$F$18,0))*C16 | AB16: =AND(_xlfn.ISFORMULA(D16),IFERROR(ROUND(D16,4)=ROUND(AA16,4),EXACT(D16,AA16)))
A17: OUT-03 | B17: PN-310 | C17: 4 | D17: 0 | F17: PN-310 | G17: 42000 | AA17: =INDEX($G$15:$G$18,MATCH(B17,$F$15:$F$18,0))*C17 | AB17: =AND(_xlfn.ISFORMULA(D17),IFERROR(ROUND(D17,4)=ROUND(AA17,4),EXACT(D17,AA17)))
A18: OUT-04 | B18: EL-205 | C18: 2 | D18: 0 | F18: BL-401 | G18: 120 | AA18: =INDEX($G$15:$G$18,MATCH(B18,$F$15:$F$18,0))*C18 | AB18: =AND(_xlfn.ISFORMULA(D18),IFERROR(ROUND(D18,4)=ROUND(AA18,4),EXACT(D18,AA18)))
A19: OUT-05 | B19: BL-401 | C19: 200 | D19: 0 | AA19: =INDEX($G$15:$G$18,MATCH(B19,$F$15:$F$18,0))*C19 | AB19: =AND(_xlfn.ISFORMULA(D19),IFERROR(ROUND(D19,4)=ROUND(AA19,4),EXACT(D19,AA19)))
A20: OUT-06 | B20: MT-101 | C20: 15 | D20: 0 | AA20: =INDEX($G$15:$G$18,MATCH(B20,$F$15:$F$18,0))*C20 | AB20: =AND(_xlfn.ISFORMULA(D20),IFERROR(ROUND(D20,4)=ROUND(AA20,4),EXACT(D20,AA20)))
A23: [표3] 분류별 품목 비율
A24: 자재명 | B24: 분류 | D24: 분류 | E24: 비율
A25: 평철 | B25: 철강 | D25: 철강 | E25: 0 | AA25: =COUNTIF($B$25:$B$34,D25)/COUNTA($B$25:$B$34) | AB25: =AND(_xlfn.ISFORMULA(E25),IFERROR(ROUND(E25,4)=ROUND(AA25,4),EXACT(E25,AA25)))
A26: 근접센서 | B26: 전기 | D26: 전기 | E26: 0 | AA26: =COUNTIF($B$25:$B$34,D26)/COUNTA($B$25:$B$34) | AB26: =AND(_xlfn.ISFORMULA(E26),IFERROR(ROUND(E26,4)=ROUND(AA26,4),EXACT(E26,AA26)))
A27: 실린더 | B27: 공압 | D27: 공압 | E27: 0 | AA27: =COUNTIF($B$25:$B$34,D27)/COUNTA($B$25:$B$34) | AB27: =AND(_xlfn.ISFORMULA(E27),IFERROR(ROUND(E27,4)=ROUND(AA27,4),EXACT(E27,AA27)))
A28: 환봉 | B28: 철강
A29: 릴레이 | B29: 전기
A30: 밸브 | B30: 공압
A31: 판재 | B31: 철강
A32: 서보모터 | B32: 전기
A33: 볼트 | B33: 철강
A34: 케이블 | B34: 전기
A37: [표4] 설비 사용 연수
A38: 설비 | B38: 도입일 | C38: 사용 연수 | E38: 기준일
A39: 프레스 | B39: 40973 | C39: 0 | E39: 46296 | AA39: =YEAR($E$39)-YEAR(B39)&"년" | AB39: =AND(_xlfn.ISFORMULA(C39),IFERROR(ROUND(C39,4)=ROUND(AA39,4),EXACT(C39,AA39)))
A40: 용접기 | B40: 43789 | C40: 0 | AA40: =YEAR($E$39)-YEAR(B40)&"년" | AB40: =AND(_xlfn.ISFORMULA(C40),IFERROR(ROUND(C40,4)=ROUND(AA40,4),EXACT(C40,AA40)))
A41: CNC | B41: 44200 | C41: 0 | AA41: =YEAR($E$39)-YEAR(B41)&"년" | AB41: =AND(_xlfn.ISFORMULA(C41),IFERROR(ROUND(C41,4)=ROUND(AA41,4),EXACT(C41,AA41)))
A42: 로봇 | B42: 45474 | C42: 0 | AA42: =YEAR($E$39)-YEAR(B42)&"년" | AB42: =AND(_xlfn.ISFORMULA(C42),IFERROR(ROUND(C42,4)=ROUND(AA42,4),EXACT(C42,AA42)))
A43: 컨베이어 | B43: 39598 | C43: 0 | AA43: =YEAR($E$39)-YEAR(B43)&"년" | AB43: =AND(_xlfn.ISFORMULA(C43),IFERROR(ROUND(C43,4)=ROUND(AA43,4),EXACT(C43,AA43)))
A44: 압축기 | B44: 46069 | C44: 0 | AA44: =YEAR($E$39)-YEAR(B44)&"년" | AB44: =AND(_xlfn.ISFORMULA(C44),IFERROR(ROUND(C44,4)=ROUND(AA44,4),EXACT(C44,AA44)))
A47: [표5] 2창고 대량 입고 합계
A48: 자재코드 | B48: 창고 | C48: 수량 | E48: 창고 | F48: 수량 | G48: 합계
...

Sheet 분석작업-1
A1: 할인율에 따른 이익
A3: 정가 | B3: 20000
A4: 할인율 | B4: 0.1
A5: 판매량 | B5: 1200
A6: 개당 원가 | B6: 12000
A7: 고정비 | B7: 3000000
A8: 이익 | B8: =B3*(1-B4)*B5-(B6*B5+B7)

Sheet 분석작업-2
A1: 자재 재고
A3: 자재코드 | B3: 자재명 | C3: 창고 | D3: 수량 | E3: 단가 | F3: 입고일
A4: MT-101 | B4: SS400 평철 | C4: 1창고 | D4: 120 | E4: 3400 | F4: 46266
A5: EL-205 | B5: 근접센서 | C5: 2창고 | D5: 40 | E5: 18500 | F5: 46266
A6: PN-310 | B6: 공압실린더 | C6: 2창고 | D6: 16 | E6: 42000 | F6: 46267
A7: MT-102 | B7: SM45C 환봉 | C7: 1창고 | D7: 80 | E7: 5200 | F7: 46268
A8: EL-206 | B8: 릴레이 24V | C8: 3창고 | D8: 150 | E8: 2100 | F8: 46269
A9: BL-401 | B9: 육각볼트 | C9: 3창고 | D9: 900 | E9: 120 | F9: 46272
A10: PN-311 | B10: 솔레노이드밸브 | C10: 2창고 | D10: 24 | E10: 35000 | F10: 46273
A11: MT-103 | B11: 알루미늄 판재 | C11: 1창고 | D11: 45 | E11: 9800 | F11: 46274
A12: EL-207 | B12: 서보모터 | C12: 3창고 | D12: 3 | E12: 185000 | F12: 46274
A13: BL-402 | B13: 와셔 M10 | C13: 3창고 | D13: 1200 | E13: 30 | F13: 46275
A14: PN-312 | B14: 에어호스 | C14: 2창고 | D14: 60 | E14: 4500 | F14: 46276
A15: MT-104 | B15: 황동봉 | C15: 1창고 | D15: 18 | E15: 15000 | F15: 46277

Sheet 기타작업-1
A1: 매크로
A3: 자재코드 | B3: 자재명 | C3: 창고 | D3: 수량 | E3: 단가 | F3: 금액
A4: MT-101 | B4: SS400 평철 | C4: 1창고 | D4: 30 | E4: 3400
A5: EL-205 | B5: 근접센서 | C5: 2창고 | D5: 8 | E5: 18500
A6: BL-401 | B6: 육각볼트 | C6: 3창고 | D6: 200 | E6: 120
A7: PN-310 | B7: 공압실린더 | C7: 2창고 | D7: 4 | E7: 42000
A8: MT-102 | B8: SM45C 환봉 | C8: 1창고 | D8: 25 | E8: 5200
A9: EL-206 | B9: 릴레이 24V | C9: 3창고 | D9: 60 | E9: 2100
A10: PN-311 | B10: 솔레노이드밸브 | C10: 2창고 | D10: 6 | E10: 35000

Sheet 기타작업-2
A1: 창고별 입출고
A3: 창고 | B3: 입고 | C3: 출고 | D3: 재고
A4: 1창고 | B4: 265 | C4: 175 | D4: 90
A5: 2창고 | B5: 140 | C5: 58 | D5: 82
A6: 3창고 | B6: 1050 | C6: 260 | D6: 790
A7: 4창고 | B7: 320 | C7: 290 | D7: 30

Sheet 채점표
A1: 채점표 — 제3회 (자동 칸은 저절로, '스스로' 칸은 O / X 를 고르세요)
A3: 작업 | B3: 문항 | C3: 배점 | D3: 방식 | E3: 점수 | F3: 확인 방법 | G3: O / X
A4: 기본작업-1 | B4: 자료 입력 (42칸 모두 정확히) | C4: 5 | D4: 자동 | E4: =IF(SUMPRODUCT(--EXACT('기본작업-1'!$A$4:$F$10&"",'채점표'!$AA$4:$AF$10&""))=42,5,0) | F4: 자동 — 한 칸이라도 다르면 0점 (실제 시험과 같음) | AA4: 46266 | AB4: MT-101 | AC4: SS400 평철 | AD4: 1창고 | AE4: 120 | AF4: 3400
A5: 기본작업-2 | B5: 1) [A1:G1] 셀을 병합하여 가운데 맞춤, 글꼴 '궁서체' · 18pt · 굵게 | C5: 2 | D5: 스스로 | E5: =IF(G5="O",C5,0) | F5: 제목 칸이 합쳐지고 궁서체 | AA5: 46266 | AB5: EL-205 | AC5: 근접센서 | AD5: 2창고 | AE5: 40 | AF5: 18500
A6: 기본작업-2 | B6: 2) [A3:G3] 영역은 가운데 맞춤, 글꼴 색 '흰색', 채우기 색 '진한 파랑' | C6: 2 | D6: 스스로 | E6: =IF(G6="O",C6,0) | F6: 머리글이 흰 글자·파란 바탕 | AA6: 46267 | AB6: PN-310 | AC6: 공압실린더 | AD6: 2창고 | AE6: 16 | AF6: 42000
A7: 기본작업-2 | B7: 3) [E4:E10] 영역에 사용자 지정 서식으로 숫자 뒤에 "EA" 표시 (예: 30EA, 0 이면 0EA) | C7: 2 | D7: 스스로 | E7: =IF(G7="O",C7,0) | F7: E4 가 30EA | AA7: 46268 | AB7: MT-102 | AC7: SM45C 환봉 | AD7: 1창고 | AE7: 80 | AF7: 5200
A8: 기본작업-2 | B8: 4) [B4:B10] 영역의 이름을 '자재코드' 로 정의 | C8: 2 | D8: 자동 | E8: =IF(ISREF(자재코드),2,0) | F8: 자동 채점 — 이름 상자에 '자재코드' | AA8: 46269 | AB8: EL-206 | AC8: 릴레이 24V | AD8: 3창고 | AE8: 150 | AF8: 2100
A9: 기본작업-2 | B9: 5) [A3:G10] 영역에 '모든 테두리', [A10:G10] 아래쪽은 '굵은 아래쪽 테두리' | C9: 2 | D9: 스스로 | E9: =IF(G9="O",C9,0) | F9: 마지막 줄 아래가 굵은 선 | AA9: 46272 | AB9: BL-401 | AC9: 육각볼트 M10 | AD9: 3창고 | AE9: 900 | AF9: 120
A10: 기본작업-3 | B10: 고급 필터 (조건 · 결과 5행) | C10: 5 | D10: 자동 | E10: =IF(AND(SUMPRODUCT(--('기본작업-3'!$A$19:$G$24&""='채점표'!$AA$12:$AG$17&""))=42,COUNTA('기본작업-3'!$A$25:$G$25)=0),5,0) | F10: 자동 — 결과가 A19 부터 정확히 5행 | AA10: 46273 | AB10: PN-311 | AC10: 솔레노이드밸브 | AD10: 2창고 | AE10: 24 | AF10: 35000
A11: 계산작업 | B11: 1. [표1] 재고 상태 [E3:E10] | C11: 8 | D11: 자동 | E11: =IF(COUNTIF('계산작업'!$AB$3:$AB$10,TRUE)=8,8,0) | F11: 자동 — 8칸 모두 맞아야 8점
A12: 계산작업 | B12: 2. [표2] 출고 금액 [D15:D20] | C12: 8 | D12: 자동 | E12: =IF(COUNTIF('계산작업'!$AB$15:$AB$20,TRUE)=6,8,0) | F12: 자동 — 6칸 모두 맞아야 8점 | AA12: 출고일 | AB12: 자재코드 | AC12: 자재명 | AD12: 창고 | AE12: 수량 | AF12: 단가 | AG12: 금액
A13: 계산작업 | B13: 3. [표3] 분류별 품목 비율 [E25:E27] | C13: 8 | D13: 자동 | E13: =IF(COUNTIF('계산작업'!$AB$25:$AB$27,TRUE)=3,8,0) | F13: 자동 — 3칸 모두 맞아야 8점 | AA13: 46275 | AB13: EL-205 | AC13: 근접센서 | AD13: 2창고 | AE13: 8 | AF13: 18500 | AG13: 148000
A14: 계산작업 | B14: 4. [표4] 설비 사용 연수 [C39:C44] | C14: 8 | D14: 자동 | E14: =IF(COUNTIF('계산작업'!$AB$39:$AB$44,TRUE)=6,8,0) | F14: 자동 — 6칸 모두 맞아야 8점 | AA14: 46277 | AB14: PN-310 | AC14: 공압실린더 | AD14: 2창고 | AE14: 4 | AF14: 42000 | AG14: 168000
A15: 계산작업 | B15: 5. [표5] 2창고 대량 입고 합계 [G49] | C15: 8 | D15: 자동 | E15: =IF(COUNTIF('계산작업'!$AB$49:$AB$49,TRUE)=1,8,0) | F15: 자동 — 1칸 모두 맞아야 8점 | AA15: 46279 | AB15: MT-102 | AC15: SM45C 환봉 | AD15: 1창고 | AE15: 120 | AF15: 5200 | AG15: 624000
A16: 분석작업-1 | B16: 시나리오 1) B4 이름이 '할인율', B8 이름이 '이익' | C16: 5 | D16: 스스로 | E16: =IF(G16="O",C16,0) | F16: 이름 상자 확인 | AA16: 46281 | AB16: PN-311 | AC16: 솔레노이드밸브 | AD16: 2창고 | AE16: 6 | AF16: 35000 | AG16: 210000
A17: 분석작업-1 | B17: 시나리오 2) [시나리오 요약] 시트가 있고 할인확대 이익 3,000,000 · 할인축소 5,400,000 | C17: 5 | D17: 스스로 | E17: =IF(G17="O",C17,0) | F17: 요약 표의 결과 셀 | AA17: 46283 | AB17: EL-207 | AC17: 서보모터 | AD17: 3창고 | AE17: 3 | AF17: 185000 | AG17: 555000
A18: 분석작업-2 | B18: 정렬 — 창고 오름차순 · 수량 내림차순 | C18: 10 | D18: 자동 | E18: =IF(SUMPRODUCT(--('분석작업-2'!$A$4:$A$15='채점표'!$AA$19:$AA$30))=12,10,0) | F18: 자동
A19: 기타작업-1 | B19: 매크로 1) [F4:F10] 에 금액(수량×단가)을 구하는 '금액' 매크로 — [H3] 위치 단추(텍스트 '금액')에 연결 | C19: 5 | D19: 스스로 | E19: =IF(G19="O",C19,0) | F19: F4 에 =D4*E4 | AA19: MT-101
A20: 기타작업-1 | B20: 매크로 2) [F4:F10] 에 쉼표 스타일(,)을 적용하는 '쉼표' 매크로 — [H6] 위치 단추(텍스트 '쉼표')에 연결 | C20: 5 | D20: 스스로 | E20: =IF(G20="O",C20,0) | F20: 단추를 누르면 102,000 처럼 | AA20: MT-102
A21: 기타작업-2 | B21: 차트 1) '3창고' 데이터를 차트에서 제외하시오 | C21: 2 | D21: 스스로 | E21: =IF(G21="O",C21,0) | F21: 가로축에 1·2·4창고만 | AA21: MT-103
A22: 기타작업-2 | B22: 차트 2) '재고' 계열을 삭제하시오 | C22: 2 | D22: 스스로 | E22: =IF(G22="O",C22,0) | F22: 범례에 입고·출고만 | AA22: MT-104
A23: 기타작업-2 | B23: 차트 3) 차트 제목 '창고별 입출고' · 글꼴 크기 14 · 굵게 | C23: 2 | D23: 스스로 | E23: =IF(G23="O",C23,0) | F23: 위쪽 제목 | AA23: PN-312
A24: 기타작업-2 | B24: 차트 4) 세로(값) 축 제목 '수량(EA)' 을 '세로 제목' 으로 추가하시오 | C24: 2 | D24: 스스로 | E24: =IF(G24="O",C24,0) | F24: 왼쪽 세로 글자 | AA24: EL-205
A25: 기타작업-2 | B25: 차트 5) '출고' 계열에 '안쪽 끝에' 데이터 레이블을 표시하시오 | C25: 2 | D25: 스스로 | E25: =IF(G25="O",C25,0) | F25: 막대 안쪽 위에 숫자 | AA25: PN-311
AA26: PN-310
B27: 합계 (100점 만점 · 70점 이상 합격) | E27: =SUM(E4:E25) | F27: =IF(E27>=70,"🎉 합격","불합격 — 틀린 작업의 [정답·해설]을 보세요") | AA27: BL-402
AA28: BL-401
A29: '스스로' 문항은 [확인 방법] 을 보고 실제로 그렇게 되어 있으면 O. 한 군데라도 다르면 X (실제 시험은 부분 점수 없음). | AA29: EL-206
AA30: EL-207

Sheet 정답·해설
A1: 정답·해설 — 제3회 (먼저 스스로 끝까지 풀고 보세요)
A3: 작업 | B3: 무엇을 | C3: 어떻게 · 정답
A4: 기본작업-1 | B4: 자료 입력 | C4: 문제지의 자료를 A4 부터 한 칸씩. 날짜는 2026-03-02 처럼 - 로 입력하면 날짜로 들어갑니다.
A5: 기본작업-2 | B5: 1) [A1:G1] 셀을 병합하여 가운데 맞춤, 글꼴 '궁서체' · 18pt · 굵게 | C5: 제목 칸이 합쳐지고 궁서체
A6: 기본작업-2 | B6: 2) [A3:G3] 영역은 가운데 맞춤, 글꼴 색 '흰색', 채우기 색 '진한 파랑' | C6: 머리글이 흰 글자·파란 바탕
A7: 기본작업-2 | B7: 3) [E4:E10] 영역에 사용자 지정 서식으로 숫자 뒤에 "EA" 표시 (예: 30EA, 0 이면 0EA) | C7: E4 가 30EA
A8: 기본작업-2 | B8: 4) [B4:B10] 영역의 이름을 '자재코드' 로 정의 | C8: 자동 채점 — 이름 상자에 '자재코드'
A9: 기본작업-2 | B9: 5) [A3:G10] 영역에 '모든 테두리', [A10:G10] 아래쪽은 '굵은 아래쪽 테두리' | C9: 마지막 줄 아래가 굵은 선
A10: 기본작업-3 | B10: 고급 필터 | C10: 조건: A15 '창고' · B15 '금액' / A16 '2창고' / B17 '>=500000' (다른 줄 = 또는) [데이터] → [고급] → '다른 장소에 복사' · 목록 범위 A3:G12 · 조건 범위 · 복사 위치 A19
A11: 계산작업 | B11: 1. [표1] 재고 상태 → [E3:E10] | C11: =IF(C3<D3,"발주",IF(C3<D3*1.5,"주의","정상")) (첫 칸에 넣고 끝까지 끌어내리기)
A12: 계산작업 | B12: 2. [표2] 출고 금액 → [D15:D20] | C12: =INDEX($G$15:$G$18,MATCH(B15,$F$15:$F$18,0))*C15 (첫 칸에 넣고 끝까지 끌어내리기)
A13: 계산작업 | B13: 3. [표3] 분류별 품목 비율 → [E25:E27] | C13: =COUNTIF($B$25:$B$34,D25)/COUNTA($B$25:$B$34) (첫 칸에 넣고 끝까지 끌어내리기)
A14: 계산작업 | B14: 4. [표4] 설비 사용 연수 → [C39:C44] | C14: =YEAR($E$39)-YEAR(B39)&"년" (첫 칸에 넣고 끝까지 끌어내리기)
... A23: 기타작업-2 | B23: 5) '출고' 계열에 '안쪽 끝에' 데이터 레이블을 표시하시오 | C23: 막대 안쪽 위에 숫자
