Workbook

Sheet 읽어보기
B2: 실전 모의고사 제2회 — 생산 라인
B3: 컴활 2급 실기와 같은 시트 이름 · 같은 배점입니다. 시간 40분, 70점 이상이면 합격.
B4: 순서
B5: ① [문제지] 시트에서 문제를 읽고 → 각 작업 시트(기본작업-1 …)에서 풉니다.
B6: ② 계산작업의 노란 칸에는 0 이 들어 있습니다. 0 을 지우고 첫 칸에 수식 → 끝까지 끌어내리기.
B7: ③ 다 풀었으면 [채점표] — 자동 칸은 저절로 점수가 나오고, '스스로' 칸은 [확인 방법] 을 보고 O / X 를 고릅니다.
B8: ④ 틀린 것은 [정답·해설] 에서 확인합니다.
B9: 매크로를 만들면 '다른 이름으로 저장' 에서 파일 형식을 Excel 매크로 사용 통합 문서(*.xlsm) 로 바꿔야 매크로가 남습니다.
B10: 값이 0 으로만 보이면 Ctrl + Alt + F9. 자동 채점 칸이 안 바뀌어 보일 때도 같습니다.

Sheet 문제지
A1: 컴퓨터활용능력 2급 실기 · 실전 모의고사 제2회 (생산 라인)
A2: 시험 시간 40분 · 100점 만점 · 70점 이상 합격. 시작 시각을 적어 두고 시작하세요 → 시작 [ : ] 끝 [ : ] 다 풀면 [채점표] 시트에서 점수를 확인합니다.
A4: 기본작업-1 · 5점
C5: [기본작업-1] 시트에 다음 자료를 [A4] 부터 그대로 입력하시오. (날짜는 2026-03-02 처럼)
C6: 지시번호 | 제품명 | 라인 | 지시일 | 수량 | 납기
C7: WO-2610-01 | 감속기어 | A | 2026-10-01 | 300 | 2026-10-08
C8: WO-2610-02 | 구동축 | B | 2026-10-01 | 150 | 2026-10-10
C9: WO-2610-03 | 밸브블록 | C | 2026-10-02 | 420 | 2026-10-09
C10: WO-2610-04 | 베어링유닛 | A | 2026-10-05 | 500 | 2026-10-14
C11: WO-2610-05 | 감속기어 | B | 2026-10-06 | 280 | 2026-10-13
C12: WO-2610-06 | 커플링 | C | 2026-10-07 | 90 | 2026-10-12
A13: ↑ (비움) 칸은 아무것도 입력하지 않습니다.
A15: 기본작업-2 · 10점
B16: 1) | C16: [A1:G1] 셀을 병합하여 가운데 맞춤, 글꼴 '돋움' · 17pt · 밑줄
B17: 2) | C17: [A3:G3] 영역에 셀 스타일 '강조색1' 적용
B18: 3) | C18: [A4:A11] 영역에 사용자 지정 서식 "mm월 dd일(aaa)" 적용 (예: 09월 01일(화))
B19: 4) | C19: [G4:G11] 영역의 이름을 '불량률' 로 정의
B20: 5) | C20: [E3] 셀에 '실제 생산 수량' 이라는 메모 삽입 (항상 표시)
A21: 기본작업-3 · 5점
C22: [A4:G11] 영역에서 불량[F]이 8 이상인 행 전체에 글꼴 스타일 '굵게', 글꼴 색 '빨강' 을 적용하시오. · 조건부 서식의 수식을 이용 · 규칙 유형은 '수식을 사용하여 서식을 지정할 셀 결정'
A23: 계산작업 · 40점 (각 8점)
B24: 1. | C24: [표1]에서 필기[B3:B10]와 실기[C3:C10]가 모두 60 이상이고 두 점수의 평균이 70 이상이면 "합격", 아니면 "불합격" 을 판정[D3:D10]에 표시하시오. → [D3:D10] (IF, AND, AVERAGE 함수 사용)
B25: 2. | C25: [표2]에서 로트번호[A15:A20]의 4번째부터 두 글자 뒤에 "월" 을 붙여 생산월[C15:C20]에 표시하시오. (예: L2603-A-017 → 03월) → [C15:C20] (MID 함수, & 연산자 사용)
B26: 3. | C26: [표3]에서 라인[A25:A32]별 시간[C25:C32]의 평균을 소수 첫째 자리까지 올림하여 평균 시간[F25:F27]에 표시하시오. (라인 이름은 E열) → [F25:F27] (ROUNDUP, AVERAGEIF 함수 사용)
B27: 4. | C27: [표4]에서 점수[C37:C42]와 오른쪽의 가로 등급표를 이용하여 등급[D37:D42]을 표시하시오. (점수가 기준값 이상인 구간의 등급) → [D37:D42] (HLOOKUP 함수 사용)
B28: 5. | C28: [표5]에서 라인이 "A" 인 제품의 생산[C47:C52] 평균을 오른쪽 조건표(F열)를 이용하여 구하시오. (소수 이하는 버림) → [G47] (DAVERAGE, ROUNDDOWN 함수 사용)
A29: 분석작업-1 · 10점
C30: [분석작업-1] 시트의 표를 이용하여 피벗 테이블을 만드시오. · 행: 라인 · 열: 제품 · 값: 생산의 합계 · 위치: [H3] · 보고서 레이아웃 '표 형식'
A31: 분석작업-2 · 10점
C32: [분석작업-2] 시트에서 [표1]~[표3] 세 분기의 제품별 생산량 '합계' 를 [G4:H8] 에 통합하시오. · [데이터] → [통합] · 사용할 레이블 '첫 행' 과 '왼쪽 열' (결과 표의 제품 이름은 이미 입력되어 있음)
A33: 기타작업-1 · 10점
C34: [기타작업-1] 시트에서 다음 두 매크로를 만들고 도형(빗면)에 연결하시오. (저장은 .xlsm 형식)
B35: 1) | C35: [F4:F9] 에 달성률(생산÷계획)을 구하는 '달성률' 매크로 — [H3] 위치 '빗면' 도형(텍스트 '달성률')에 연결
B36: 2) | C36: [F4:F9] 에 백분율 스타일(%)을 적용하는 '백분율' 매크로 — [H6] 위치 '빗면' 도형(텍스트 '백분율')에 연결
A37: 기타작업-2 · 10점 (각 2점)
C38: [기타작업-2] 시트의 차트(묶은 세로 막대 · 계획·생산)를 다음과 같이 고치시오.
B39: 1) | C39: 차트 종류를 '묶은 가로 막대형' 으로 바꾸시오
B40: 2) | C40: 차트 제목을 셀 [A1] 과 연결하시오
B41: 3) | C41: 가로(값) 축의 최소값 600, 주 단위 200 으로 지정하시오
B42: 4) | C42: 생산 계열의 '간격 너비' 를 50% 로 지정하시오
...

Sheet 기본작업-1
A1: 작업 지시서
A3: 지시번호 | B3: 제품명 | C3: 라인 | D3: 지시일 | E3: 수량 | F3: 납기

Sheet 기본작업-2
A1: 라인별 생산 실적
A3: 일자 | B3: 라인 | C3: 제품 | D3: 계획 | E3: 생산 | F3: 불량 | G3: 불량률
A4: 46266 | B4: A | C4: 감속기어 | D4: 300 | E4: 296 | F4: 6 | G4: =ROUND(F4/E4,3)
A5: 46266 | B5: B | C5: 구동축 | D5: 200 | E5: 212 | F5: 3 | G5: =ROUND(F5/E5,3)
A6: 46267 | B6: C | C6: 밸브블록 | D6: 400 | E6: 372 | F6: 15 | G6: =ROUND(F6/E6,3)
A7: 46267 | B7: A | C7: 베어링유닛 | D7: 500 | E7: 498 | F7: 9 | G7: =ROUND(F7/E7,3)
A8: 46268 | B8: B | C8: 감속기어 | D8: 300 | E8: 305 | F8: 4 | G8: =ROUND(F8/E8,3)
A9: 46268 | B9: C | C9: 커플링 | D9: 100 | E9: 96 | F9: 5 | G9: =ROUND(F9/E9,3)
A10: 46269 | B10: A | C10: 구동축 | D10: 200 | E10: 188 | F10: 10 | G10: =ROUND(F10/E10,3)
A11: 46269 | B11: B | C11: 밸브블록 | D11: 400 | E11: 415 | F11: 6 | G11: =ROUND(F11/E11,3)

Sheet 기본작업-3
A1: 조건부 서식
A3: 일자 | B3: 라인 | C3: 제품 | D3: 계획 | E3: 생산 | F3: 불량 | G3: 불량률
A4: 46266 | B4: A | C4: 감속기어 | D4: 300 | E4: 296 | F4: 6 | G4: 0.02
A5: 46266 | B5: B | C5: 구동축 | D5: 200 | E5: 212 | F5: 3 | G5: 0.014
A6: 46267 | B6: C | C6: 밸브블록 | D6: 400 | E6: 372 | F6: 15 | G6: 0.04
A7: 46267 | B7: A | C7: 베어링유닛 | D7: 500 | E7: 498 | F7: 9 | G7: 0.018
A8: 46268 | B8: B | C8: 감속기어 | D8: 300 | E8: 305 | F8: 4 | G8: 0.013
A9: 46268 | B9: C | C9: 커플링 | D9: 100 | E9: 96 | F9: 5 | G9: 0.052
A10: 46269 | B10: A | C10: 구동축 | D10: 200 | E10: 188 | F10: 10 | G10: 0.053
A11: 46269 | B11: B | C11: 밸브블록 | D11: 400 | E11: 415 | F11: 6 | G11: 0.014

Sheet 계산작업
A1: [표1] 기능 평가
A2: 사원 | B2: 필기 | C2: 실기 | D2: 판정
A3: 김도윤 | B3: 80 | C3: 70 | D3: 0 | AA3: =IF(AND(B3>=60,C3>=60,AVERAGE(B3:C3)>=70),"합격","불합격") | AB3: =AND(_xlfn.ISFORMULA(D3),IFERROR(ROUND(D3,4)=ROUND(AA3,4),EXACT(D3,AA3)))
A4: 이서연 | B4: 60 | C4: 80 | D4: 0 | AA4: =IF(AND(B4>=60,C4>=60,AVERAGE(B4:C4)>=70),"합격","불합격") | AB4: =AND(_xlfn.ISFORMULA(D4),IFERROR(ROUND(D4,4)=ROUND(AA4,4),EXACT(D4,AA4)))
A5: 박지훈 | B5: 59 | C5: 95 | D5: 0 | AA5: =IF(AND(B5>=60,C5>=60,AVERAGE(B5:C5)>=70),"합격","불합격") | AB5: =AND(_xlfn.ISFORMULA(D5),IFERROR(ROUND(D5,4)=ROUND(AA5,4),EXACT(D5,AA5)))
A6: 최하은 | B6: 72 | C6: 68 | D6: 0 | AA6: =IF(AND(B6>=60,C6>=60,AVERAGE(B6:C6)>=70),"합격","불합격") | AB6: =AND(_xlfn.ISFORMULA(D6),IFERROR(ROUND(D6,4)=ROUND(AA6,4),EXACT(D6,AA6)))
A7: 정민재 | B7: 90 | C7: 55 | D7: 0 | AA7: =IF(AND(B7>=60,C7>=60,AVERAGE(B7:C7)>=70),"합격","불합격") | AB7: =AND(_xlfn.ISFORMULA(D7),IFERROR(ROUND(D7,4)=ROUND(AA7,4),EXACT(D7,AA7)))
A8: 한수아 | B8: 66 | C8: 74 | D8: 0 | AA8: =IF(AND(B8>=60,C8>=60,AVERAGE(B8:C8)>=70),"합격","불합격") | AB8: =AND(_xlfn.ISFORMULA(D8),IFERROR(ROUND(D8,4)=ROUND(AA8,4),EXACT(D8,AA8)))
A9: 오지성 | B9: 100 | C9: 60 | D9: 0 | AA9: =IF(AND(B9>=60,C9>=60,AVERAGE(B9:C9)>=70),"합격","불합격") | AB9: =AND(_xlfn.ISFORMULA(D9),IFERROR(ROUND(D9,4)=ROUND(AA9,4),EXACT(D9,AA9)))
A10: 윤채원 | B10: 70 | C10: 69 | D10: 0 | AA10: =IF(AND(B10>=60,C10>=60,AVERAGE(B10:C10)>=70),"합격","불합격") | AB10: =AND(_xlfn.ISFORMULA(D10),IFERROR(ROUND(D10,4)=ROUND(AA10,4),EXACT(D10,AA10)))
A13: [표2] 로트 관리
A14: 로트번호 | B14: 제품 | C14: 생산월
A15: L2603-A-017 | B15: 감속기어 | C15: 0 | AA15: =MID(A15,4,2)&"월" | AB15: =AND(_xlfn.ISFORMULA(C15),IFERROR(ROUND(C15,4)=ROUND(AA15,4),EXACT(C15,AA15)))
A16: L2611-B-102 | B16: 구동축 | C16: 0 | AA16: =MID(A16,4,2)&"월" | AB16: =AND(_xlfn.ISFORMULA(C16),IFERROR(ROUND(C16,4)=ROUND(AA16,4),EXACT(C16,AA16)))
A17: L2607-C-045 | B17: 밸브 | C17: 0 | AA17: =MID(A17,4,2)&"월" | AB17: =AND(_xlfn.ISFORMULA(C17),IFERROR(ROUND(C17,4)=ROUND(AA17,4),EXACT(C17,AA17)))
A18: L2612-A-003 | B18: 커플링 | C18: 0 | AA18: =MID(A18,4,2)&"월" | AB18: =AND(_xlfn.ISFORMULA(C18),IFERROR(ROUND(C18,4)=ROUND(AA18,4),EXACT(C18,AA18)))
A19: L2601-B-220 | B19: 베어링 | C19: 0 | AA19: =MID(A19,4,2)&"월" | AB19: =AND(_xlfn.ISFORMULA(C19),IFERROR(ROUND(C19,4)=ROUND(AA19,4),EXACT(C19,AA19)))
A20: L2609-C-011 | B20: 기어 | C20: 0 | AA20: =MID(A20,4,2)&"월" | AB20: =AND(_xlfn.ISFORMULA(C20),IFERROR(ROUND(C20,4)=ROUND(AA20,4),EXACT(C20,AA20)))
A23: [표3] 라인별 작업시간
A24: 라인 | B24: 작업 | C24: 시간 | E24: 라인 | F24: 평균 시간
A25: B | B25: 조립 | C25: 3.2 | E25: A | F25: 0 | AA25: =ROUNDUP(AVERAGEIF($A$25:$A$32,E25,$C$25:$C$32),1) | AB25: =AND(_xlfn.ISFORMULA(F25),IFERROR(ROUND(F25,4)=ROUND(AA25,4),EXACT(F25,AA25)))
A26: A | B26: 용접 | C26: 2.45 | E26: B | F26: 0 | AA26: =ROUNDUP(AVERAGEIF($A$25:$A$32,E26,$C$25:$C$32),1) | AB26: =AND(_xlfn.ISFORMULA(F26),IFERROR(ROUND(F26,4)=ROUND(AA26,4),EXACT(F26,AA26)))
A27: C | B27: 가공 | C27: 4.1 | E27: C | F27: 0 | AA27: =ROUNDUP(AVERAGEIF($A$25:$A$32,E27,$C$25:$C$32),1) | AB27: =AND(_xlfn.ISFORMULA(F27),IFERROR(ROUND(F27,4)=ROUND(AA27,4),EXACT(F27,AA27)))
A28: A | B28: 조립 | C28: 3.3
A29: B | B29: 도장 | C29: 1.85
A30: C | B30: 검사 | C30: 0.9
A31: A | B31: 검사 | C31: 1.1
A32: B | B32: 포장 | C32: 2
A35: [표4] 품질 점수 등급
A36: 제품 | B36: 라인 | C36: 점수 | D36: 등급 | G36: 점수 | H36: 0 | I36: 60 | J36: 70 | K36: 80 | L36: 90
A37: 감속기어 | B37: A | C37: 92 | D37: 0 | G37: 등급 | H37: F | I37: D | J37: C | K37: B | L37: A | AA37: =HLOOKUP(C37,$H$36:$L$37,2,TRUE) | AB37: =AND(_xlfn.ISFORMULA(D37),IFERROR(ROUND(D37,4)=ROUND(AA37,4),EXACT(D37,AA37)))
A38: 구동축 | B38: B | C38: 68 | D38: 0 | AA38: =HLOOKUP(C38,$H$36:$L$37,2,TRUE) | AB38: =AND(_xlfn.ISFORMULA(D38),IFERROR(ROUND(D38,4)=ROUND(AA38,4),EXACT(D38,AA38)))
A39: 밸브블록 | B39: C | C39: 80 | D39: 0 | AA39: =HLOOKUP(C39,$H$36:$L$37,2,TRUE) | AB39: =AND(_xlfn.ISFORMULA(D39),IFERROR(ROUND(D39,4)=ROUND(AA39,4),EXACT(D39,AA39)))
A40: 베어링 | B40: A | C40: 59 | D40: 0 | AA40: =HLOOKUP(C40,$H$36:$L$37,2,TRUE) | AB40: =AND(_xlfn.ISFORMULA(D40),IFERROR(ROUND(D40,4)=ROUND(AA40,4),EXACT(D40,AA40)))
A41: 커플링 | B41: B | C41: 75 | D41: 0 | AA41: =HLOOKUP(C41,$H$36:$L$37,2,TRUE) | AB41: =AND(_xlfn.ISFORMULA(D41),IFERROR(ROUND(D41,4)=ROUND(AA41,4),EXACT(D41,AA41)))
A42: 기어 | B42: C | C42: 100 | D42: 0 | AA42: =HLOOKUP(C42,$H$36:$L$37,2,TRUE) | AB42: =AND(_xlfn.ISFORMULA(D42),IFERROR(ROUND(D42,4)=ROUND(AA42,4),EXACT(D42,AA42)))
A45: [표5] 라인 A 생산 평균
A46: 라인 | B46: 제품 | C46: 생산 | D46: 불량 | F46: 라인 | G46: 생산 평균
A47: A | B47: 감속기어 | C47: 296 | D47: 6 | F47: A | G47: 0 | AA47: =ROUNDDOWN(DAVERAGE(A46:D52,3,F46:F47),0) | AB47: =AND(_xlfn.ISFORMULA(G47),IFERROR(ROUND(G47,4)=ROUND(AA47,4),EXACT(G47,AA47)))
A48: B | B48: 구동축 | C48: 212 | D48: 3
...

Sheet 분석작업-1
A1: 분석작업-1
A3: 일자 | B3: 라인 | C3: 제품 | D3: 생산 | E3: 불량
A4: 46266 | B4: A | C4: 감속기어 | D4: 296 | E4: 6
A5: 46266 | B5: B | C5: 구동축 | D5: 212 | E5: 3
A6: 46267 | B6: C | C6: 밸브블록 | D6: 372 | E6: 15
A7: 46267 | B7: A | C7: 베어링유닛 | D7: 498 | E7: 9
A8: 46268 | B8: B | C8: 감속기어 | D8: 305 | E8: 4
A9: 46268 | B9: C | C9: 구동축 | D9: 96 | E9: 5
A10: 46269 | B10: A | C10: 구동축 | D10: 188 | E10: 10
A11: 46269 | B11: B | C11: 밸브블록 | D11: 415 | E11: 6
A12: 46270 | B12: C | C12: 감속기어 | D12: 280 | E12: 2
A13: 46270 | B13: A | C13: 밸브블록 | D13: 390 | E13: 8

Sheet 분석작업-2
A1: 분기별 제품 생산량
G2: 통합 결과
A3: [1분기] | G3: 제품 | H3: 생산량
A4: 제품 | B4: 생산량 | G4: 감속기어
A5: 감속기어 | B5: 820 | G5: 구동축
A6: 구동축 | B6: 510 | G6: 밸브블록
A7: 밸브블록 | B7: 640 | G7: 커플링
A8: 커플링 | B8: 230 | G8: 베어링
A10: [2분기]
A11: 제품 | B11: 생산량
A12: 구동축 | B12: 600
A13: 감속기어 | B13: 910
A14: 베어링 | B14: 480
A15: 밸브블록 | B15: 590
A17: [3분기]
A18: 제품 | B18: 생산량
A19: 밸브블록 | B19: 700
A20: 커플링 | B20: 260
A21: 감속기어 | B21: 880
A22: 베어링 | B22: 520

Sheet 기타작업-1
A1: 매크로
A3: 일자 | B3: 라인 | C3: 제품 | D3: 계획 | E3: 생산 | F3: 달성률
A4: 46266 | B4: A | C4: 감속기어 | D4: 300 | E4: 296
A5: 46266 | B5: B | C5: 구동축 | D5: 200 | E5: 212
A6: 46267 | B6: C | C6: 밸브블록 | D6: 400 | E6: 372
A7: 46267 | B7: A | C7: 베어링유닛 | D7: 500 | E7: 498
A8: 46268 | B8: B | C8: 감속기어 | D8: 300 | E8: 305
A9: 46268 | B9: C | C9: 커플링 | D9: 100 | E9: 96

Sheet 기타작업-2
A1: 라인별 계획 대비 생산
A3: 라인 | B3: 계획 | C3: 생산
A4: A라인 | B4: 1500 | C4: 1462
A5: B라인 | B5: 1200 | C5: 1244
A6: C라인 | B6: 1000 | C6: 948
A7: D라인 | B7: 800 | C7: 812

Sheet 채점표
A1: 채점표 — 제2회 (자동 칸은 저절로, '스스로' 칸은 O / X 를 고르세요)
A3: 작업 | B3: 문항 | C3: 배점 | D3: 방식 | E3: 점수 | F3: 확인 방법 | G3: O / X
A4: 기본작업-1 | B4: 자료 입력 (36칸 모두 정확히) | C4: 5 | D4: 자동 | E4: =IF(SUMPRODUCT(--EXACT('기본작업-1'!$A$4:$F$9&"",'채점표'!$AA$4:$AF$9&""))=36,5,0) | F4: 자동 — 한 칸이라도 다르면 0점 (실제 시험과 같음) | AA4: WO-2610-01 | AB4: 감속기어 | AC4: A | AD4: 46296 | AE4: 300 | AF4: 46303
A5: 기본작업-2 | B5: 1) [A1:G1] 셀을 병합하여 가운데 맞춤, 글꼴 '돋움' · 17pt · 밑줄 | C5: 2 | D5: 스스로 | E5: =IF(G5="O",C5,0) | F5: 제목 칸이 합쳐지고 밑줄 | AA5: WO-2610-02 | AB5: 구동축 | AC5: B | AD5: 46296 | AE5: 150 | AF5: 46305
A6: 기본작업-2 | B6: 2) [A3:G3] 영역에 셀 스타일 '강조색1' 적용 | C6: 2 | D6: 스스로 | E6: =IF(G6="O",C6,0) | F6: 머리글 줄이 파란 계열 스타일 | AA6: WO-2610-03 | AB6: 밸브블록 | AC6: C | AD6: 46297 | AE6: 420 | AF6: 46304
A7: 기본작업-2 | B7: 3) [A4:A11] 영역에 사용자 지정 서식 "mm월 dd일(aaa)" 적용 (예: 09월 01일(화)) | C7: 2 | D7: 스스로 | E7: =IF(G7="O",C7,0) | F7: A4 가 09월 01일(화) | AA7: WO-2610-04 | AB7: 베어링유닛 | AC7: A | AD7: 46300 | AE7: 500 | AF7: 46309
A8: 기본작업-2 | B8: 4) [G4:G11] 영역의 이름을 '불량률' 로 정의 | C8: 2 | D8: 자동 | E8: =IF(ISREF(불량률),2,0) | F8: 자동 채점 — 이름 상자에 '불량률' | AA8: WO-2610-05 | AB8: 감속기어 | AC8: B | AD8: 46301 | AE8: 280 | AF8: 46308
A9: 기본작업-2 | B9: 5) [E3] 셀에 '실제 생산 수량' 이라는 메모 삽입 (항상 표시) | C9: 2 | D9: 스스로 | E9: =IF(G9="O",C9,0) | F9: E3 옆에 메모 상자가 늘 보임 | AA9: WO-2610-06 | AB9: 커플링 | AC9: C | AD9: 46302 | AE9: 90 | AF9: 46307
A10: 기본작업-3 | B10: 조건부 서식 — 불량이 8 이상인 행 — 9월 2일 C · 9월 2일 A · 9월 4일 A — 행 전체가 굵은 빨강 | C10: 5 | D10: 스스로 | E10: =IF(G10="O",C10,0) | F10: 불량이 8 이상인 행 — 9월 2일 C · 9월 2일 A · 9월 4일 A — 행 전체가 굵은 빨강 (그 세 줄만 빨강) / 수식이 =$F4>=8 (F 앞에만 $) ([조건부 서식] → [규칙 관리] 에서 확인)
A11: 계산작업 | B11: 1. [표1] 기능 평가 [D3:D10] | C11: 8 | D11: 자동 | E11: =IF(COUNTIF('계산작업'!$AB$3:$AB$10,TRUE)=8,8,0) | F11: 자동 — 8칸 모두 맞아야 8점 | AA11: 2610
A12: 계산작업 | B12: 2. [표2] 로트 관리 [C15:C20] | C12: 8 | D12: 자동 | E12: =IF(COUNTIF('계산작업'!$AB$15:$AB$20,TRUE)=6,8,0) | F12: 자동 — 6칸 모두 맞아야 8점 | AA12: 1110
A13: 계산작업 | B13: 3. [표3] 라인별 작업시간 [F25:F27] | C13: 8 | D13: 자동 | E13: =IF(COUNTIF('계산작업'!$AB$25:$AB$27,TRUE)=3,8,0) | F13: 자동 — 3칸 모두 맞아야 8점 | AA13: 1930
A14: 계산작업 | B14: 4. [표4] 품질 점수 등급 [D37:D42] | C14: 8 | D14: 자동 | E14: =IF(COUNTIF('계산작업'!$AB$37:$AB$42,TRUE)=6,8,0) | F14: 자동 — 6칸 모두 맞아야 8점 | AA14: 490
A15: 계산작업 | B15: 5. [표5] 라인 A 생산 평균 [G47] | C15: 8 | D15: 자동 | E15: =IF(COUNTIF('계산작업'!$AB$47:$AB$47,TRUE)=1,8,0) | F15: 자동 — 1칸 모두 맞아야 8점 | AA15: 1000
A16: 분석작업-1 | B16: 피벗 1) 피벗 테이블이 H3 에서 시작하고 행에 A·B·C, 열에 제품 이름 | C16: 4 | D16: 스스로 | E16: =IF(G16="O",C16,0) | F16: H3 칸을 누르면 [피벗 테이블 분석] 메뉴가 나타남
A17: 분석작업-1 | B17: 피벗 2) A 라인 총합계 1,372 · B 라인 932 · C 라인 748 · 전체 3,052 | C17: 3 | D17: 스스로 | E17: =IF(G17="O",C17,0) | F17: 맨 오른쪽 '총합계' 열
A18: 분석작업-1 | B18: 피벗 3) 레이아웃이 '표 형식' (머리글에 '라인', '제품' 이 보임) | C18: 3 | D18: 스스로 | E18: =IF(G18="O",C18,0) | F18: [디자인] → [보고서 레이아웃]
A19: 분석작업-2 | B19: 통합 — 제품별 생산량 합계 [H4:H8] | C19: 10 | D19: 자동 | E19: =IF(SUMPRODUCT(--('분석작업-2'!$H$4:$H$8='채점표'!$AA$11:$AA$15))=5,10,0) | F19: 자동
A20: 기타작업-1 | B20: 매크로 1) [F4:F9] 에 달성률(생산÷계획)을 구하는 '달성률' 매크로 — [H3] 위치 '빗면' 도형(텍스트 '달성률')에 연결 | C20: 5 | D20: 스스로 | E20: =IF(G20="O",C20,0) | F20: F4 에 =E4/D4 가 들어가고 도형을 누르면 다시 채워짐
A21: 기타작업-1 | B21: 매크로 2) [F4:F9] 에 백분율 스타일(%)을 적용하는 '백분율' 매크로 — [H6] 위치 '빗면' 도형(텍스트 '백분율')에 연결 | C21: 5 | D21: 스스로 | E21: =IF(G21="O",C21,0) | F21: 도형을 누르면 99% 처럼 보임
A22: 기타작업-2 | B22: 차트 1) 차트 종류를 '묶은 가로 막대형' 으로 바꾸시오 | C22: 2 | D22: 스스로 | E22: =IF(G22="O",C22,0) | F22: 막대가 옆으로 누움
A23: 기타작업-2 | B23: 차트 2) 차트 제목을 셀 [A1] 과 연결하시오 | C23: 2 | D23: 스스로 | E23: =IF(G23="O",C23,0) | F23: 제목을 누르면 수식 입력줄에 ='기타작업-2'!$A$1
A24: 기타작업-2 | B24: 차트 3) 가로(값) 축의 최소값 600, 주 단위 200 으로 지정하시오 | C24: 2 | D24: 스스로 | E24: =IF(G24="O",C24,0) | F24: 축이 600 부터
A25: 기타작업-2 | B25: 차트 4) 생산 계열의 '간격 너비' 를 50% 로 지정하시오 | C25: 2 | D25: 스스로 | E25: =IF(G25="O",C25,0) | F25: 막대가 굵어짐
A26: 기타작업-2 | B26: 차트 5) 차트 영역에 '둥근 모서리' 와 그림자(오프셋 오른쪽 아래)를 지정하시오 | C26: 2 | D26: 스스로 | E26: =IF(G26="O",C26,0) | F26: 차트 테두리가 둥글고 그림자
B28: 합계 (100점 만점 · 70점 이상 합격) | E28: =SUM(E4:E26) | F28: =IF(E28>=70,"🎉 합격","불합격 — 틀린 작업의 [정답·해설]을 보세요")
A30: '스스로' 문항은 [확인 방법] 을 보고 실제로 그렇게 되어 있으면 O. 한 군데라도 다르면 X (실제 시험은 부분 점수 없음).

Sheet 정답·해설
A1: 정답·해설 — 제2회 (먼저 스스로 끝까지 풀고 보세요)
A3: 작업 | B3: 무엇을 | C3: 어떻게 · 정답
A4: 기본작업-1 | B4: 자료 입력 | C4: 문제지의 자료를 A4 부터 한 칸씩. 날짜는 2026-03-02 처럼 - 로 입력하면 날짜로 들어갑니다.
A5: 기본작업-2 | B5: 1) [A1:G1] 셀을 병합하여 가운데 맞춤, 글꼴 '돋움' · 17pt · 밑줄 | C5: 제목 칸이 합쳐지고 밑줄
A6: 기본작업-2 | B6: 2) [A3:G3] 영역에 셀 스타일 '강조색1' 적용 | C6: 머리글 줄이 파란 계열 스타일
A7: 기본작업-2 | B7: 3) [A4:A11] 영역에 사용자 지정 서식 "mm월 dd일(aaa)" 적용 (예: 09월 01일(화)) | C7: A4 가 09월 01일(화)
A8: 기본작업-2 | B8: 4) [G4:G11] 영역의 이름을 '불량률' 로 정의 | C8: 자동 채점 — 이름 상자에 '불량률'
A9: 기본작업-2 | B9: 5) [E3] 셀에 '실제 생산 수량' 이라는 메모 삽입 (항상 표시) | C9: E3 옆에 메모 상자가 늘 보임
A10: 기본작업-3 | B10: 조건부 서식 | C10: A4:G11 선택 → [홈] → [조건부 서식] → [새 규칙] '수식을 사용하여 서식을 지정할 셀 결정' → 수식 =$F4>=8 [서식] → 글꼴 : 굵게 · 빨강 → 확인
A11: 계산작업 | B11: 1. [표1] 기능 평가 → [D3:D10] | C11: =IF(AND(B3>=60,C3>=60,AVERAGE(B3:C3)>=70),"합격","불합격") (첫 칸에 넣고 끝까지 끌어내리기)
A12: 계산작업 | B12: 2. [표2] 로트 관리 → [C15:C20] | C12: =MID(A15,4,2)&"월" (첫 칸에 넣고 끝까지 끌어내리기)
A13: 계산작업 | B13: 3. [표3] 라인별 작업시간 → [F25:F27] | C13: =ROUNDUP(AVERAGEIF($A$25:$A$32,E25,$C$25:$C$32),1) (첫 칸에 넣고 끝까지 끌어내리기)
A14: 계산작업 | B14: 4. [표4] 품질 점수 등급 → [D37:D42] | C14: =HLOOKUP(C37,$H$36:$L$37,2,TRUE) (첫 칸에 넣고 끝까지 끌어내리기)
... A23: 기타작업-2 | B23: 5) 차트 영역에 '둥근 모서리' 와 그림자(오프셋 오른쪽 아래)를 지정하시오 | C23: 차트 테두리가 둥글고 그림자
