Workbook

Sheet 읽어보기
B2: 컴활 1급 실기 실전 모의고사 제2회 — 출하 실적
B3: 1급 스프레드시트 실무와 같은 시트 이름 · 같은 배점입니다. 시간 45분, 70점 이상이면 합격.
B4: 순서
B5: ① [문제지] 시트를 읽고 → 각 작업 시트에서 풉니다.
B6: ② 계산작업 노란 칸의 0 을 지우고 첫 칸에 수식 → 끝까지 끌어내리기. 배열 수식은 Ctrl + Shift + Enter.
B7: ③ 계산작업 5번은 사용자 정의 함수 — [개발 도구] → [Visual Basic] → 모듈에 Function 을 만들고 =fn…() 로 계산합니다.
B8: ④ 다 풀면 [채점표] — 자동 칸은 저절로, '스스로' 칸은 [확인 방법] 을 보고 O / X.
B9: 함수·매크로·VBA 가 들어가면 '다른 이름으로 저장' → Excel 매크로 사용 통합 문서(*.xlsm). 그냥 저장하면 코드가 사라집니다.
B10: [개발 도구] 탭이 없으면 [파일] → [옵션] → [리본 사용자 지정] 에서 '개발 도구' 체크.

Sheet 문제지
A1: 컴퓨터활용능력 1급 실기 · 스프레드시트 실무 · 실전 모의고사 제2회 (출하 실적)
A2: 시험 시간 45분 · 100점 만점 · 70점 이상 합격. 시작 [ : ] 끝 [ : ] 사용자 정의 함수·매크로·VBA 를 넣었으면 Excel 매크로 사용 통합 문서(*.xlsm)로 저장하세요.
A4: 기본작업-1 · 10점
B5: 1. | C5: [A3:F15] 영역에서 출하일의 월이 10월이면서 수량이 수량 전체 평균 이상인 행의 '출하일', '거래처', '제품', '수량' 열만 고급 필터로 추출하시오. · 조건은 [A17:A18] 영역에 AND, MONTH, AVERAGE 함수를 사용한 수식으로 입력 · 결과는 [A20] 셀부터 표시
B6: 2. | C6: [A4:F15] 영역에서 거래처가 '대한기계' 이면서 금액이 10,000,000 이상인 행 전체에 글꼴 '굵게', 글꼴 색 '파랑' 을 적용하시오. · AND 함수를 사용한 수식으로 조건 지정
A7: 기본작업-2 · 5점
B8: 3. | C8: [기본작업-2] 시트의 [B4:E10] 영역에만 셀 잠금을 해제하고, 나머지 셀은 수정할 수 없게 시트를 보호하시오. · '잠긴 셀 선택' 은 허용하지 않음(잠금 해제된 셀 선택만 허용) · 암호는 지정하지 않음
A9: 계산작업 · 30점 (각 6점)
B10: 1. | C10: [표1]에서 거래처[A3:A10]와 분기[B3:B10]가 E·F열과 같은 금액[C3:C10]의 합계를 합계[G3:G6]에 구하시오. (단위: 십만 원) → [G3:G6]
B11: 2. | C11: [표2]에서 거래처[A15:A22]가 E열의 거래처와 같은 수량[C15:C22] 중 가장 큰 값을 최대 수량[F15:F17]에 구하시오. (MAX, IF 함수를 이용한 배열 수식) → [F15:F17] ※ Ctrl+Shift+Enter
B12: 3. | C12: [표3]에서 지역[B27:B32]과 차종[C27:C32]으로 오른쪽 운임표에서 운임을 찾아 운임[D27:D32]에 표시하시오. (VLOOKUP, MATCH 함수) → [D27:D32]
B13: 4. | C13: [표4]에서 제품[A37:A42]이 E열과 같고 등급[B37:B42]이 "A" 인 단가[C37:C42]의 평균을 백의 자리에서 반올림(천 원 단위)하여 평균 단가[F37:F40]에 표시하되, 해당 자료가 없으면 "없음" 을 표시하시오. → [F37:F40]
B14: 5. | C14: [표5]에서 사용자 정의 함수 'fn운송비' 를 작성하여 운송비[D47:D52]를 표시하시오. fn운송비는 중량과 거리를 인수로 받아, 중량이 100 이하이면 거리×500, 100 초과이면 거리×800 을 돌려준다. (IF 문 사용 · Public Function fn운송비(중량, 거리)) → [D47:D52]
A15: 분석작업-1 · 10점
C16: [분석작업-1] 시트의 표로 피벗 테이블을 만드시오. · 행: 출하일(월 단위로 그룹) · 열: 거래처 · 값: 금액의 합계 · 위치 [I3] · 값의 표시 형식 '숫자' 천 단위 구분 기호 · 행 총합계만 표시(열 총합계 해제)
A17: 분석작업-2 · 10점
C18: [분석작업-2] 시트에서 [표1]~[표3] 세 달의 제품별 '수량' 과 '금액' 의 평균을 [H4:J8] 에 통합하시오. · 함수 '평균' · 사용할 레이블 '첫 행' 과 '왼쪽 열'
A19: 기타작업-1 · 10점 (각 2점)
C20: [기타작업-1] 시트의 차트(묶은 세로 막대 · 9월·10월)를 다음과 같이 고치시오. (각 2점)
B21: 1) | C21: '동양기공' 데이터를 차트에서 제외하시오
B22: 2) | C22: 차트 종류를 '누적 세로 막대형' 으로 바꾸시오
B23: 3) | C23: 세로(값) 축 제목 '금액(백만 원)' 을 '세로 제목' 으로 추가하시오
B24: 4) | C24: '10월' 계열에 '가운데' 데이터 레이블 '값' 을 표시하시오
B25: 5) | C25: 범례를 '위쪽', 차트 영역 테두리 '둥근 모서리' 를 지정하시오
A26: 기타작업-2 · 10점 (각 5점)
C27: [기타작업-2] 시트에서 다음 두 매크로를 만들고 연결하시오. (각 5점 · 저장은 .xlsm)
B28: 1) | C28: [D4:D7] 에 합계(9월+10월)를 SUM 으로 구하는 '합계' 매크로 — [F3:G4] 영역 단추(텍스트 '합계')에 연결
B29: 2) | C29: [A3:D3] 영역에 셀 스타일 '강조색2' 를 적용하는 '스타일' 매크로 — [F6:G7] 영역 도형 '빗면'(텍스트 '스타일')에 연결
A30: 기타작업-3 · 15점 (각 5점)
C31: [기타작업-3] 시트에서 다음과 같이 프로그래밍하시오. (각 5점) ※ 실제 시험은 미리 만든 사용자 폼(입력 폼)을 쓰지만, 이 연습 파일에는 폼을 넣을 수 없어 단추·InputBox·이벤트로 같은 문법을 연습합니다.
B32: 1) | C32: [G3] 위치 단추(텍스트 '출하 등록')에, InputBox 로 거래처·제품·수량을 받아 표 마지막 다음 줄에 넣고 출하일은 오늘 날짜로 넣는 '출하등록' 프로시저를 연결하시오.
B33: 2) | C33: 수량을 넣을 때 500 이상이면 '대량 출하입니다' 메시지가 뜨도록 '출하등록' 에 If 문을 덧붙이시오.
B34: 3) | C34: 통합 문서를 열 때(Workbook_Open) '출하 관리를 시작합니다' 메시지가 뜨게 하시오.

Sheet 기본작업-1
A1: 기본작업-1
A3: 출하일 | B3: 출하번호 | C3: 거래처 | D3: 제품 | E3: 수량 | F3: 금액
A4: 46267 | B4: S-001 | C4: 대한기계 | D4: 감속기어 | E4: 420 | F4: 18900000
A5: 46270 | B5: S-002 | C5: 한빛정밀 | D5: 구동축 | E5: 160 | F5: 12480000
A6: 46274 | B6: S-003 | C6: 대한기계 | D6: 밸브블록 | E6: 300 | F6: 9900000
A7: 46280 | B7: S-004 | C7: 서해산업 | D7: 커플링 | E7: 520 | F7: 4160000
A8: 46287 | B8: S-005 | C8: 한빛정밀 | D8: 감속기어 | E8: 250 | F8: 11250000
A9: 46294 | B9: S-006 | C9: 서해산업 | D9: 구동축 | E9: 90 | F9: 7020000
A10: 46296 | B10: S-007 | C10: 대한기계 | D10: 커플링 | E10: 610 | F10: 4880000
A11: 46301 | B11: S-008 | C11: 한빛정밀 | D11: 밸브블록 | E11: 330 | F11: 10890000
A12: 46308 | B12: S-009 | C12: 서해산업 | D12: 감속기어 | E12: 180 | F12: 8100000
A13: 46315 | B13: S-010 | C13: 대한기계 | D13: 구동축 | E13: 210 | F13: 16380000
A14: 46322 | B14: S-011 | C14: 한빛정밀 | D14: 커플링 | E14: 700 | F14: 5600000
A15: 46325 | B15: S-012 | C15: 서해산업 | D15: 밸브블록 | E15: 260 | F15: 8580000

Sheet 기본작업-2
A1: 기본작업-2 (시트 보호)
A3: 출하일 | B3: 출하번호 | C3: 거래처 | D3: 제품 | E3: 수량 | F3: 금액
A4: 46267 | B4: S-001 | C4: 대한기계 | D4: 감속기어 | E4: 420 | F4: 18900000
A5: 46270 | B5: S-002 | C5: 한빛정밀 | D5: 구동축 | E5: 160 | F5: 12480000
A6: 46274 | B6: S-003 | C6: 대한기계 | D6: 밸브블록 | E6: 300 | F6: 9900000
A7: 46280 | B7: S-004 | C7: 서해산업 | D7: 커플링 | E7: 520 | F7: 4160000
A8: 46287 | B8: S-005 | C8: 한빛정밀 | D8: 감속기어 | E8: 250 | F8: 11250000
A9: 46294 | B9: S-006 | C9: 서해산업 | D9: 구동축 | E9: 90 | F9: 7020000
A10: 46296 | B10: S-007 | C10: 대한기계 | D10: 커플링 | E10: 610 | F10: 4880000

Sheet 계산작업
A1: [표1] 거래처·분기별 금액
A2: 거래처 | B2: 분기 | C2: 금액 | E2: 거래처 | F2: 분기 | G2: 합계
A3: 대한기계 | B3: 3분기 | C3: 189 | E3: 대한기계 | F3: 3분기 | G3: 0 | AA3: =SUMIFS($C$3:$C$10,$A$3:$A$10,E3,$B$3:$B$10,F3) | AB3: =AND(_xlfn.ISFORMULA(G3),IFERROR(ROUND(G3,4)=ROUND(AA3,4),EXACT(G3,AA3)))
A4: 한빛정밀 | B4: 3분기 | C4: 125 | E4: 대한기계 | F4: 4분기 | G4: 0 | AA4: =SUMIFS($C$3:$C$10,$A$3:$A$10,E4,$B$3:$B$10,F4) | AB4: =AND(_xlfn.ISFORMULA(G4),IFERROR(ROUND(G4,4)=ROUND(AA4,4),EXACT(G4,AA4)))
A5: 대한기계 | B5: 4분기 | C5: 49 | E5: 한빛정밀 | F5: 3분기 | G5: 0 | AA5: =SUMIFS($C$3:$C$10,$A$3:$A$10,E5,$B$3:$B$10,F5) | AB5: =AND(_xlfn.ISFORMULA(G5),IFERROR(ROUND(G5,4)=ROUND(AA5,4),EXACT(G5,AA5)))
A6: 서해산업 | B6: 3분기 | C6: 42 | E6: 한빛정밀 | F6: 4분기 | G6: 0 | AA6: =SUMIFS($C$3:$C$10,$A$3:$A$10,E6,$B$3:$B$10,F6) | AB6: =AND(_xlfn.ISFORMULA(G6),IFERROR(ROUND(G6,4)=ROUND(AA6,4),EXACT(G6,AA6)))
A7: 대한기계 | B7: 3분기 | C7: 99
A8: 한빛정밀 | B8: 4분기 | C8: 109
A9: 대한기계 | B9: 4분기 | C9: 164
A10: 한빛정밀 | B10: 3분기 | C10: 113
A13: [표2] 거래처별 최대 출하량
A14: 거래처 | B14: 제품 | C14: 수량 | E14: 거래처 | F14: 최대 수량
A15: 대한기계 | B15: 기어 | C15: 420 | E15: 대한기계 | F15: 0 | AA15: {=MAX(IF($A$15:$A$22=E15,$C$15:$C$22))} | AB15: =AND(_xlfn.ISFORMULA(F15),IFERROR(ROUND(F15,4)=ROUND(AA15,4),EXACT(F15,AA15)))
A16: 한빛정밀 | B16: 축 | C16: 160 | E16: 한빛정밀 | F16: 0 | AA16: {=MAX(IF($A$15:$A$22=E16,$C$15:$C$22))} | AB16: =AND(_xlfn.ISFORMULA(F16),IFERROR(ROUND(F16,4)=ROUND(AA16,4),EXACT(F16,AA16)))
A17: 대한기계 | B17: 밸브 | C17: 610 | E17: 서해산업 | F17: 0 | AA17: {=MAX(IF($A$15:$A$22=E17,$C$15:$C$22))} | AB17: =AND(_xlfn.ISFORMULA(F17),IFERROR(ROUND(F17,4)=ROUND(AA17,4),EXACT(F17,AA17)))
A18: 서해산업 | B18: 커플링 | C18: 520
A19: 한빛정밀 | B19: 기어 | C19: 700
A20: 서해산업 | B20: 축 | C20: 90
A21: 대한기계 | B21: 커플링 | C21: 210
A22: 한빛정밀 | B22: 밸브 | C22: 330
A25: [표3] 운임 조회
A26: 출하번호 | B26: 지역 | C26: 차종 | D26: 운임 | F26: 지역 | G26: 1톤 | H26: 2.5톤 | I26: 5톤
A27: S-01 | B27: 경기 | C27: 2.5톤 | D27: 0 | F27: 서울 | G27: 60000 | H27: 90000 | I27: 150000 | AA27: =VLOOKUP(B27,$F$27:$I$30,MATCH(C27,$F$26:$I$26,0),FALSE) | AB27: =AND(_xlfn.ISFORMULA(D27),IFERROR(ROUND(D27,4)=ROUND(AA27,4),EXACT(D27,AA27)))
A28: S-02 | B28: 서울 | C28: 5톤 | D28: 0 | F28: 경기 | G28: 80000 | H28: 120000 | I28: 190000 | AA28: =VLOOKUP(B28,$F$27:$I$30,MATCH(C28,$F$26:$I$26,0),FALSE) | AB28: =AND(_xlfn.ISFORMULA(D28),IFERROR(ROUND(D28,4)=ROUND(AA28,4),EXACT(D28,AA28)))
A29: S-03 | B29: 충청 | C29: 1톤 | D29: 0 | F29: 충청 | G29: 130000 | H29: 180000 | I29: 260000 | AA29: =VLOOKUP(B29,$F$27:$I$30,MATCH(C29,$F$26:$I$26,0),FALSE) | AB29: =AND(_xlfn.ISFORMULA(D29),IFERROR(ROUND(D29,4)=ROUND(AA29,4),EXACT(D29,AA29)))
A30: S-04 | B30: 경기 | C30: 1톤 | D30: 0 | F30: 경상 | G30: 200000 | H30: 270000 | I30: 380000 | AA30: =VLOOKUP(B30,$F$27:$I$30,MATCH(C30,$F$26:$I$26,0),FALSE) | AB30: =AND(_xlfn.ISFORMULA(D30),IFERROR(ROUND(D30,4)=ROUND(AA30,4),EXACT(D30,AA30)))
A31: S-05 | B31: 경상 | C31: 5톤 | D31: 0 | AA31: =VLOOKUP(B31,$F$27:$I$30,MATCH(C31,$F$26:$I$26,0),FALSE) | AB31: =AND(_xlfn.ISFORMULA(D31),IFERROR(ROUND(D31,4)=ROUND(AA31,4),EXACT(D31,AA31)))
A32: S-06 | B32: 서울 | C32: 2.5톤 | D32: 0 | AA32: =VLOOKUP(B32,$F$27:$I$30,MATCH(C32,$F$26:$I$26,0),FALSE) | AB32: =AND(_xlfn.ISFORMULA(D32),IFERROR(ROUND(D32,4)=ROUND(AA32,4),EXACT(D32,AA32)))
A35: [표4] 제품별 평균 단가
A36: 제품 | B36: 등급 | C36: 단가 | E36: 제품 | F36: 평균 단가
A37: 기어 | B37: A | C37: 45000 | E37: 기어 | F37: 0 | AA37: =IFERROR(ROUND(AVERAGEIFS($C$37:$C$42,$A$37:$A$42,E37,$B$37:$B$42,"A"),-3),"없음") | AB37: =AND(_xlfn.ISFORMULA(F37),IFERROR(ROUND(F37,4)=ROUND(AA37,4),EXACT(F37,AA37)))
A38: 축 | B38: A | C38: 78000 | E38: 축 | F38: 0 | AA38: =IFERROR(ROUND(AVERAGEIFS($C$37:$C$42,$A$37:$A$42,E38,$B$37:$B$42,"A"),-3),"없음") | AB38: =AND(_xlfn.ISFORMULA(F38),IFERROR(ROUND(F38,4)=ROUND(AA38,4),EXACT(F38,AA38)))
A39: 기어 | B39: B | C39: 41000 | E39: 밸브 | F39: 0 | AA39: =IFERROR(ROUND(AVERAGEIFS($C$37:$C$42,$A$37:$A$42,E39,$B$37:$B$42,"A"),-3),"없음") | AB39: =AND(_xlfn.ISFORMULA(F39),IFERROR(ROUND(F39,4)=ROUND(AA39,4),EXACT(F39,AA39)))
A40: 축 | B40: B | C40: 70500 | E40: 커플링 | F40: 0 | AA40: =IFERROR(ROUND(AVERAGEIFS($C$37:$C$42,$A$37:$A$42,E40,$B$37:$B$42,"A"),-3),"없음") | AB40: =AND(_xlfn.ISFORMULA(F40),IFERROR(ROUND(F40,4)=ROUND(AA40,4),EXACT(F40,AA40)))
A41: 기어 | B41: A | C41: 46250
A42: 커플링 | B42: B | C42: 8000
A45: [표5] 운송비 (사용자 정의 함수)
A46: 출하번호 | B46: 중량(kg) | C46: 거리(km) | D46: 운송비
A47: T-1 | B47: 80 | C47: 30 | D47: 0 | AA47: =IF(B47<=100,C47*500,C47*800) | AB47: =AND(_xlfn.ISFORMULA(D47),IFERROR(ROUND(D47,4)=ROUND(AA47,4),EXACT(D47,AA47)))
A48: T-2 | B48: 100 | C48: 50 | D48: 0 | AA48: =IF(B48<=100,C48*500,C48*800) | AB48: =AND(_xlfn.ISFORMULA(D48),IFERROR(ROUND(D48,4)=ROUND(AA48,4),EXACT(D48,AA48)))
...

Sheet 분석작업-1
A1: 분석작업-1
A3: 출하일 | B3: 출하번호 | C3: 거래처 | D3: 제품 | E3: 수량 | F3: 금액
A4: 46267 | B4: S-001 | C4: 대한기계 | D4: 감속기어 | E4: 420 | F4: 18900000
A5: 46270 | B5: S-002 | C5: 한빛정밀 | D5: 구동축 | E5: 160 | F5: 12480000
A6: 46274 | B6: S-003 | C6: 대한기계 | D6: 밸브블록 | E6: 300 | F6: 9900000
A7: 46280 | B7: S-004 | C7: 서해산업 | D7: 커플링 | E7: 520 | F7: 4160000
A8: 46287 | B8: S-005 | C8: 한빛정밀 | D8: 감속기어 | E8: 250 | F8: 11250000
A9: 46294 | B9: S-006 | C9: 서해산업 | D9: 구동축 | E9: 90 | F9: 7020000
A10: 46296 | B10: S-007 | C10: 대한기계 | D10: 커플링 | E10: 610 | F10: 4880000
A11: 46301 | B11: S-008 | C11: 한빛정밀 | D11: 밸브블록 | E11: 330 | F11: 10890000
A12: 46308 | B12: S-009 | C12: 서해산업 | D12: 감속기어 | E12: 180 | F12: 8100000
A13: 46315 | B13: S-010 | C13: 대한기계 | D13: 구동축 | E13: 210 | F13: 16380000
A14: 46322 | B14: S-011 | C14: 한빛정밀 | D14: 커플링 | E14: 700 | F14: 5600000
A15: 46325 | B15: S-012 | C15: 서해산업 | D15: 밸브블록 | E15: 260 | F15: 8580000

Sheet 분석작업-2
A1: 월별 제품 출하
H2: 통합 결과 (평균)
A3: [7월] | H3: 제품 | I3: 수량 | J3: 금액
A4: 제품 | B4: 수량 | C4: 금액 | H4: 감속기어
A5: 감속기어 | B5: 400 | C5: 180 | H5: 구동축
A6: 구동축 | B6: 150 | C6: 117 | H6: 밸브블록
A7: 밸브블록 | B7: 280 | C7: 92 | H7: 커플링
A8: 커플링 | B8: 500 | C8: 40 | H8: 베어링
A10: [8월]
A11: 제품 | B11: 수량 | C11: 금액
A12: 구동축 | B12: 170 | C12: 132
A13: 감속기어 | B13: 380 | C13: 171
A14: 커플링 | B14: 620 | C14: 49
A15: 베어링 | B15: 300 | C15: 36
A17: [9월]
A18: 제품 | B18: 수량 | C18: 금액
A19: 밸브블록 | B19: 320 | C19: 105
A20: 감속기어 | B20: 420 | C20: 189
A21: 베어링 | B21: 260 | C21: 31
A22: 구동축 | B22: 160 | C22: 125

Sheet 기타작업-1
A1: 거래처별 출하 금액
A3: 거래처 | B3: 9월 | C3: 10월
A4: 대한기계 | B4: 28.8 | C4: 21.3
A5: 한빛정밀 | B5: 23.7 | C5: 16.5
A6: 서해산업 | B6: 11.2 | C6: 16.7
A7: 동양기공 | B7: 9.4 | C7: 12.8

Sheet 기타작업-2
A1: 매크로
A3: 거래처 | B3: 9월 | C3: 10월 | D3: 합계
A4: 대한기계 | B4: 28.8 | C4: 21.3
A5: 한빛정밀 | B5: 23.7 | C5: 16.5
A6: 서해산업 | B6: 11.2 | C6: 16.7
A7: 동양기공 | B7: 9.4 | C7: 12.8

Sheet 기타작업-3
A1: VBA 프로그래밍
A3: 출하일 | B3: 거래처 | C3: 제품 | D3: 수량
A4: 46296 | B4: 대한기계 | C4: 커플링 | D4: 610
A5: 46301 | B5: 한빛정밀 | C5: 밸브블록 | D5: 330

Sheet 채점표
A1: 채점표 — 1급 제2회 (자동 칸은 저절로, '스스로' 칸은 G열에 O / X)
A3: 작업 | B3: 문항 | C3: 배점 | D3: 방식 | E3: 점수 | F3: 확인 방법 | G3: O / X
A4: 기본작업-1 | B4: 1. 고급 필터 (결과 2행) | C4: 5 | D4: 자동 | E4: =IF(AND(SUMPRODUCT(--('기본작업-1'!$A$20:$D$22&""='채점표'!$AA$4:$AD$6&""))=12,COUNTA('기본작업-1'!$A$23:$D$23)=0),5,0) | F4: 자동 — A20 부터 필드 이름 + 2행 정확히 | AA4: 출하일 | AB4: 거래처 | AC4: 제품 | AD4: 수량
A5: 기본작업-1 | B5: 2. 조건부 서식 — S-001 · S-010 두 행만 굵은 파랑 — 수식 =AND($C4="대한기계",$F4>=10000000) | C5: 5 | D5: 스스로 | E5: =IF(G5="O",C5,0) | F5: [홈] → [조건부 서식] → [규칙 관리] 에서 수식 확인 | AA5: 46296 | AB5: 대한기계 | AC5: 커플링 | AD5: 610
A6: 기본작업-2 | B6: 3. 시트 보호 — 문제 조건 모두 | C6: 5 | D6: 스스로 | E6: =IF(G6="O",C6,0) | F6: A1 을 누를 수 없고 B4:E10 만 고칠 수 있음 · [검토] → [시트 보호 해제] 가 보임 | AA6: 46322 | AB6: 한빛정밀 | AC6: 커플링 | AD6: 700
A7: 계산작업 | B7: 1. [표1] 거래처·분기별 금액 [G3:G6] | C7: 6 | D7: 자동 | E7: =IF(COUNTIF('계산작업'!$AB$3:$AB$6,TRUE)=4,6,0) | F7: 자동 — 4칸 모두 맞아야 6점
A8: 계산작업 | B8: 2. [표2] 거래처별 최대 출하량 [F15:F17] | C8: 6 | D8: 자동 | E8: =IF(COUNTIF('계산작업'!$AB$15:$AB$17,TRUE)=3,6,0) | F8: 자동 — 3칸 모두 맞아야 6점 | AA8: 400 | AB8: 180
A9: 계산작업 | B9: 3. [표3] 운임 조회 [D27:D32] | C9: 6 | D9: 자동 | E9: =IF(COUNTIF('계산작업'!$AB$27:$AB$32,TRUE)=6,6,0) | F9: 자동 — 6칸 모두 맞아야 6점 | AA9: 160 | AB9: 124.66667
A10: 계산작업 | B10: 4. [표4] 제품별 평균 단가 [F37:F40] | C10: 6 | D10: 자동 | E10: =IF(COUNTIF('계산작업'!$AB$37:$AB$40,TRUE)=4,6,0) | F10: 자동 — 4칸 모두 맞아야 6점 | AA10: 300 | AB10: 98.5
A11: 계산작업 | B11: 5. [표5] 운송비 (사용자 정의 함수) [D47:D52] | C11: 6 | D11: 자동 | E11: =IF(COUNTIF('계산작업'!$AB$47:$AB$52,TRUE)=6,6,0) | F11: 자동 — 6칸 모두 맞아야 6점 (함수를 만든 뒤 =fn…() 로 계산한 결과로 채점) | AA11: 560 | AB11: 44.5
A12: 분석작업-1 | B12: 피벗 1) I3 에서 시작, 행이 '9월'·'10월' 두 줄, 열에 거래처 3곳 | C12: 4 | D12: 스스로 | E12: =IF(G12="O",C12,0) | F12: 피벗 표를 보고 확인 | AA12: 280 | AB12: 33.5
A13: 분석작업-1 | B13: 피벗 2) 9월 합계 63,710,000 · 10월 54,430,000 (쉼표 표시) | C13: 3 | D13: 스스로 | E13: =IF(G13="O",C13,0) | F13: 피벗 표를 보고 확인
A14: 분석작업-1 | B14: 피벗 3) 맨 아래 '총합계' 줄이 없고 오른쪽 '총합계' 열만 있음 | C14: 3 | D14: 스스로 | E14: =IF(G14="O",C14,0) | F14: 피벗 표를 보고 확인
A15: 분석작업-2 | B15: 통합 — 제품별 수량·금액 평균 [I4:J8] | C15: 10 | D15: 자동 | E15: =IF(SUMPRODUCT(--(ROUND('분석작업-2'!$I$4:$J$8,2)=ROUND('채점표'!$AA$8:$AB$12,2)))=10,10,0) | F15: 자동
A16: 기타작업-1 | B16: 차트 1) '동양기공' 데이터를 차트에서 제외하시오 | C16: 2 | D16: 스스로 | E16: =IF(G16="O",C16,0) | F16: 가로축에 거래처 3곳
A17: 기타작업-1 | B17: 차트 2) 차트 종류를 '누적 세로 막대형' 으로 바꾸시오 | C17: 2 | D17: 스스로 | E17: =IF(G17="O",C17,0) | F17: 막대가 위로 쌓임
A18: 기타작업-1 | B18: 차트 3) 세로(값) 축 제목 '금액(백만 원)' 을 '세로 제목' 으로 추가하시오 | C18: 2 | D18: 스스로 | E18: =IF(G18="O",C18,0) | F18: 왼쪽 세로 글자
A19: 기타작업-1 | B19: 차트 4) '10월' 계열에 '가운데' 데이터 레이블 '값' 을 표시하시오 | C19: 2 | D19: 스스로 | E19: =IF(G19="O",C19,0) | F19: 막대 안 가운데 숫자
A20: 기타작업-1 | B20: 차트 5) 범례를 '위쪽', 차트 영역 테두리 '둥근 모서리' 를 지정하시오 | C20: 2 | D20: 스스로 | E20: =IF(G20="O",C20,0) | F20: 범례가 차트 위
A21: 기타작업-2 | B21: 매크로 1) [D4:D7] 에 합계(9월+10월)를 SUM 으로 구하는 '합계' 매크로 — [F3:G4] 영역 단추(텍스트 '합계')에 연결 | C21: 5 | D21: 스스로 | E21: =IF(G21="O",C21,0) | F21: D4 에 =SUM(B4:C4)
A22: 기타작업-2 | B22: 매크로 2) [A3:D3] 영역에 셀 스타일 '강조색2' 를 적용하는 '스타일' 매크로 — [F6:G7] 영역 도형 '빗면'(텍스트 '스타일')에 연결 | C22: 5 | D22: 스스로 | E22: =IF(G22="O",C22,0) | F22: 머리글 줄 색이 바뀜
A23: 기타작업-3 | B23: VBA 1) [G3] 위치 단추(텍스트 '출하 등록')에, InputBox 로 거래처·제품·수량을 받아 표 마지막 다음 줄에 넣고 출하일은 오늘 날짜로 넣는 '출하등록' 프로시저를 연결하시오. | C23: 5 | D23: 스스로 | E23: =IF(G23="O",C23,0) | F23: 6행에 새 줄
A24: 기타작업-3 | B24: VBA 2) 수량을 넣을 때 500 이상이면 '대량 출하입니다' 메시지가 뜨도록 '출하등록' 에 If 문을 덧붙이시오. | C24: 5 | D24: 스스로 | E24: =IF(G24="O",C24,0) | F24: 500 넣으면 메시지
A25: 기타작업-3 | B25: VBA 3) 통합 문서를 열 때(Workbook_Open) '출하 관리를 시작합니다' 메시지가 뜨게 하시오. | C25: 5 | D25: 스스로 | E25: =IF(G25="O",C25,0) | F25: 현재_통합_문서(ThisWorkbook) 모듈에 작성, 저장 후 다시 열면 메시지
B27: 합계 (100점 만점 · 70점 이상 합격) | E27: =SUM(E4:E25) | F27: =IF(E27>=70,"🎉 합격","불합격 — 틀린 작업의 [정답·해설]을 보세요")
A29: '스스로' 문항은 [확인 방법] 을 보고 실제로 그렇게 되어 있으면 O. 한 군데라도 다르면 X (실제 시험은 부분 점수 없음).

Sheet 정답·해설
A1: 정답·해설 — 1급 제2회 (먼저 끝까지 풀고 보세요)
A3: 작업 | B3: 무엇을 | C3: 어떻게 · 정답
A4: 기본작업-1 | B4: 고급 필터 | C4: A17 에 원본에 없는 이름(예: '조건') 또는 비워 두고, A18 에 =AND(MONTH(A4)=10,E4>=AVERAGE($E$4:$E$15)) → [고급] 조건 범위 A17:A18, 복사 위치 A20:D20 (필드 이름 미리 입력)
A5: 기본작업-1 | B5: 조건부 서식 | C5: S-001 · S-010 두 행만 굵은 파랑 — 수식 =AND($C4="대한기계",$F4>=10000000)
A6: 기본작업-2 | B6: 시트 보호 | C6: A1 을 누를 수 없고 B4:E10 만 고칠 수 있음 · [검토] → [시트 보호 해제] 가 보임
A7: 계산작업 | B7: 1. [표1] 거래처·분기별 금액 → [G3:G6] | C7: =SUMIFS($C$3:$C$10,$A$3:$A$10,E3,$B$3:$B$10,F3) (첫 칸에 넣고 끝까지 끌어내리기)
A8: 계산작업 | B8: 2. [표2] 거래처별 최대 출하량 → [F15:F17] | C8: =MAX(IF($A$15:$A$22=E15,$C$15:$C$22)) {배열: Ctrl+Shift+Enter} (첫 칸에 넣고 끝까지 끌어내리기)
A9: 계산작업 | B9: 3. [표3] 운임 조회 → [D27:D32] | C9: =VLOOKUP(B27,$F$27:$I$30,MATCH(C27,$F$26:$I$26,0),FALSE) (첫 칸에 넣고 끝까지 끌어내리기)
A10: 계산작업 | B10: 4. [표4] 제품별 평균 단가 → [F37:F40] | C10: =IFERROR(ROUND(AVERAGEIFS($C$37:$C$42,$A$37:$A$42,E37,$B$37:$B$42,"A"),-3),"없음") (첫 칸에 넣고 끝까지 끌어내리기)
A11: 계산작업 | B11: 5. [표5] 운송비 (사용자 정의 함수) | C11: [개발 도구] → [Visual Basic] → [삽입] → [모듈] 에 입력: Public Function fn운송비(중량, 거리) If 중량 <= 100 Then fn운송비 = 거리 * 500 Else fn운송비 = 거리 * 800 End If End Function 그다음 D47 에 =fn운송비(B47,C47) 를 넣고 D52 까지 끌어내리기
A12: 분석작업-1 | B12: 피벗 테이블 | C12: 표 안 → [삽입] → [피벗 테이블] → 기존 워크시트 I3 출하일 → 행, 거래처 → 열, 금액 → 값 행의 날짜 하나 오른쪽 클릭 → [그룹] → '월' 만 선택 값 필드 설정 → 표시 형식 숫자·쉼표 [디자인] → [총합계] → '행의 총합계만 설정'
A13: 분석작업-2 | B13: [분석작업-2] 시트에서 [표1]~[표3] 세 달의 제품별 '수량' 과 '금액' 의 평균을 [H4:J8] 에 통합하시오. | C13: H3:J8 (머리글 포함) 선택 → [데이터] → [통합] 함수 '평균', 참조에 세 표를 머리글까지 각각 [추가] '첫 행' · '왼쪽 열' 체크 → 확인
A14: 기타작업-3 | B14: 1) [G3] 위치 단추 | C14: Sub 출하등록() Dim r As Long r = Range("A3").CurrentRegion.Rows.Count + 3 Cells(r, 1) = Date Cells(r, 2) = InputBox("거래처") Cells(r, 3) = InputBox("제품") Cells(r, 4) = Val(InputBox("수량")) End Sub
... A21: 기타작업-1 | B21: 5) 범례를 '위쪽', 차트 영역 테두리 '둥근 모서리' 를 지정하시오 | C21: 범례가 차트 위
