Workbook

Sheet 읽어보기
B2: 컴활 1급 실기 실전 모의고사 제3회 — 설비 가동
B3: 1급 스프레드시트 실무와 같은 시트 이름 · 같은 배점입니다. 시간 45분, 70점 이상이면 합격.
B4: 순서
B5: ① [문제지] 시트를 읽고 → 각 작업 시트에서 풉니다.
B6: ② 계산작업 노란 칸의 0 을 지우고 첫 칸에 수식 → 끝까지 끌어내리기. 배열 수식은 Ctrl + Shift + Enter.
B7: ③ 계산작업 5번은 사용자 정의 함수 — [개발 도구] → [Visual Basic] → 모듈에 Function 을 만들고 =fn…() 로 계산합니다.
B8: ④ 다 풀면 [채점표] — 자동 칸은 저절로, '스스로' 칸은 [확인 방법] 을 보고 O / X.
B9: 함수·매크로·VBA 가 들어가면 '다른 이름으로 저장' → Excel 매크로 사용 통합 문서(*.xlsm). 그냥 저장하면 코드가 사라집니다.
B10: [개발 도구] 탭이 없으면 [파일] → [옵션] → [리본 사용자 지정] 에서 '개발 도구' 체크.

Sheet 문제지
A1: 컴퓨터활용능력 1급 실기 · 스프레드시트 실무 · 실전 모의고사 제3회 (설비 가동)
A2: 시험 시간 45분 · 100점 만점 · 70점 이상 합격. 시작 [ : ] 끝 [ : ] 사용자 정의 함수·매크로·VBA 를 넣었으면 Excel 매크로 사용 통합 문서(*.xlsm)로 저장하세요.
A4: 기본작업-1 · 10점
B5: 1. | C5: [A3:F15] 영역에서 구분이 '프레스' 이거나 가동률이 75% 미만인 행의 '설비코드', '설비명', '가동률' 열만 고급 필터로 추출하시오. · 조건은 [A17:B19] 영역에 입력 · 결과는 [A21] 셀부터 표시
B6: 2. | C6: [A4:F15] 영역에서 가동률이 상위 3위 이내인 행 전체에 채우기 색 '연한 녹색' 을 적용하시오. · LARGE 함수를 사용한 수식으로 조건 지정
A7: 기본작업-2 · 5점
B8: 3. | C8: [기본작업-2] 시트를 다음과 같이 설정하시오. · [A1:F20] 만 인쇄 영역 · 머리글 오른쪽에 현재 날짜 · 행/열 머리글(1 2 3, A B C) 도 인쇄 · 페이지 나누기 미리 보기로 보기
A9: 계산작업 · 30점 (각 6점)
B10: 1. | C10: [표1]에서 구분[A3:A10]과 라인[B3:B10]이 E·F열과 같은 가동시간[C3:C10]의 평균을 소수 첫째 자리에서 올림하여 정수로 평균[G3:G5]에 표시하시오. → [G3:G5]
B11: 2. | C11: [표2]에서 구분[A15:A22]이 E열과 같으면서 가동률[C15:C22]이 90% 이상인 설비 수를 [F15:F17]에 구하시오. (SUM 함수를 이용한 배열 수식) → [F15:F17] ※ Ctrl+Shift+Enter
B12: 3. | C12: [표3]에서 가동률[B27:B32]을 오른쪽 가로 등급표(F:I열, 기준값 이상인 구간)에서 찾아 등급[C27:C32]에 표시하시오. (HLOOKUP 함수) → [C27:C32]
B13: 4. | C13: [표4]에서 설비코드[A37:A42]의 앞 두 글자를 대문자로 바꾸고 "-" 와 코드의 마지막 세 글자를 이어 표시코드[C37:C42]에 표시하시오. (예: pr2019007 → PR-007) → [C37:C42]
B14: 5. | C14: [표5]에서 사용자 정의 함수 'fn점검' 을 작성하여 점검[C47:C52]을 표시하시오. fn점검은 월 가동시간을 인수로 받아, 180 이상이면 "정밀점검", 120 이상이면 "일반점검", 그 외는 "생략" 을 돌려준다. (Select Case 문 사용 · Public Function fn점검(가동시간)) → [C47:C52]
A15: 분석작업-1 · 10점
C16: [분석작업-1] 시트의 표로 피벗 테이블을 만드시오. · 행: 구분 · 값: 가동시간의 평균, 가동률의 평균 · 위치 [I3] · 가동시간 평균은 소수 1자리, 가동률 평균은 '백분율' 소수 1자리 · 가동률 평균 기준 내림차순 정렬
A17: 분석작업-2 · 10점
C18: [분석작업-2] 시트의 [A3:E20] 표에서 '설비코드' 와 '점검일' 이 같은 중복 행을 [중복된 항목 제거] 로 지우시오.
A19: 기타작업-1 · 10점 (각 2점)
C20: [기타작업-1] 시트의 차트(묶은 세로 막대 · 가동시간·계획시간)를 다음과 같이 고치시오. (각 2점)
B21: 1) | C21: 차트 종류를 '묶은 가로 막대형' 으로 바꾸고 세로(항목) 축을 '항목을 거꾸로' 표시하시오
B22: 2) | C22: '계획시간' 계열의 채우기를 '채우기 없음', 테두리 '실선' 으로 바꾸시오
B23: 3) | C23: 계열 겹치기 100%, 간격 너비 60% 로 지정하시오
B24: 4) | C24: 차트 제목 '구분별 가동 현황' · 글꼴 굵게 14pt
B25: 5) | C25: '가동시간' 계열에 데이터 레이블 '안쪽 끝에' 표시하시오
A26: 기타작업-2 · 10점 (각 5점)
C27: [기타작업-2] 시트에서 다음 두 매크로를 만들고 연결하시오. (각 5점 · 저장은 .xlsm)
B28: 1) | C28: [D4:D8] 에 가동률(가동시간÷계획시간)을 구하는 '가동률' 매크로 — [F3:G4] 영역 단추(텍스트 '가동률')에 연결
B29: 2) | C29: [D4:D8] 에 조건부 서식 '데이터 막대 — 그라데이션 채우기 파랑' 을 적용하는 '막대' 매크로 — [F6:G7] 영역 단추(텍스트 '막대')에 연결
A30: 기타작업-3 · 15점 (각 5점)
C31: [기타작업-3] 시트에서 다음과 같이 프로그래밍하시오. (각 5점) ※ 실제 시험은 미리 만든 사용자 폼(입력 폼)을 쓰지만, 이 연습 파일에는 폼을 넣을 수 없어 단추·InputBox·이벤트로 같은 문법을 연습합니다.
B32: 1) | C32: [G3] 위치 단추(텍스트 '점검 등록')에, InputBox 로 설비코드·구분·비용을 받아 표 마지막 다음 줄에 넣고 점검일은 오늘 날짜로 넣는 '점검등록' 프로시저를 연결하시오.
B33: 2) | C33: 구분이 '고장' 이면 그 줄의 글꼴 색을 빨강(vbRed)으로 바꾸도록 '점검등록' 에 덧붙이시오.
B34: 3) | C34: [G6] 위치 단추(텍스트 '비용 합계')에, D열 비용 합계를 '총 점검 비용: 360,000원' 처럼 메시지로 보여 주는 '비용합계' 프로시저를 연결하시오.

Sheet 기본작업-1
A1: 기본작업-1
A3: 설비코드 | B3: 설비명 | C3: 구분 | D3: 가동시간 | E3: 계획시간 | F3: 가동률
A4: PR-101 | B4: 유압프레스1 | C4: 프레스 | D4: 186 | E4: 200 | F4: 0.93
A5: PR-102 | B5: 유압프레스2 | C5: 프레스 | D5: 150 | E5: 200 | F5: 0.75
A6: WD-201 | B6: 스폿용접기 | C6: 용접 | D6: 170 | E6: 200 | F6: 0.85
A7: WD-202 | B7: 아크용접기 | C7: 용접 | D7: 140 | E7: 200 | F7: 0.7
A8: CN-301 | B8: CNC선반 | C8: 가공 | D8: 190 | E8: 200 | F8: 0.95
A9: CN-302 | B9: 머시닝센터 | C9: 가공 | D9: 155 | E9: 200 | F9: 0.775
A10: RB-401 | B10: 조립로봇1 | C10: 조립 | D10: 196 | E10: 200 | F10: 0.98
A11: RB-402 | B11: 조립로봇2 | C11: 조립 | D11: 162 | E11: 200 | F11: 0.81
A12: CV-501 | B12: 컨베이어 | C12: 이송 | D12: 200 | E12: 200 | F12: 1
A13: AC-601 | B13: 공기압축기 | C13: 유틸 | D13: 120 | E13: 200 | F13: 0.6
A14: PR-103 | B14: 단동프레스 | C14: 프레스 | D14: 178 | E14: 200 | F14: 0.89
A15: CN-303 | B15: 밀링 | C15: 가공 | D15: 140 | E15: 200 | F15: 0.7

Sheet 기본작업-2
A1: 기본작업-2 (페이지 레이아웃)
A3: 설비코드 | B3: 설비명 | C3: 구분 | D3: 가동시간 | E3: 계획시간 | F3: 가동률
A4: PR-101 | B4: 유압프레스1 | C4: 프레스 | D4: 186 | E4: 200 | F4: 0.93
A5: PR-102 | B5: 유압프레스2 | C5: 프레스 | D5: 150 | E5: 200 | F5: 0.75
A6: WD-201 | B6: 스폿용접기 | C6: 용접 | D6: 170 | E6: 200 | F6: 0.85
A7: WD-202 | B7: 아크용접기 | C7: 용접 | D7: 140 | E7: 200 | F7: 0.7
A8: CN-301 | B8: CNC선반 | C8: 가공 | D8: 190 | E8: 200 | F8: 0.95
A9: CN-302 | B9: 머시닝센터 | C9: 가공 | D9: 155 | E9: 200 | F9: 0.775
A10: RB-401 | B10: 조립로봇1 | C10: 조립 | D10: 196 | E10: 200 | F10: 0.98
A11: RB-402 | B11: 조립로봇2 | C11: 조립 | D11: 162 | E11: 200 | F11: 0.81
A12: CV-501 | B12: 컨베이어 | C12: 이송 | D12: 200 | E12: 200 | F12: 1
A13: AC-601 | B13: 공기압축기 | C13: 유틸 | D13: 120 | E13: 200 | F13: 0.6
A14: PR-103 | B14: 단동프레스 | C14: 프레스 | D14: 178 | E14: 200 | F14: 0.89
A15: CN-303 | B15: 밀링 | C15: 가공 | D15: 140 | E15: 200 | F15: 0.7
... A43: WD-202 | B43: 아크용접기 | C43: 용접 | D43: 140 | E43: 200 | F43: 0.7

Sheet 계산작업
A1: [표1] 구분별 평균 가동시간
A2: 구분 | B2: 라인 | C2: 가동시간 | E2: 구분 | F2: 라인 | G2: 평균
A3: 프레스 | B3: 1 | C3: 186 | E3: 프레스 | F3: 1 | G3: 0 | AA3: =ROUNDUP(AVERAGEIFS($C$3:$C$10,$A$3:$A$10,E3,$B$3:$B$10,F3),0) | AB3: =AND(_xlfn.ISFORMULA(G3),IFERROR(ROUND(G3,4)=ROUND(AA3,4),EXACT(G3,AA3)))
A4: 용접 | B4: 1 | C4: 170 | E4: 프레스 | F4: 2 | G4: 0 | AA4: =ROUNDUP(AVERAGEIFS($C$3:$C$10,$A$3:$A$10,E4,$B$3:$B$10,F4),0) | AB4: =AND(_xlfn.ISFORMULA(G4),IFERROR(ROUND(G4,4)=ROUND(AA4,4),EXACT(G4,AA4)))
A5: 프레스 | B5: 2 | C5: 150 | E5: 가공 | F5: 1 | G5: 0 | AA5: =ROUNDUP(AVERAGEIFS($C$3:$C$10,$A$3:$A$10,E5,$B$3:$B$10,F5),0) | AB5: =AND(_xlfn.ISFORMULA(G5),IFERROR(ROUND(G5,4)=ROUND(AA5,4),EXACT(G5,AA5)))
A6: 가공 | B6: 1 | C6: 190
A7: 프레스 | B7: 1 | C7: 178
A8: 가공 | B8: 1 | C8: 155
A9: 용접 | B9: 2 | C9: 140
A10: 프레스 | B10: 2 | C10: 161
A13: [표2] 구분별 목표 달성 설비 수
A14: 구분 | B14: 설비 | C14: 가동률 | E14: 구분 | F14: 90% 이상
A15: 프레스 | B15: PR1 | C15: 0.93 | E15: 프레스 | F15: 0 | AA15: {=SUM(($A$15:$A$22=E15)*($C$15:$C$22>=0.9))} | AB15: =AND(_xlfn.ISFORMULA(F15),IFERROR(ROUND(F15,4)=ROUND(AA15,4),EXACT(F15,AA15)))
A16: 용접 | B16: WD1 | C16: 0.85 | E16: 용접 | F16: 0 | AA16: {=SUM(($A$15:$A$22=E16)*($C$15:$C$22>=0.9))} | AB16: =AND(_xlfn.ISFORMULA(F16),IFERROR(ROUND(F16,4)=ROUND(AA16,4),EXACT(F16,AA16)))
A17: 프레스 | B17: PR2 | C17: 0.9 | E17: 가공 | F17: 0 | AA17: {=SUM(($A$15:$A$22=E17)*($C$15:$C$22>=0.9))} | AB17: =AND(_xlfn.ISFORMULA(F17),IFERROR(ROUND(F17,4)=ROUND(AA17,4),EXACT(F17,AA17)))
A18: 가공 | B18: CN1 | C18: 0.95
A19: 가공 | B19: CN2 | C19: 0.78
A20: 용접 | B20: WD2 | C20: 0.91
A21: 프레스 | B21: PR3 | C21: 0.89
A22: 가공 | B22: CN3 | C22: 0.97
A25: [표3] 가동률 등급
A26: 설비 | B26: 가동률 | C26: 등급 | E26: 가동률 | F26: 0 | G26: 0.7 | H26: 0.8 | I26: 0.9
A27: PR1 | B27: 0.93 | C27: 0 | E27: 등급 | F27: D | G27: C | H27: B | I27: A | AA27: =HLOOKUP(B27,$F$26:$I$27,2,TRUE) | AB27: =AND(_xlfn.ISFORMULA(C27),IFERROR(ROUND(C27,4)=ROUND(AA27,4),EXACT(C27,AA27)))
A28: PR2 | B28: 0.7 | C28: 0 | AA28: =HLOOKUP(B28,$F$26:$I$27,2,TRUE) | AB28: =AND(_xlfn.ISFORMULA(C28),IFERROR(ROUND(C28,4)=ROUND(AA28,4),EXACT(C28,AA28)))
A29: WD1 | B29: 0.69 | C29: 0 | AA29: =HLOOKUP(B29,$F$26:$I$27,2,TRUE) | AB29: =AND(_xlfn.ISFORMULA(C29),IFERROR(ROUND(C29,4)=ROUND(AA29,4),EXACT(C29,AA29)))
A30: CN1 | B30: 0.8 | C30: 0 | AA30: =HLOOKUP(B30,$F$26:$I$27,2,TRUE) | AB30: =AND(_xlfn.ISFORMULA(C30),IFERROR(ROUND(C30,4)=ROUND(AA30,4),EXACT(C30,AA30)))
A31: CN2 | B31: 0.99 | C31: 0 | AA31: =HLOOKUP(B31,$F$26:$I$27,2,TRUE) | AB31: =AND(_xlfn.ISFORMULA(C31),IFERROR(ROUND(C31,4)=ROUND(AA31,4),EXACT(C31,AA31)))
A32: AC1 | B32: 0.45 | C32: 0 | AA32: =HLOOKUP(B32,$F$26:$I$27,2,TRUE) | AB32: =AND(_xlfn.ISFORMULA(C32),IFERROR(ROUND(C32,4)=ROUND(AA32,4),EXACT(C32,AA32)))
A35: [표4] 설비 코드 줄여 쓰기
A36: 설비코드 | B36: 도입연도 | C36: 표시코드
A37: pr2019007 | B37: 2019 | C37: 0 | AA37: =UPPER(LEFT(A37,2))&"-"&RIGHT(A37,3) | AB37: =AND(_xlfn.ISFORMULA(C37),IFERROR(ROUND(C37,4)=ROUND(AA37,4),EXACT(C37,AA37)))
A38: wd2021113 | B38: 2021 | C38: 0 | AA38: =UPPER(LEFT(A38,2))&"-"&RIGHT(A38,3) | AB38: =AND(_xlfn.ISFORMULA(C38),IFERROR(ROUND(C38,4)=ROUND(AA38,4),EXACT(C38,AA38)))
A39: cn2018042 | B39: 2018 | C39: 0 | AA39: =UPPER(LEFT(A39,2))&"-"&RIGHT(A39,3) | AB39: =AND(_xlfn.ISFORMULA(C39),IFERROR(ROUND(C39,4)=ROUND(AA39,4),EXACT(C39,AA39)))
A40: rb2024009 | B40: 2024 | C40: 0 | AA40: =UPPER(LEFT(A40,2))&"-"&RIGHT(A40,3) | AB40: =AND(_xlfn.ISFORMULA(C40),IFERROR(ROUND(C40,4)=ROUND(AA40,4),EXACT(C40,AA40)))
A41: ac2012300 | B41: 2012 | C41: 0 | AA41: =UPPER(LEFT(A41,2))&"-"&RIGHT(A41,3) | AB41: =AND(_xlfn.ISFORMULA(C41),IFERROR(ROUND(C41,4)=ROUND(AA41,4),EXACT(C41,AA41)))
A42: cv2020051 | B42: 2020 | C42: 0 | AA42: =UPPER(LEFT(A42,2))&"-"&RIGHT(A42,3) | AB42: =AND(_xlfn.ISFORMULA(C42),IFERROR(ROUND(C42,4)=ROUND(AA42,4),EXACT(C42,AA42)))
A45: [표5] 점검 구분 (사용자 정의 함수)
A46: 설비 | B46: 월 가동시간 | C46: 점검
A47: PR1 | B47: 186 | C47: 0 | AA47: =IF(B47>=180,"정밀점검",IF(B47>=120,"일반점검","생략")) | AB47: =AND(_xlfn.ISFORMULA(C47),IFERROR(ROUND(C47,4)=ROUND(AA47,4),EXACT(C47,AA47)))
A48: PR2 | B48: 180 | C48: 0 | AA48: =IF(B48>=180,"정밀점검",IF(B48>=120,"일반점검","생략")) | AB48: =AND(_xlfn.ISFORMULA(C48),IFERROR(ROUND(C48,4)=ROUND(AA48,4),EXACT(C48,AA48)))
...

Sheet 분석작업-1
A1: 분석작업-1
A3: 설비코드 | B3: 설비명 | C3: 구분 | D3: 가동시간 | E3: 계획시간 | F3: 가동률
A4: PR-101 | B4: 유압프레스1 | C4: 프레스 | D4: 186 | E4: 200 | F4: 0.93
A5: PR-102 | B5: 유압프레스2 | C5: 프레스 | D5: 150 | E5: 200 | F5: 0.75
A6: WD-201 | B6: 스폿용접기 | C6: 용접 | D6: 170 | E6: 200 | F6: 0.85
A7: WD-202 | B7: 아크용접기 | C7: 용접 | D7: 140 | E7: 200 | F7: 0.7
A8: CN-301 | B8: CNC선반 | C8: 가공 | D8: 190 | E8: 200 | F8: 0.95
A9: CN-302 | B9: 머시닝센터 | C9: 가공 | D9: 155 | E9: 200 | F9: 0.775
A10: RB-401 | B10: 조립로봇1 | C10: 조립 | D10: 196 | E10: 200 | F10: 0.98
A11: RB-402 | B11: 조립로봇2 | C11: 조립 | D11: 162 | E11: 200 | F11: 0.81
A12: CV-501 | B12: 컨베이어 | C12: 이송 | D12: 200 | E12: 200 | F12: 1
A13: AC-601 | B13: 공기압축기 | C13: 유틸 | D13: 120 | E13: 200 | F13: 0.6
A14: PR-103 | B14: 단동프레스 | C14: 프레스 | D14: 178 | E14: 200 | F14: 0.89
A15: CN-303 | B15: 밀링 | C15: 가공 | D15: 140 | E15: 200 | F15: 0.7

Sheet 분석작업-2
A1: 설비 점검 기록
A3: 설비코드 | B3: 점검일 | C3: 점검자 | D3: 구분 | E3: 비용
A4: PR-101 | B4: 46266 | C4: 김도윤 | D4: 정기 | E4: 120000
A5: WD-201 | B5: 46266 | C5: 이서연 | D5: 정기 | E5: 80000
A6: PR-101 | B6: 46266 | C6: 김도윤 | D6: 정기 | E6: 120000
A7: CN-301 | B7: 46267 | C7: 박지훈 | D7: 고장 | E7: 240000
A8: RB-401 | B8: 46268 | C8: 최하은 | D8: 정기 | E8: 60000
A9: WD-201 | B9: 46266 | C9: 정민재 | D9: 정기 | E9: 80000
A10: CN-301 | B10: 46274 | C10: 박지훈 | D10: 정기 | E10: 90000
A11: PR-102 | B11: 46275 | C11: 김도윤 | D11: 고장 | E11: 210000
A12: RB-401 | B12: 46268 | C12: 최하은 | D12: 정기 | E12: 60000
A13: CV-501 | B13: 46276 | C13: 한수아 | D13: 정기 | E13: 30000
A14: PR-102 | B14: 46277 | C14: 오지성 | D14: 정기 | E14: 45000
A15: CN-301 | B15: 46267 | C15: 박지훈 | D15: 고장 | E15: 240000
... A20: RB-402 | B20: 46283 | C20: 최하은 | D20: 고장 | E20: 95000

Sheet 기타작업-1
A1: 구분별 가동 현황
A3: 구분 | B3: 가동시간 | C3: 계획시간
A4: 프레스 | B4: 514 | C4: 600
A5: 용접 | B5: 310 | C5: 400
A6: 가공 | B6: 485 | C6: 600
A7: 조립 | B7: 358 | C7: 400
A8: 이송 | B8: 200 | C8: 200

Sheet 기타작업-2
A1: 매크로
A3: 설비코드 | B3: 가동시간 | C3: 계획시간 | D3: 가동률
A4: PR-101 | B4: 186 | C4: 200
A5: WD-201 | B5: 170 | C5: 200
A6: CN-301 | B6: 190 | C6: 200
A7: RB-401 | B7: 196 | C7: 200
A8: AC-601 | B8: 120 | C8: 200

Sheet 기타작업-3
A1: VBA 프로그래밍
A3: 설비코드 | B3: 점검일 | C3: 구분 | D3: 비용
A4: PR-101 | B4: 46266 | C4: 정기 | D4: 120000
A5: CN-301 | B5: 46267 | C5: 고장 | D5: 240000

Sheet 채점표
A1: 채점표 — 1급 제3회 (자동 칸은 저절로, '스스로' 칸은 G열에 O / X)
A3: 작업 | B3: 문항 | C3: 배점 | D3: 방식 | E3: 점수 | F3: 확인 방법 | G3: O / X
A4: 기본작업-1 | B4: 1. 고급 필터 (결과 6행) | C4: 5 | D4: 자동 | E4: =IF(AND(SUMPRODUCT(--('기본작업-1'!$A$21:$C$27&""='채점표'!$AA$4:$AC$10&""))=21,COUNTA('기본작업-1'!$A$28:$C$28)=0),5,0) | F4: 자동 — A21 부터 필드 이름 + 6행 정확히 | AA4: 설비코드 | AB4: 설비명 | AC4: 가동률
A5: 기본작업-1 | B5: 2. 조건부 서식 — CV-501 · RB-401 · CN-301 세 행 — 수식 =$F4>=LARGE($F$4:$F$15,3) | C5: 5 | D5: 스스로 | E5: =IF(G5="O",C5,0) | F5: [홈] → [조건부 서식] → [규칙 관리] 에서 수식 확인 | AA5: PR-101 | AB5: 유압프레스1 | AC5: 0.93
A6: 기본작업-2 | B6: 3. 페이지 레이아웃 — 문제 조건 모두 | C6: 5 | D6: 스스로 | E6: =IF(G6="O",C6,0) | F6: [페이지 레이아웃] → 인쇄 영역 A1:F20, 머리글 오른쪽 &[날짜], [시트] 탭 '행/열 머리글' 체크, [보기] 페이지 나누기 미리 보기 | AA6: PR-102 | AB6: 유압프레스2 | AC6: 0.75
A7: 계산작업 | B7: 1. [표1] 구분별 평균 가동시간 [G3:G5] | C7: 6 | D7: 자동 | E7: =IF(COUNTIF('계산작업'!$AB$3:$AB$5,TRUE)=3,6,0) | F7: 자동 — 3칸 모두 맞아야 6점 | AA7: WD-202 | AB7: 아크용접기 | AC7: 0.7
A8: 계산작업 | B8: 2. [표2] 구분별 목표 달성 설비 수 [F15:F17] | C8: 6 | D8: 자동 | E8: =IF(COUNTIF('계산작업'!$AB$15:$AB$17,TRUE)=3,6,0) | F8: 자동 — 3칸 모두 맞아야 6점 | AA8: AC-601 | AB8: 공기압축기 | AC8: 0.6
A9: 계산작업 | B9: 3. [표3] 가동률 등급 [C27:C32] | C9: 6 | D9: 자동 | E9: =IF(COUNTIF('계산작업'!$AB$27:$AB$32,TRUE)=6,6,0) | F9: 자동 — 6칸 모두 맞아야 6점 | AA9: PR-103 | AB9: 단동프레스 | AC9: 0.89
A10: 계산작업 | B10: 4. [표4] 설비 코드 줄여 쓰기 [C37:C42] | C10: 6 | D10: 자동 | E10: =IF(COUNTIF('계산작업'!$AB$37:$AB$42,TRUE)=6,6,0) | F10: 자동 — 6칸 모두 맞아야 6점 | AA10: CN-303 | AB10: 밀링 | AC10: 0.7
A11: 계산작업 | B11: 5. [표5] 점검 구분 (사용자 정의 함수) [C47:C52] | C11: 6 | D11: 자동 | E11: =IF(COUNTIF('계산작업'!$AB$47:$AB$52,TRUE)=6,6,0) | F11: 자동 — 6칸 모두 맞아야 6점 (함수를 만든 뒤 =fn…() 로 계산한 결과로 채점)
A12: 분석작업-1 | B12: 피벗 1) I3 에서 시작, 행에 구분 6개 | C12: 3 | D12: 스스로 | E12: =IF(G12="O",C12,0) | F12: 피벗 표를 보고 확인 | AA12: PR-101
A13: 분석작업-1 | B13: 피벗 2) 표시 형식: 가동시간 평균 소수 1자리 · 가동률 평균 % | C13: 3 | D13: 스스로 | E13: =IF(G13="O",C13,0) | F13: 피벗 표를 보고 확인 | AA13: WD-201
A14: 분석작업-1 | B14: 피벗 3) 맨 위가 '이송'(100.0%), 그다음 '조립'(89.5%) — 가동률 내림차순 | C14: 4 | D14: 스스로 | E14: =IF(G14="O",C14,0) | F14: 피벗 표를 보고 확인 | AA14: CN-301
A15: 분석작업-2 | B15: 중복된 항목 제거 — 남은 12행 (5행 제거) | C15: 10 | D15: 자동 | E15: =IF(AND(COUNTA('분석작업-2'!$A$4:$A$30)=12,SUMPRODUCT(--('분석작업-2'!$A$4:$A$15='채점표'!$AA$12:$AA$23))=12),10,0) | F15: 자동 | AA15: RB-401
A16: 기타작업-1 | B16: 차트 1) 차트 종류를 '묶은 가로 막대형' 으로 바꾸고 세로(항목) 축을 '항목을 거꾸로' 표시하시오 | C16: 2 | D16: 스스로 | E16: =IF(G16="O",C16,0) | F16: 프레스가 맨 위 | AA16: CN-301
A17: 기타작업-1 | B17: 차트 2) '계획시간' 계열의 채우기를 '채우기 없음', 테두리 '실선' 으로 바꾸시오 | C17: 2 | D17: 스스로 | E17: =IF(G17="O",C17,0) | F17: 빈 테두리 막대 | AA17: PR-102
A18: 기타작업-1 | B18: 차트 3) 계열 겹치기 100%, 간격 너비 60% 로 지정하시오 | C18: 2 | D18: 스스로 | E18: =IF(G18="O",C18,0) | F18: 두 막대가 포개짐 | AA18: CV-501
A19: 기타작업-1 | B19: 차트 4) 차트 제목 '구분별 가동 현황' · 글꼴 굵게 14pt | C19: 2 | D19: 스스로 | E19: =IF(G19="O",C19,0) | F19: 위쪽 제목 | AA19: PR-102
A20: 기타작업-1 | B20: 차트 5) '가동시간' 계열에 데이터 레이블 '안쪽 끝에' 표시하시오 | C20: 2 | D20: 스스로 | E20: =IF(G20="O",C20,0) | F20: 막대 안 끝에 숫자 | AA20: AC-601
A21: 기타작업-2 | B21: 매크로 1) [D4:D8] 에 가동률(가동시간÷계획시간)을 구하는 '가동률' 매크로 — [F3:G4] 영역 단추(텍스트 '가동률')에 연결 | C21: 5 | D21: 스스로 | E21: =IF(G21="O",C21,0) | F21: D4 에 =B4/C4 | AA21: WD-202
A22: 기타작업-2 | B22: 매크로 2) [D4:D8] 에 조건부 서식 '데이터 막대 — 그라데이션 채우기 파랑' 을 적용하는 '막대' 매크로 — [F6:G7] 영역 단추(텍스트 '막대')에 연결 | C22: 5 | D22: 스스로 | E22: =IF(G22="O",C22,0) | F22: 칸 안에 파란 막대 | AA22: PR-101
A23: 기타작업-3 | B23: VBA 1) [G3] 위치 단추(텍스트 '점검 등록')에, InputBox 로 설비코드·구분·비용을 받아 표 마지막 다음 줄에 넣고 점검일은 오늘 날짜로 넣는 '점검등록' 프로시저를 연결하시오. | C23: 5 | D23: 스스로 | E23: =IF(G23="O",C23,0) | F23: 6행에 새 줄 | AA23: RB-402
A24: 기타작업-3 | B24: VBA 2) 구분이 '고장' 이면 그 줄의 글꼴 색을 빨강(vbRed)으로 바꾸도록 '점검등록' 에 덧붙이시오. | C24: 5 | D24: 스스로 | E24: =IF(G24="O",C24,0) | F24: 고장 입력 줄이 빨강
A25: 기타작업-3 | B25: VBA 3) [G6] 위치 단추(텍스트 '비용 합계')에, D열 비용 합계를 '총 점검 비용: 360,000원' 처럼 메시지로 보여 주는 '비용합계' 프로시저를 연결하시오. | C25: 5 | D25: 스스로 | E25: =IF(G25="O",C25,0) | F25: 누르면 합계 메시지
B27: 합계 (100점 만점 · 70점 이상 합격) | E27: =SUM(E4:E25) | F27: =IF(E27>=70,"🎉 합격","불합격 — 틀린 작업의 [정답·해설]을 보세요")
A29: '스스로' 문항은 [확인 방법] 을 보고 실제로 그렇게 되어 있으면 O. 한 군데라도 다르면 X (실제 시험은 부분 점수 없음).

Sheet 정답·해설
A1: 정답·해설 — 1급 제3회 (먼저 끝까지 풀고 보세요)
A3: 작업 | B3: 무엇을 | C3: 어떻게 · 정답
A4: 기본작업-1 | B4: 고급 필터 | C4: A17 '구분' · B17 '가동률' / A18 '프레스' / B19 '<0.75' (다른 줄 = 또는) → 복사 위치 A21:C21
A5: 기본작업-1 | B5: 조건부 서식 | C5: CV-501 · RB-401 · CN-301 세 행 — 수식 =$F4>=LARGE($F$4:$F$15,3)
A6: 기본작업-2 | B6: 페이지 레이아웃 | C6: [페이지 레이아웃] → 인쇄 영역 A1:F20, 머리글 오른쪽 &[날짜], [시트] 탭 '행/열 머리글' 체크, [보기] 페이지 나누기 미리 보기
A7: 계산작업 | B7: 1. [표1] 구분별 평균 가동시간 → [G3:G5] | C7: =ROUNDUP(AVERAGEIFS($C$3:$C$10,$A$3:$A$10,E3,$B$3:$B$10,F3),0) (첫 칸에 넣고 끝까지 끌어내리기)
A8: 계산작업 | B8: 2. [표2] 구분별 목표 달성 설비 수 → [F15:F17] | C8: =SUM(($A$15:$A$22=E15)*($C$15:$C$22>=0.9)) {배열: Ctrl+Shift+Enter} (첫 칸에 넣고 끝까지 끌어내리기)
A9: 계산작업 | B9: 3. [표3] 가동률 등급 → [C27:C32] | C9: =HLOOKUP(B27,$F$26:$I$27,2,TRUE) (첫 칸에 넣고 끝까지 끌어내리기)
A10: 계산작업 | B10: 4. [표4] 설비 코드 줄여 쓰기 → [C37:C42] | C10: =UPPER(LEFT(A37,2))&"-"&RIGHT(A37,3) (첫 칸에 넣고 끝까지 끌어내리기)
A11: 계산작업 | B11: 5. [표5] 점검 구분 (사용자 정의 함수) | C11: [개발 도구] → [Visual Basic] → [삽입] → [모듈] 에 입력: Public Function fn점검(가동시간) Select Case 가동시간 Case Is >= 180 fn점검 = "정밀점검" Case Is >= 120 fn점검 = "일반점검" Case Else fn점검 = "생략" End Select End Function 그다음 C47 에 =fn점검(B47) 를 넣고 C52 까지 끌어내리기
A12: 분석작업-1 | B12: 피벗 테이블 | C12: 표 안 → [삽입] → [피벗 테이블] → 기존 워크시트 I3 구분 → 행, 가동시간·가동률 → 값 값 필드 설정 → '평균' 으로, 각각 표시 형식 가동률 평균 칸 오른쪽 클릭 → [정렬] → 내림차순
A13: 분석작업-2 | B13: [분석작업-2] 시트의 [A3:E20] 표에서 '설비코드' 와 '점검일' 이 같은 중복 행을 [중복된 항목 제거] 로 지우시오. | C13: 표 안 → [데이터] → [중복된 항목 제거] '모두 선택 취소' → 설비코드·점검일만 체크 → 확인 '중복 값 5개가 제거되었습니다' 확인
A14: 기타작업-3 | B14: 1) [G3] 위치 단추 | C14: Sub 점검등록() Dim r As Long r = Range("A3").CurrentRegion.Rows.Count + 3 Cells(r, 1) = InputBox("설비코드") Cells(r, 2) = Date Cells(r, 3) = InputBox("구분") Cells(r, 4) = Val(InputBox("비용")) End Sub
... A21: 기타작업-1 | B21: 5) '가동시간' 계열에 데이터 레이블 '안쪽 끝에' 표시하시오 | C21: 막대 안 끝에 숫자
