Workbook

Sheet 읽어보기
B2: 컴활 1급 실기 실전 모의고사 제1회 — 공정 품질
B3: 1급 스프레드시트 실무와 같은 시트 이름 · 같은 배점입니다. 시간 45분, 70점 이상이면 합격.
B4: 순서
B5: ① [문제지] 시트를 읽고 → 각 작업 시트에서 풉니다.
B6: ② 계산작업 노란 칸의 0 을 지우고 첫 칸에 수식 → 끝까지 끌어내리기. 배열 수식은 Ctrl + Shift + Enter.
B7: ③ 계산작업 5번은 사용자 정의 함수 — [개발 도구] → [Visual Basic] → 모듈에 Function 을 만들고 =fn…() 로 계산합니다.
B8: ④ 다 풀면 [채점표] — 자동 칸은 저절로, '스스로' 칸은 [확인 방법] 을 보고 O / X.
B9: 함수·매크로·VBA 가 들어가면 '다른 이름으로 저장' → Excel 매크로 사용 통합 문서(*.xlsm). 그냥 저장하면 코드가 사라집니다.
B10: [개발 도구] 탭이 없으면 [파일] → [옵션] → [리본 사용자 지정] 에서 '개발 도구' 체크.

Sheet 문제지
A1: 컴퓨터활용능력 1급 실기 · 스프레드시트 실무 · 실전 모의고사 제1회 (공정 품질)
A2: 시험 시간 45분 · 100점 만점 · 70점 이상 합격. 시작 [ : ] 끝 [ : ] 사용자 정의 함수·매크로·VBA 를 넣었으면 Excel 매크로 사용 통합 문서(*.xlsm)로 저장하세요.
A4: 기본작업-1 · 10점
B5: 1. | C5: [A3:G15] 영역에서 라인이 'A' 이면서 불량률이 2% 이상인 행의 '로트번호', '제품', '불량수', '불량률' 열만 고급 필터로 추출하시오. · 조건은 [A17:B18] 영역에 입력 · 결과는 [A20] 셀부터 표시
B6: 2. | C6: [A4:G15] 영역에서 불량수가 불량수 전체 평균 이상인 행 전체에 채우기 색 '노랑' 을 적용하시오. · AVERAGE 함수를 사용한 수식으로 조건 지정 · 규칙 유형 '수식을 사용하여 서식을 지정할 셀 결정'
A7: 기본작업-2 · 5점
B8: 3. | C8: [기본작업-2] 시트를 다음과 같이 인쇄되게 설정하시오. · 용지 방향 가로, 페이지 가운데(가로) 맞춤 · 3행이 매 페이지 위에 반복 · 바닥글 가운데에 '1 / 3' 처럼 '현재 쪽 / 전체 쪽'
A9: 계산작업 · 30점 (각 6점)
B10: 1. | C10: [표1]에서 라인[B3:B10]이 G열의 라인과 같은 것의 불량수[D3:D10] 합계를 불량 합계[H3:H5]에 구하시오. (SUM 함수를 이용한 배열 수식) → [H3:H5] ※ Ctrl+Shift+Enter
B11: 2. | C11: [표2]에서 검사수[B15:B22]가 100 이상이면서 불량률[D15:D22]이 2% 이하이면 "합격", 그 외는 "재검" 을 판정[E15:E22]에 표시하시오. → [E15:E22]
B12: 3. | C12: [표3]에서 라인[F27:F30]과 월[G27:G30]로 왼쪽 가동률 표에서 값을 찾아 가동률[H27:H30]에 표시하시오. (INDEX, MATCH 함수) → [H27:H30]
B13: 4. | C13: [표4]에서 라인[A35:A42]과 제품[B35:B42]이 D·E열의 라인·제품과 같은 건수를 구해 "3건" 처럼 건수[F35:F37]에 표시하시오. → [F35:F37]
B14: 5. | C14: [표5]에서 사용자 정의 함수 'fn등급' 을 작성하여 등급[C47:C52]을 표시하시오. fn등급은 불량률을 인수로 받아, 불량률이 1% 이하이면 "우수", 3% 이하이면 "보통", 그 외는 "관리" 를 돌려준다. (IF 문 사용 · Public Function fn등급(불량률)) → [C47:C52]
A15: 분석작업-1 · 10점
C16: [분석작업-1] 시트의 표로 피벗 테이블을 만드시오. · 행: 제품 · 열: 라인 · 값: 불량수의 합계, 검사수의 합계 · 위치 [J3] · 값 필드는 열 방향 대신 행 방향(Σ 값 을 행으로) · 보고서 레이아웃 '개요 형식'
A17: 분석작업-2 · 10점
C18: [분석작업-2] 시트에서 [데이터 표] 기능으로 판매 단가[C3]와 판매량[C4]의 변화에 따른 이익을 [C11:F15] 영역에 계산하시오. · 행 입력 셀 C3 (단가 → 가로), 열 입력 셀 C4 (판매량 → 세로)
A19: 기타작업-1 · 10점 (각 2점)
C20: [기타작업-1] 시트의 차트(묶은 세로 막대 · 검사수·불량수)를 다음과 같이 고치시오. (각 2점)
B21: 1) | C21: '불량수' 계열을 삭제하고 '불량률' 계열을 추가하시오
B22: 2) | C22: '불량률' 계열을 '표식이 있는 꺾은선형' 으로, 보조 축에 표시하시오
B23: 3) | C23: 보조 세로(값) 축의 최소값 0, 최대값 0.03, 표시 형식 '백분율' 소수 1자리
B24: 4) | C24: 차트 제목을 셀 [A1] 과 연결하고, 차트 스타일 '스타일 6' 을 적용하시오
B25: 5) | C25: '불량률' 계열의 '9월' 요소에만 데이터 레이블 '값' 을 '위쪽' 에 표시하시오
A26: 기타작업-2 · 10점 (각 5점)
C27: [기타작업-2] 시트에서 다음 두 매크로를 만들고 연결하시오. (각 5점 · 저장은 .xlsm)
B28: 1) | C28: [D4:D8] 에 불량률(불량수÷검사수)을 구하는 '불량률' 매크로 — [F3:G4] 영역에 '단추'(양식 컨트롤, 텍스트 '불량률')를 그려 연결
B29: 2) | C29: [D4:D8] 에 표시 형식 '백분율' 소수 1자리를 적용하는 '서식' 매크로 — [F6:G7] 영역에 도형 '사각형: 둥근 모서리'(텍스트 '서식')를 그려 연결
A30: 기타작업-3 · 15점 (각 5점)
C31: [기타작업-3] 시트에서 다음과 같이 프로그래밍하시오. (각 5점) ※ 실제 시험은 미리 만든 사용자 폼(입력 폼)을 쓰지만, 이 연습 파일에는 폼을 넣을 수 없어 단추·InputBox·이벤트로 같은 문법을 연습합니다.
B32: 1) | C32: [H3] 위치에 단추(텍스트 '입력')를 만들고, 누르면 InputBox 로 라인·제품·검사수·불량수를 차례로 받아 표의 마지막 행 다음 줄에 입력하는 '검사입력' 프로시저를 연결하시오. (검사일은 Date 로 오늘 날짜)
B33: 2) | C33: [기타작업-3] 시트를 선택(Activate)할 때마다 [H1] 셀에 '오늘 날짜: 2026-09-28' 처럼 표시되는 이벤트 프로시저를 작성하시오.
B34: 3) | C34: [H6] 위치에 단추(텍스트 '종료')를 만들고, 누르면 '검사 기록을 마칩니다.' 메시지를 보여 준 뒤 통합 문서를 저장하는 '종료' 프로시저를 연결하시오.

Sheet 기본작업-1
A1: 기본작업-1
A3: 검사일 | B3: 로트번호 | C3: 라인 | D3: 제품 | E3: 검사수 | F3: 불량수 | G3: 불량률
A4: 46266 | B4: L0901-A | C4: A | D4: 감속기어 | E4: 120 | F4: 3 | G4: 0.025
A5: 46266 | B5: L0901-B | C5: B | D5: 구동축 | E5: 80 | F5: 1 | G5: 0.0125
A6: 46267 | B6: L0902-A | C6: A | D6: 밸브블록 | E6: 150 | F6: 6 | G6: 0.04
A7: 46267 | B7: L0902-C | C7: C | D7: 감속기어 | E7: 90 | F7: 4 | G7: 0.0444
A8: 46268 | B8: L0903-B | C8: B | D8: 커플링 | E8: 200 | F8: 2 | G8: 0.01
A9: 46268 | B9: L0903-A | C9: A | D9: 구동축 | E9: 100 | F9: 2 | G9: 0.02
A10: 46269 | B10: L0904-C | C10: C | D10: 밸브블록 | E10: 110 | F10: 1 | G10: 0.0091
A11: 46269 | B11: L0904-A | C11: A | D11: 커플링 | E11: 60 | F11: 3 | G11: 0.05
A12: 46272 | B12: L0907-B | C12: B | D12: 감속기어 | E12: 130 | F12: 5 | G12: 0.0385
A13: 46272 | B13: L0907-C | C13: C | D13: 구동축 | E13: 70 | F13: 0 | G13: 0
A14: 46273 | B14: L0908-A | C14: A | D14: 감속기어 | E14: 140 | F14: 1 | G14: 0.0071
A15: 46273 | B15: L0908-B | C15: B | D15: 밸브블록 | E15: 95 | F15: 3 | G15: 0.0316

Sheet 기본작업-2
A1: 기본작업-2 (페이지 레이아웃)
A3: 검사일 | B3: 로트번호 | C3: 라인 | D3: 제품 | E3: 검사수 | F3: 불량수
A4: 46266 | B4: L0901-A | C4: A | D4: 감속기어 | E4: 120 | F4: 3
A5: 46266 | B5: L0901-B | C5: B | D5: 구동축 | E5: 80 | F5: 1
A6: 46267 | B6: L0902-A | C6: A | D6: 밸브블록 | E6: 150 | F6: 6
A7: 46267 | B7: L0902-C | C7: C | D7: 감속기어 | E7: 90 | F7: 4
A8: 46268 | B8: L0903-B | C8: B | D8: 커플링 | E8: 200 | F8: 2
A9: 46268 | B9: L0903-A | C9: A | D9: 구동축 | E9: 100 | F9: 2
A10: 46269 | B10: L0904-C | C10: C | D10: 밸브블록 | E10: 110 | F10: 1
A11: 46269 | B11: L0904-A | C11: A | D11: 커플링 | E11: 60 | F11: 3
A12: 46272 | B12: L0907-B | C12: B | D12: 감속기어 | E12: 130 | F12: 5
A13: 46272 | B13: L0907-C | C13: C | D13: 구동축 | E13: 70 | F13: 0
A14: 46273 | B14: L0908-A | C14: A | D14: 감속기어 | E14: 140 | F14: 1
A15: 46273 | B15: L0908-B | C15: B | D15: 밸브블록 | E15: 95 | F15: 3
... A43: 46267 | B43: L0902-C | C43: C | D43: 감속기어 | E43: 90 | F43: 4

Sheet 계산작업
A1: [표1] 라인별 불량수 합계
A2: 검사일 | B2: 라인 | C2: 제품 | D2: 불량수 | G2: 라인 | H2: 불량 합계
A3: 46266 | B3: B | C3: 감속기어 | D3: 3 | G3: A | H3: 0 | AA3: {=SUM(($B$3:$B$10=G3)*$D$3:$D$10)} | AB3: =AND(_xlfn.ISFORMULA(H3),IFERROR(ROUND(H3,4)=ROUND(AA3,4),EXACT(H3,AA3)))
A4: 46266 | B4: A | C4: 구동축 | D4: 1 | G4: B | H4: 0 | AA4: {=SUM(($B$3:$B$10=G4)*$D$3:$D$10)} | AB4: =AND(_xlfn.ISFORMULA(H4),IFERROR(ROUND(H4,4)=ROUND(AA4,4),EXACT(H4,AA4)))
A5: 46267 | B5: C | C5: 밸브 | D5: 6 | G5: C | H5: 0 | AA5: {=SUM(($B$3:$B$10=G5)*$D$3:$D$10)} | AB5: =AND(_xlfn.ISFORMULA(H5),IFERROR(ROUND(H5,4)=ROUND(AA5,4),EXACT(H5,AA5)))
A6: 46267 | B6: A | C6: 기어 | D6: 4
A7: 46268 | B7: B | C7: 커플링 | D7: 2
A8: 46268 | B8: C | C8: 구동축 | D8: 2
A9: 46269 | B9: A | C9: 밸브 | D9: 5
A10: 46269 | B10: B | C10: 기어 | D10: 1
A13: [표2] 로트 판정
A14: 로트번호 | B14: 검사수 | C14: 불량수 | D14: 불량률 | E14: 판정
A15: L01 | B15: 120 | C15: 2 | D15: 0.0167 | E15: 0 | AA15: =IF(AND(B15>=100,D15<=2%),"합격","재검") | AB15: =AND(_xlfn.ISFORMULA(E15),IFERROR(ROUND(E15,4)=ROUND(AA15,4),EXACT(E15,AA15)))
A16: L02 | B16: 80 | C16: 2 | D16: 0.025 | E16: 0 | AA16: =IF(AND(B16>=100,D16<=2%),"합격","재검") | AB16: =AND(_xlfn.ISFORMULA(E16),IFERROR(ROUND(E16,4)=ROUND(AA16,4),EXACT(E16,AA16)))
A17: L03 | B17: 150 | C17: 3 | D17: 0.02 | E17: 0 | AA17: =IF(AND(B17>=100,D17<=2%),"합격","재검") | AB17: =AND(_xlfn.ISFORMULA(E17),IFERROR(ROUND(E17,4)=ROUND(AA17,4),EXACT(E17,AA17)))
A18: L04 | B18: 90 | C18: 1 | D18: 0.0111 | E18: 0 | AA18: =IF(AND(B18>=100,D18<=2%),"합격","재검") | AB18: =AND(_xlfn.ISFORMULA(E18),IFERROR(ROUND(E18,4)=ROUND(AA18,4),EXACT(E18,AA18)))
A19: L05 | B19: 100 | C19: 2 | D19: 0.02 | E19: 0 | AA19: =IF(AND(B19>=100,D19<=2%),"합격","재검") | AB19: =AND(_xlfn.ISFORMULA(E19),IFERROR(ROUND(E19,4)=ROUND(AA19,4),EXACT(E19,AA19)))
A20: L06 | B20: 200 | C20: 5 | D20: 0.025 | E20: 0 | AA20: =IF(AND(B20>=100,D20<=2%),"합격","재검") | AB20: =AND(_xlfn.ISFORMULA(E20),IFERROR(ROUND(E20,4)=ROUND(AA20,4),EXACT(E20,AA20)))
A21: L07 | B21: 99 | C21: 1 | D21: 0.0101 | E21: 0 | AA21: =IF(AND(B21>=100,D21<=2%),"합격","재검") | AB21: =AND(_xlfn.ISFORMULA(E21),IFERROR(ROUND(E21,4)=ROUND(AA21,4),EXACT(E21,AA21)))
A22: L08 | B22: 130 | C22: 1 | D22: 0.0077 | E22: 0 | AA22: =IF(AND(B22>=100,D22<=2%),"합격","재검") | AB22: =AND(_xlfn.ISFORMULA(E22),IFERROR(ROUND(E22,4)=ROUND(AA22,4),EXACT(E22,AA22)))
A25: [표3] 라인·월별 가동률 조회
A26: 라인 | B26: 7월 | C26: 8월 | D26: 9월 | F26: 라인 | G26: 월 | H26: 가동률
A27: A | B27: 0.91 | C27: 0.88 | D27: 0.93 | F27: B | G27: 9월 | H27: 0 | AA27: =INDEX($B$27:$D$30,MATCH(F27,$A$27:$A$30,0),MATCH(G27,$B$26:$D$26,0)) | AB27: =AND(_xlfn.ISFORMULA(H27),IFERROR(ROUND(H27,4)=ROUND(AA27,4),EXACT(H27,AA27)))
A28: B | B28: 0.84 | C28: 0.9 | D28: 0.87 | F28: A | G28: 7월 | H28: 0 | AA28: =INDEX($B$27:$D$30,MATCH(F28,$A$27:$A$30,0),MATCH(G28,$B$26:$D$26,0)) | AB28: =AND(_xlfn.ISFORMULA(H28),IFERROR(ROUND(H28,4)=ROUND(AA28,4),EXACT(H28,AA28)))
A29: C | B29: 0.79 | C29: 0.82 | D29: 0.95 | F29: C | G29: 8월 | H29: 0 | AA29: =INDEX($B$27:$D$30,MATCH(F29,$A$27:$A$30,0),MATCH(G29,$B$26:$D$26,0)) | AB29: =AND(_xlfn.ISFORMULA(H29),IFERROR(ROUND(H29,4)=ROUND(AA29,4),EXACT(H29,AA29)))
A30: D | B30: 0.88 | C30: 0.86 | D30: 0.8 | F30: D | G30: 9월 | H30: 0 | AA30: =INDEX($B$27:$D$30,MATCH(F30,$A$27:$A$30,0),MATCH(G30,$B$26:$D$26,0)) | AB30: =AND(_xlfn.ISFORMULA(H30),IFERROR(ROUND(H30,4)=ROUND(AA30,4),EXACT(H30,AA30)))
A33: [표4] 라인·제품별 검사 건수
A34: 라인 | B34: 제품 | D34: 라인 | E34: 제품 | F34: 건수
A35: A | B35: 기어 | D35: A | E35: 기어 | F35: 0 | AA35: =COUNTIFS($A$35:$A$42,D35,$B$35:$B$42,E35)&"건" | AB35: =AND(_xlfn.ISFORMULA(F35),IFERROR(ROUND(F35,4)=ROUND(AA35,4),EXACT(F35,AA35)))
A36: B | B36: 축 | D36: B | E36: 기어 | F36: 0 | AA36: =COUNTIFS($A$35:$A$42,D36,$B$35:$B$42,E36)&"건" | AB36: =AND(_xlfn.ISFORMULA(F36),IFERROR(ROUND(F36,4)=ROUND(AA36,4),EXACT(F36,AA36)))
A37: A | B37: 축 | D37: A | E37: 축 | F37: 0 | AA37: =COUNTIFS($A$35:$A$42,D37,$B$35:$B$42,E37)&"건" | AB37: =AND(_xlfn.ISFORMULA(F37),IFERROR(ROUND(F37,4)=ROUND(AA37,4),EXACT(F37,AA37)))
A38: A | B38: 기어
A39: B | B39: 기어
A40: C | B40: 축
A41: A | B41: 기어
A42: B | B42: 축
A45: [표5] 품질 등급 (사용자 정의 함수)
A46: 로트번호 | B46: 불량률 | C46: 등급
A47: L11 | B47: 0.008 | C47: 0 | AA47: =IF(B47<=0.01,"우수",IF(B47<=0.03,"보통","관리")) | AB47: =AND(_xlfn.ISFORMULA(C47),IFERROR(ROUND(C47,4)=ROUND(AA47,4),EXACT(C47,AA47)))
A48: L12 | B48: 0.01 | C48: 0 | AA48: =IF(B48<=0.01,"우수",IF(B48<=0.03,"보통","관리")) | AB48: =AND(_xlfn.ISFORMULA(C48),IFERROR(ROUND(C48,4)=ROUND(AA48,4),EXACT(C48,AA48)))
...

Sheet 분석작업-1
A1: 분석작업-1
A3: 검사일 | B3: 로트번호 | C3: 라인 | D3: 제품 | E3: 검사수 | F3: 불량수 | G3: 불량률
A4: 46266 | B4: L0901-A | C4: A | D4: 감속기어 | E4: 120 | F4: 3 | G4: 0.025
A5: 46266 | B5: L0901-B | C5: B | D5: 구동축 | E5: 80 | F5: 1 | G5: 0.0125
A6: 46267 | B6: L0902-A | C6: A | D6: 밸브블록 | E6: 150 | F6: 6 | G6: 0.04
A7: 46267 | B7: L0902-C | C7: C | D7: 감속기어 | E7: 90 | F7: 4 | G7: 0.0444
A8: 46268 | B8: L0903-B | C8: B | D8: 커플링 | E8: 200 | F8: 2 | G8: 0.01
A9: 46268 | B9: L0903-A | C9: A | D9: 구동축 | E9: 100 | F9: 2 | G9: 0.02
A10: 46269 | B10: L0904-C | C10: C | D10: 밸브블록 | E10: 110 | F10: 1 | G10: 0.0091
A11: 46269 | B11: L0904-A | C11: A | D11: 커플링 | E11: 60 | F11: 3 | G11: 0.05
A12: 46272 | B12: L0907-B | C12: B | D12: 감속기어 | E12: 130 | F12: 5 | G12: 0.0385
A13: 46272 | B13: L0907-C | C13: C | D13: 구동축 | E13: 70 | F13: 0 | G13: 0
A14: 46273 | B14: L0908-A | C14: A | D14: 감속기어 | E14: 140 | F14: 1 | G14: 0.0071
A15: 46273 | B15: L0908-B | C15: B | D15: 밸브블록 | E15: 95 | F15: 3 | G15: 0.0316

Sheet 분석작업-2
A1: 판매 이익 모형
B3: 판매 단가 | C3: 12000
B4: 판매량 | C4: 500
B5: 개당 변동비 | C5: 7000
B6: 고정비 | C6: 2000000
B7: 이익 | C7: =C3*C4-(C5*C4+C6)
B9: 판매량 ↓ / 판매 단가 →
B10: =C7 | C10: 10000 | D10: 11000 | E10: 12000 | F10: 13000
B11: 300
B12: 400
B13: 500
B14: 600
B15: 700

Sheet 기타작업-1
A1: 월별 검사 실적
A3: 월 | B3: 검사수 | C3: 불량수 | D3: 불량률
A4: 4월 | B4: 1180 | C4: 25 | D4: 0.0212
A5: 5월 | B5: 1250 | C5: 21 | D5: 0.0168
A6: 6월 | B6: 1320 | C6: 30 | D6: 0.0227
A7: 7월 | B7: 1400 | C7: 18 | D7: 0.0129
A8: 8월 | B8: 1290 | C8: 15 | D8: 0.0116
A9: 9월 | B9: 1345 | C9: 31 | D9: 0.023

Sheet 기타작업-2
A1: 매크로
A3: 라인 | B3: 검사수 | C3: 불량수 | D3: 불량률
A4: A | B4: 570 | C4: 15
A5: B | B5: 505 | C5: 11
A6: C | B6: 270 | C6: 5
A7: D | B7: 330 | C7: 9
A8: E | B8: 410 | C8: 4

Sheet 기타작업-3
A1: VBA 프로그래밍
A3: 검사일 | B3: 라인 | C3: 제품 | D3: 검사수 | E3: 불량수
A4: 46266 | B4: A | C4: 감속기어 | D4: 120 | E4: 3
A5: 46267 | B5: B | C5: 구동축 | D5: 80 | E5: 1
A6: 46268 | B6: C | C6: 밸브블록 | D6: 150 | E6: 6

Sheet 채점표
A1: 채점표 — 1급 제1회 (자동 칸은 저절로, '스스로' 칸은 G열에 O / X)
A3: 작업 | B3: 문항 | C3: 배점 | D3: 방식 | E3: 점수 | F3: 확인 방법 | G3: O / X
A4: 기본작업-1 | B4: 1. 고급 필터 (결과 4행) | C4: 5 | D4: 자동 | E4: =IF(AND(SUMPRODUCT(--('기본작업-1'!$A$20:$D$24&""='채점표'!$AA$4:$AD$8&""))=20,COUNTA('기본작업-1'!$A$25:$D$25)=0),5,0) | F4: 자동 — A20 부터 필드 이름 + 4행 정확히 | AA4: 로트번호 | AB4: 제품 | AC4: 불량수 | AD4: 불량률
A5: 기본작업-1 | B5: 2. 조건부 서식 — 불량수 3 이상(평균 2.58 이상)인 6행이 노랑 — 수식 =$F4>=AVERAGE($F$4:$F$15) | C5: 5 | D5: 스스로 | E5: =IF(G5="O",C5,0) | F5: [홈] → [조건부 서식] → [규칙 관리] 에서 수식 확인 | AA5: L0901-A | AB5: 감속기어 | AC5: 3 | AD5: 0.025
A6: 기본작업-2 | B6: 3. 페이지 레이아웃 — 문제 조건 모두 | C6: 5 | D6: 스스로 | E6: =IF(G6="O",C6,0) | F6: [페이지 레이아웃] → [페이지 설정] 에서 가로·가로 가운데·인쇄 제목 $3:$3·바닥글 &[페이지] / &[전체 페이지 수] | AA6: L0902-A | AB6: 밸브블록 | AC6: 6 | AD6: 0.04
A7: 계산작업 | B7: 1. [표1] 라인별 불량수 합계 [H3:H5] | C7: 6 | D7: 자동 | E7: =IF(COUNTIF('계산작업'!$AB$3:$AB$5,TRUE)=3,6,0) | F7: 자동 — 3칸 모두 맞아야 6점 | AA7: L0903-A | AB7: 구동축 | AC7: 2 | AD7: 0.02
A8: 계산작업 | B8: 2. [표2] 로트 판정 [E15:E22] | C8: 6 | D8: 자동 | E8: =IF(COUNTIF('계산작업'!$AB$15:$AB$22,TRUE)=8,6,0) | F8: 자동 — 8칸 모두 맞아야 6점 | AA8: L0904-A | AB8: 커플링 | AC8: 3 | AD8: 0.05
A9: 계산작업 | B9: 3. [표3] 라인·월별 가동률 조회 [H27:H30] | C9: 6 | D9: 자동 | E9: =IF(COUNTIF('계산작업'!$AB$27:$AB$30,TRUE)=4,6,0) | F9: 자동 — 4칸 모두 맞아야 6점
A10: 계산작업 | B10: 4. [표4] 라인·제품별 검사 건수 [F35:F37] | C10: 6 | D10: 자동 | E10: =IF(COUNTIF('계산작업'!$AB$35:$AB$37,TRUE)=3,6,0) | F10: 자동 — 3칸 모두 맞아야 6점 | AA10: -1100000 | AB10: -800000 | AC10: -500000 | AD10: -200000
A11: 계산작업 | B11: 5. [표5] 품질 등급 (사용자 정의 함수) [C47:C52] | C11: 6 | D11: 자동 | E11: =IF(COUNTIF('계산작업'!$AB$47:$AB$52,TRUE)=6,6,0) | F11: 자동 — 6칸 모두 맞아야 6점 (함수를 만든 뒤 =fn…() 로 계산한 결과로 채점) | AA11: -800000 | AB11: -400000 | AC11: 0 | AD11: 400000
A12: 분석작업-1 | B12: 피벗 1) J3 에서 시작, 행에 제품 4개, 열에 라인 A·B·C | C12: 4 | D12: 스스로 | E12: =IF(G12="O",C12,0) | F12: 피벗 표를 보고 확인 | AA12: -500000 | AB12: 0 | AC12: 500000 | AD12: 1000000
A13: 분석작업-1 | B13: 피벗 2) 제품마다 '합계 : 불량수' · '합계 : 검사수' 두 줄 (Σ 값이 행 영역) | C13: 3 | D13: 스스로 | E13: =IF(G13="O",C13,0) | F13: 피벗 표를 보고 확인 | AA13: -200000 | AB13: 400000 | AC13: 1000000 | AD13: 1600000
A14: 분석작업-1 | B14: 피벗 3) 총합계: 불량수 31 · 검사수 1,345, 레이아웃 '개요 형식' | C14: 3 | D14: 스스로 | E14: =IF(G14="O",C14,0) | F14: 피벗 표를 보고 확인 | AA14: 100000 | AB14: 800000 | AC14: 1500000 | AD14: 2200000
A15: 분석작업-2 | B15: 데이터 표 — [C11:F15] 이익 20칸 | C15: 10 | D15: 자동 | E15: =IF(SUMPRODUCT(--('분석작업-2'!$C$11:$F$15='채점표'!$AA$10:$AD$14))=20,10,0) | F15: 자동
A16: 기타작업-1 | B16: 차트 1) '불량수' 계열을 삭제하고 '불량률' 계열을 추가하시오 | C16: 2 | D16: 스스로 | E16: =IF(G16="O",C16,0) | F16: 범례에 검사수·불량률
A17: 기타작업-1 | B17: 차트 2) '불량률' 계열을 '표식이 있는 꺾은선형' 으로, 보조 축에 표시하시오 | C17: 2 | D17: 스스로 | E17: =IF(G17="O",C17,0) | F17: 오른쪽에 % 축
A18: 기타작업-1 | B18: 차트 3) 보조 세로(값) 축의 최소값 0, 최대값 0.03, 표시 형식 '백분율' 소수 1자리 | C18: 2 | D18: 스스로 | E18: =IF(G18="O",C18,0) | F18: 보조 축 0.0% ~ 3.0%
A19: 기타작업-1 | B19: 차트 4) 차트 제목을 셀 [A1] 과 연결하고, 차트 스타일 '스타일 6' 을 적용하시오 | C19: 2 | D19: 스스로 | E19: =IF(G19="O",C19,0) | F19: 제목 수식 ='기타작업-1'!$A$1
A20: 기타작업-1 | B20: 차트 5) '불량률' 계열의 '9월' 요소에만 데이터 레이블 '값' 을 '위쪽' 에 표시하시오 | C20: 2 | D20: 스스로 | E20: =IF(G20="O",C20,0) | F20: 9월 점 위에만 2.3%
A21: 기타작업-2 | B21: 매크로 1) [D4:D8] 에 불량률(불량수÷검사수)을 구하는 '불량률' 매크로 — [F3:G4] 영역에 '단추'(양식 컨트롤, 텍스트 '불량률')를 그려 연결 | C21: 5 | D21: 스스로 | E21: =IF(G21="O",C21,0) | F21: D4 에 =C4/B4
A22: 기타작업-2 | B22: 매크로 2) [D4:D8] 에 표시 형식 '백분율' 소수 1자리를 적용하는 '서식' 매크로 — [F6:G7] 영역에 도형 '사각형: 둥근 모서리'(텍스트 '서식')를 그려 연결 | C22: 5 | D22: 스스로 | E22: =IF(G22="O",C22,0) | F22: 도형을 누르면 2.6%
A23: 기타작업-3 | B23: VBA 1) [H3] 위치에 단추(텍스트 '입력')를 만들고, 누르면 InputBox 로 라인·제품·검사수·불량수를 차례로 받아 표의 마지막 행 다음 줄에 입력하는 '검사입력' 프로시저를 연결하시오. (검사일은 Date 로 오늘 날짜) | C23: 5 | D23: 스스로 | E23: =IF(G23="O",C23,0) | F23: 단추를 누르고 값 4개를 넣으면 7행에 새 줄
A24: 기타작업-3 | B24: VBA 2) [기타작업-3] 시트를 선택(Activate)할 때마다 [H1] 셀에 '오늘 날짜: 2026-09-28' 처럼 표시되는 이벤트 프로시저를 작성하시오. | C24: 5 | D24: 스스로 | E24: =IF(G24="O",C24,0) | F24: 다른 시트에 갔다 오면 H1 이 바뀜 (시트 모듈에 작성)
A25: 기타작업-3 | B25: VBA 3) [H6] 위치에 단추(텍스트 '종료')를 만들고, 누르면 '검사 기록을 마칩니다.' 메시지를 보여 준 뒤 통합 문서를 저장하는 '종료' 프로시저를 연결하시오. | C25: 5 | D25: 스스로 | E25: =IF(G25="O",C25,0) | F25: 메시지 뒤 저장됨
B27: 합계 (100점 만점 · 70점 이상 합격) | E27: =SUM(E4:E25) | F27: =IF(E27>=70,"🎉 합격","불합격 — 틀린 작업의 [정답·해설]을 보세요")
A29: '스스로' 문항은 [확인 방법] 을 보고 실제로 그렇게 되어 있으면 O. 한 군데라도 다르면 X (실제 시험은 부분 점수 없음).

Sheet 정답·해설
A1: 정답·해설 — 1급 제1회 (먼저 끝까지 풀고 보세요)
A3: 작업 | B3: 무엇을 | C3: 어떻게 · 정답
A4: 기본작업-1 | B4: 고급 필터 | C4: A17 '라인' · B17 '불량률' / A18 'A' · B18 '>=0.02' → [데이터]→[고급] '다른 장소에 복사', 복사 위치에는 A20:D20 에 미리 적어 둔 네 필드 이름을 지정
A5: 기본작업-1 | B5: 조건부 서식 | C5: 불량수 3 이상(평균 2.58 이상)인 6행이 노랑 — 수식 =$F4>=AVERAGE($F$4:$F$15)
A6: 기본작업-2 | B6: 페이지 레이아웃 | C6: [페이지 레이아웃] → [페이지 설정] 에서 가로·가로 가운데·인쇄 제목 $3:$3·바닥글 &[페이지] / &[전체 페이지 수]
A7: 계산작업 | B7: 1. [표1] 라인별 불량수 합계 → [H3:H5] | C7: =SUM(($B$3:$B$10=G3)*$D$3:$D$10) {배열: Ctrl+Shift+Enter} (첫 칸에 넣고 끝까지 끌어내리기)
A8: 계산작업 | B8: 2. [표2] 로트 판정 → [E15:E22] | C8: =IF(AND(B15>=100,D15<=2%),"합격","재검") (첫 칸에 넣고 끝까지 끌어내리기)
A9: 계산작업 | B9: 3. [표3] 라인·월별 가동률 조회 → [H27:H30] | C9: =INDEX($B$27:$D$30,MATCH(F27,$A$27:$A$30,0),MATCH(G27,$B$26:$D$26,0)) (첫 칸에 넣고 끝까지 끌어내리기)
A10: 계산작업 | B10: 4. [표4] 라인·제품별 검사 건수 → [F35:F37] | C10: =COUNTIFS($A$35:$A$42,D35,$B$35:$B$42,E35)&"건" (첫 칸에 넣고 끝까지 끌어내리기)
A11: 계산작업 | B11: 5. [표5] 품질 등급 (사용자 정의 함수) | C11: [개발 도구] → [Visual Basic] → [삽입] → [모듈] 에 입력: Public Function fn등급(불량률) If 불량률 <= 0.01 Then fn등급 = "우수" ElseIf 불량률 <= 0.03 Then fn등급 = "보통" Else fn등급 = "관리" End If End Function 그다음 C47 에 =fn등급(B47) 를 넣고 C52 까지 끌어내리기
A12: 분석작업-1 | B12: 피벗 테이블 | C12: 표 안 → [삽입] → [피벗 테이블] → 기존 워크시트 J3 제품 → 행, 라인 → 열, 불량수·검사수 → 값 열 영역의 'Σ 값' 을 행 영역으로 끌어 옮김 [디자인] → [보고서 레이아웃] → '개요 형식으로 표시'
A13: 분석작업-2 | B13: [분석작업-2] 시트에서 [데이터 표] 기능으로 판매 단가[C3]와 판매량[C4]의 변화에 따른 이익을 [C11:F15] 영역에 계산하시오. | C13: B10 에 =C7 (이익 셀) 이 이미 들어 있음 → B10:F15 선택 [데이터] → [가상 분석] → [데이터 표] 행 입력 셀 C3 · 열 입력 셀 C4 → 확인
A14: 기타작업-3 | B14: 1) [H3] 위치에 단추 | C14: Sub 검사입력() Dim r As Long r = Range("A3").CurrentRegion.Rows.Count + 3 Cells(r, 1) = Date Cells(r, 2) = InputBox("라인") Cells(r, 3) = InputBox("제품") Cells(r, 4) = Val(InputBox("검사수")) Cells(r, 5) = Val(InputBox("불량수")) End Sub
... A21: 기타작업-1 | B21: 5) '불량률' 계열의 '9월' 요소에만 데이터 레이블 '값' 을 '위쪽' 에 표시하시오 | C21: 9월 점 위에만 2.3%
