Workbook

Sheet 읽어보기
B2: 1급 실기 ② 분석작업 — 출하 실적
B4: 시트 안내
B5: 출하실적 — 48건. 피벗(그룹화·계산 필드)·부분합·정렬·중복 제거용 + 계산 문제 6개
B6: 통합대상 — 분기별 작은 표 3개. [데이터 → 통합] 연습
B7: 데이터표 — 1변수·2변수 데이터 표(가상 분석) 연습
B8: 미션 — 해야 할 일 14가지 체크리스트
B9: 따라하기 — 14가지를 1단계·2단계… 로 풀어 쓴 것 (이것이 정답입니다)
B11: 1급에서 더 나오는 것
B12: 피벗 : 날짜 그룹화(월·분기) · 계산 필드 · 값 표시 형식(비율) · 보고서 필터 · 슬라이서
B13: 가상 분석 : 데이터 표(한 셀을 여러 값으로 바꿔 결과를 한꺼번에) · 시나리오 · 목표값 찾기
B14: 통합 : 흩어진 표 여러 개를 항목 기준으로 합치기 · 중복된 항목 제거
B15: 데이터 표의 결과 칸은 한 칸만 지울 수 없습니다(배열). 범위를 통째로 잡아야 지워집니다.

Sheet 출하실적
A3: 출하일 | B3: 지역 | C3: 거래처 | D3: 제품 | E3: 수량 | F3: 단가 | G3: 금액 | H3: 담당자
A4: 46027 | B4: 수도권 | C4: 대한정밀 | D4: 베어링유닛 | E4: 120 | F4: 12000 | G4: 0 | H4: 김현수 | AB4: =E4*F4
A5: 46032 | B5: 충청권 | C5: 성일기공 | D5: 감속기어 | E5: 20 | F5: 45000 | H5: 박지훈 | AB5: =E5*F5
A6: 46037 | B6: 영남권 | C6: 한빛모터스 | D6: 구동축 | E6: 60 | F6: 78000 | H6: 이서연 | AB6: =E6*F6
A7: 46042 | B7: 호남권 | C7: 제일오토 | D7: 밸브블록 | E7: 80 | F7: 33000 | H7: 최민재 | AB7: =E7*F7
A8: 46047 | B8: 수도권 | C8: 세진테크 | D8: 베어링유닛 | E8: 40 | F8: 12000 | H8: 김현수 | AB8: =E8*F8
A9: 46052 | B9: 충청권 | C9: 동양산업 | D9: 감속기어 | E9: 55 | F9: 45000 | H9: 박지훈 | AB9: =E9*F9
A10: 46057 | B10: 영남권 | C10: 대한정밀 | D10: 구동축 | E10: 100 | F10: 78000 | H10: 이서연 | AB10: =E10*F10
A11: 46062 | B11: 호남권 | C11: 성일기공 | D11: 밸브블록 | E11: 40 | F11: 33000 | H11: 최민재 | AB11: =E11*F11
A12: 46067 | B12: 수도권 | C12: 한빛모터스 | D12: 베어링유닛 | E12: 35 | F12: 12000 | H12: 김현수 | AB12: =E12*F12
A13: 46072 | B13: 충청권 | C13: 제일오토 | D13: 감속기어 | E13: 35 | F13: 45000 | H13: 박지훈 | AB13: =E13*F13
A14: 46077 | B14: 영남권 | C14: 세진테크 | D14: 구동축 | E14: 55 | F14: 78000 | H14: 이서연 | AB14: =E14*F14
A15: 46082 | B15: 호남권 | C15: 동양산업 | D15: 밸브블록 | E15: 80 | F15: 33000 | H15: 최민재 | AB15: =E15*F15
A16: 46087 | B16: 수도권 | C16: 대한정밀 | D16: 베어링유닛 | E16: 55 | F16: 12000 | H16: 김현수 | AB16: =E16*F16
... A51: 46262 | B51: 호남권 | C51: 동양산업 | D51: 밸브블록 | E51: 120 | F51: 33000 | H51: 최민재 | AB51: =E51*F51
A53: 금액 채점 → | G53: =SUMPRODUCT(--($G$4:$G$51=$AB$4:$AB$51))&" / 48"
A54: G4 에 =E4*F4 를 만들고 G51 까지 끌어 내리면 48 / 48 이 됩니다.
A56: ■ 계산 문제 6개
A57: 번호 ▶ 넣을 칸 | B57: 문제 — 무엇을 구하나 | E57: 답 | F57: 채점 | G57: 힌트
A58: 피벗을 만들기 전에 값으로 확인해 보기 — ▶ 표시된 칸(E열)에
A59: 1 ▶E59 | B59: 전체 금액[G4:G51] 합계. (G열을 먼저 채우세요) | E59: 0 | F59: =IF(NOT(_xlfn.ISFORMULA(E59)),"↖ 0 지우고 수식",IF(IFERROR(ROUND(E59,4)=ROUND(AB59,4),E59=AB59),"✔ 맞음","✘ 다시")) | G59: SUM | AB59: =SUM(AB4:AB51)
A60: 2 ▶E60 | B60: '수도권' 의 수량 합계. | E60: 0 | F60: =IF(NOT(_xlfn.ISFORMULA(E60)),"↖ 0 지우고 수식",IF(IFERROR(ROUND(E60,4)=ROUND(AB60,4),E60=AB60),"✔ 맞음","✘ 다시")) | G60: SUMIF · 지역은 B열 | AB60: =SUMIF($B$4:$B$51,"수도권",$E$4:$E$51)
A61: 3 ▶E61 | B61: '수도권' 이면서 제품이 '구동축' 인 건수. | E61: 0 | F61: =IF(NOT(_xlfn.ISFORMULA(E61)),"↖ 0 지우고 수식",IF(IFERROR(ROUND(E61,4)=ROUND(AB61,4),E61=AB61),"✔ 맞음","✘ 다시")) | G61: COUNTIFS(범위1, 조건1, 범위2, 조건2) | AB61: =COUNTIFS(B4:B51,"수도권",D4:D51,"구동축")
A62: 4 ▶E62 | B62: 거래처가 '대한정밀' 인 줄의 평균 수량을 소수 첫째 자리까지. | E62: 0 | F62: =IF(NOT(_xlfn.ISFORMULA(E62)),"↖ 0 지우고 수식",IF(IFERROR(ROUND(E62,4)=ROUND(AB62,4),E62=AB62),"✔ 맞음","✘ 다시")) | G62: AVERAGEIF 를 ROUND 로 | AB62: =ROUND(AVERAGEIF($C$4:$C$51,"대한정밀",$E$4:$E$51),1)
A63: 5 ▶E63 | B63: 1분기(1~3월)에 출하된 건수. | E63: 0 | F63: =IF(NOT(_xlfn.ISFORMULA(E63)),"↖ 0 지우고 수식",IF(IFERROR(ROUND(E63,4)=ROUND(AB63,4),E63=AB63),"✔ 맞음","✘ 다시")) | G63: MONTH 를 그대로 못 씁니다 — SUMPRODUCT 로 | AB63: =SUMPRODUCT((MONTH(A4:A51)<=3)*1)
A64: 6 ▶E64 | B64: 담당자별로 가장 많은 수량을 낸 한 건의 수량. (담당자 '김현수' 기준) | E64: 0 | F64: =IF(NOT(_xlfn.ISFORMULA(E64)),"↖ 0 지우고 수식",IF(IFERROR(ROUND(E64,4)=ROUND(AB64,4),E64=AB64),"✔ 맞음","✘ 다시")) | G64: SUMPRODUCT(MAX((조건)*범위)) | AB64: =SUMPRODUCT(MAX((H4:H51="김현수")*E4:E51))

Sheet 통합대상
A1: 분기별 출하 요약 — [데이터 → 통합] 으로 합치기
A2: 제품 이름의 순서와 개수가 표마다 다릅니다. 그래서 '첫 행·왼쪽 열' 을 기준으로 통합해야 합니다.
A4: 1분기 (A5:C9) | E4: 2분기 (E5:G8) | I4: 3분기 (I5:K9)
A5: 제품 | B5: 수량 | C5: 금액 | E5: 제품 | F5: 수량 | G5: 금액 | I5: 제품 | J5: 수량 | K5: 금액
A6: 베어링유닛 | B6: 320 | C6: 3840000 | E6: 감속기어 | F6: 205 | G6: 9225000 | I6: 구동축 | J6: 120 | K6: 9360000
A7: 감속기어 | B7: 180 | C7: 8100000 | E7: 베어링유닛 | F7: 410 | G7: 4920000 | I7: 밸브블록 | J7: 240 | K7: 7920000
A8: 구동축 | B8: 95 | C8: 7410000 | E8: 밸브블록 | F8: 165 | G8: 5445000 | I8: 베어링유닛 | J8: 275 | K8: 3300000
A9: 밸브블록 | B9: 210 | C9: 6930000 | I9: 감속기어 | J9: 190 | K9: 8550000
A12: → 통합 결과를 A15 부터 만드세요. (함수 : 합계 / 사용할 레이블 : 첫 행·왼쪽 열 모두 체크)

Sheet 데이터표
A1: 데이터 표(가상 분석) — 값을 여러 개 넣어 결과를 한꺼번에 보기
A2: 손익 모형입니다. 파란 칸은 입력값, 초록 칸은 수식입니다.
A4: 판매수량(개) | B4: 800
A5: 판매단가(원) | B5: 45000
A6: 개당 변동비(원) | B6: 28000
A7: 고정비(원) | B7: 9000000
A9: 영업이익(원) | B9: =B4*(B5-B6)-B7
A12: 1변수 데이터 표 — 판매수량이 바뀌면 영업이익은? (A13:B19)
A13: 판매수량 | B13: 영업이익 | H13: ① B13 에 =B9 를 넣고 ② A13:B19 를 잡은 뒤 ③ 데이터 → 가상 분석 → 데이터 표
A14: 400 | H14: ④ '열 입력 셀' 에 $B$4 (수량이 세로로 놓였으므로 '열')
A15: 600
A16: 800
A17: 1000
A18: 1200
A19: 1400
A21: 2변수 데이터 표 — 수량 × 단가 (A22:F27)
B22: 40000 | C22: 43000 | D22: 45000 | E22: 48000 | F22: 52000 | H22: ① 왼쪽 위 모서리 A22 에 =B9 ② A22:F27 선택 ③ 행 입력 셀 $B$5, 열 입력 셀 $B$4
A23: 400
A24: 600
A25: 800
A26: 1000
A27: 1200

Sheet 미션
A1: 1급 ② 분석작업 미션 14가지
A2: 다 한 미션은 □ 칸에 v 를 쳐 두세요. 어떻게 하는지는 [따라하기] 시트에 있습니다.
A4: 번호 | B4: 미션 — 무엇을 하는가 | C4: 다 함 | D4: 어디서 (메뉴)
A5: 1 | B5: [출하실적 G4] 금액을 =E4*F4 로 만들고 G51 까지 채우기. | C5: □ | D5: 채우기 핸들 두 번 클릭
A6: 2 | B6: [출하실적] 새 시트에 피벗 — 행 지역, 열 제품, 값 금액 합계. | C6: □ | D6: 삽입 → 피벗 테이블
A7: 3 | B7: [출하실적] 피벗에서 출하일을 '분기' 로 그룹화해 행에 넣기. | C7: □ | D7: 날짜 오른쪽 클릭 → 그룹
A8: 4 | B8: [출하실적] 피벗에 '개당단가' 계산 필드 만들기 (금액÷수량). | C8: □ | D8: 피벗 분석 → 필드·항목 및 집합
A9: 5 | B9: [출하실적] 금액을 '열 합계 비율(%)' 로 보이게 바꾸기. | C9: □ | D9: 값 필드 설정 → 값 표시 형식
A10: 6 | B10: [출하실적] 피벗에 담당자를 보고서 필터로 넣기. | C10: □ | D10: 필드를 [필터] 로 끌기
A11: 7 | B11: [출하실적] 피벗에 슬라이서(지역) 넣기. | C11: □ | D11: 피벗 분석 → 슬라이서 삽입
A12: 8 | B12: [출하실적] 담당자 오름차순 + 금액 내림차순 정렬. | C12: □ | D12: 데이터 → 정렬 → 기준 추가
A13: 9 | B13: [출하실적] 거래처+제품 이 겹치는 중복 행 제거. | C13: □ | D13: 데이터 → 중복된 항목 제거
A14: 10 | B14: [출하실적] 거래처별 금액 합계 부분합 (정렬 먼저). | C14: □ | D14: 데이터 → 부분합
A15: 11 | B15: [통합대상] 세 분기 표를 제품 기준으로 A15 부터 통합. | C15: □ | D15: 데이터 → 통합
A16: 12 | B16: [데이터표] 1변수 데이터 표 완성. | C16: □ | D16: 열 입력 셀 $B$4
... A18: 14 | B18: [데이터표] 영업이익이 0 이 되는 판매수량 구하기 (손익분기점). | C18: □ | D18: 목표값 찾기

Sheet 따라하기
A1: 1급 ② 분석작업 — 단계별로 따라 하기
A2: 1급 분석작업은 메뉴 위치와 체크박스 하나에서 점수가 갈립니다. 순서대로 한 번씩 해 보세요.
A4: 미션 1 · 금액 채우기
A5: 어디서 | B5: [출하실적] G4 → G51
A6: 1단계 | B6: G4 의 0 을 지우고 =E4*F4 를 넣습니다. | C6: 수량 × 단가
A7: 2단계 | B7: G4 오른쪽 아래 네모를 두 번 클릭합니다. | C7: 51행까지 한 번에 채워집니다
A8: 3단계 | B8: 표 아래 [금액 채점] 이 48 / 48 인지 봅니다.
A9: 확인 | B9: 이렇게 되면 성공 — G열이 모두 채워집니다
A11: 미션 2 · 피벗 테이블 만들기
A12: 어디서 | B12: [출하실적] 삽입 → 피벗 테이블
A13: 1단계 | B13: 표 안의 아무 칸을 클릭하고 삽입 → 피벗 테이블 → 확인. | C13: 범위는 저절로 잡힙니다
A14: 2단계 | B14: 오른쪽 필드 목록에서 지역 을 [행] 으로 끕니다.
A15: 3단계 | B15: 제품 을 [열] 로, 금액 을 [값] 으로 끕니다. | C15: 숫자는 자동으로 합계가 됩니다
A16: 4단계 | B16: 값 영역에서 오른쪽 클릭 → 값 필드 설정 → 표시 형식 → 쉼표.
A17: 확인 | B17: 이렇게 되면 성공 — 지역 × 제품 의 금액 표가 만들어집니다
A19: 미션 3 · 날짜를 분기로 그룹화
A20: 어디서 | B20: 피벗 안의 날짜 필드
A21: 1단계 | B21: 출하일 을 [행] 으로 끌어 놓습니다. | C21: 날짜가 하루씩 나열됩니다
A22: 2단계 | B22: 피벗 안의 날짜 셀 하나를 오른쪽 클릭 → [그룹].
A23: 3단계 | B23: [분기] 를 고릅니다. (월도 함께 고르면 계층이 생깁니다) | C23: 확인
A24: 4단계 | B24: 행 영역에서 분기와 지역의 순서를 끌어 바꿔 봅니다. | C24: 위에 있는 것이 바깥 묶음이 됩니다
A25: 확인 | B25: 이렇게 되면 성공 — 1분기·2분기… 로 묶여 나옵니다
A27: 미션 4 · 계산 필드 만들기
A28: 어디서 | B28: 피벗 분석 → 필드, 항목 및 집합
A29: 1단계 | B29: 피벗 안을 클릭하고 [피벗 테이블 분석] 탭을 엽니다. | C29: 리본 맨 오른쪽 그룹
A30: 2단계 | B30: [필드, 항목 및 집합] → [계산 필드].
A31: 3단계 | B31: 이름에 개당단가 , 수식에 =금액/수량 을 넣습니다. | C31: 필드 이름은 아래 목록에서 더블클릭해 넣으면 오타가 없습니다
A32: 4단계 | B32: [추가] → 확인. | C32: ★ 원본 표를 건드리지 않고 피벗 안에서만 새 열이 생깁니다
A33: 확인 | B33: 이렇게 되면 성공 — 값 영역에 '합계: 개당단가' 가 나타납니다
A35: 미션 5 · 값 표시 형식 — 비율로 보기
A36: 어디서 | B36: 피벗 값 영역
A37: 1단계 | B37: 값 영역의 숫자 하나를 오른쪽 클릭합니다.
A38: 2단계 | B38: [값 표시 형식] → [열 합계 비율].
A39: 3단계 | B39: 숫자가 %로 바뀌는지 봅니다. | C39: 합계가 100% 가 됩니다
A40: 4단계 | B40: 되돌리려면 같은 자리에서 [계산 없음].
A41: 확인 | B41: 이렇게 되면 성공 — 각 칸이 그 열에서 차지하는 비중(%)으로 보입니다
A43: 미션 6 · 보고서 필터 · 슬라이서
A44: 어디서 | B44: 피벗 필드 목록 · 피벗 분석 탭
A45: 1단계 | B45: 담당자 를 [필터] 영역으로 끕니다. | C45: 피벗 맨 위에 필터 칸이 생깁니다
A46: 2단계 | B46: 그 칸에서 한 사람을 골라 봅니다. | C46: 표 전체가 그 사람 것만 보여 줍니다
...

Sheet 계산 문제 정답
A1: 1급 ② 분석작업 — 계산 문제 정답
A2: 먼저 스스로 만들어 본 뒤에 펼쳐 보세요. [넣을 칸] 이 그 답을 적을 자리이고, [정답값] 은 제대로 넣었을 때 나와야 하는 값입니다.
A4: 표 아래 계산 문제 6개
A5: 번호 | B5: 넣을 칸 | C5: 무엇을 구하나 | D5: 정답 수식 | E5: 정답값 | F5: 왜 그런가 · 자주 하는 실수
A6: 1 | B6: 출하실적 E59 | C6: 전체 금액[G4:G51] 합계. (G열을 먼저 채우세요) | D6: =SUM(G4:G51) | E6: ='출하실적'!AB59
A7: 2 | B7: 출하실적 E60 | C7: '수도권' 의 수량 합계. | D7: =SUMIF($B$4:$B$51,"수도권",$E$4:$E$51) | E7: ='출하실적'!AB60
A8: 3 | B8: 출하실적 E61 | C8: '수도권' 이면서 제품이 '구동축' 인 건수. | D8: =COUNTIFS(B4:B51,"수도권",D4:D51,"구동축") | E8: ='출하실적'!AB61
A9: 4 | B9: 출하실적 E62 | C9: 거래처가 '대한정밀' 인 줄의 평균 수량을 소수 첫째 자리까지. | D9: =ROUND(AVERAGEIF($C$4:$C$51,"대한정밀",$E$4:$E$51),1) | E9: ='출하실적'!AB62
A10: 5 | B10: 출하실적 E63 | C10: 1분기(1~3월)에 출하된 건수. | D10: =SUMPRODUCT((MONTH(A4:A51)<=3)*1) | E10: ='출하실적'!AB63 | F10: 조건에 함수를 써야 할 때는 SUMPRODUCT 가 편합니다
A11: 6 | B11: 출하실적 E64 | C11: 담당자별로 가장 많은 수량을 낸 한 건의 수량. (담당자 '김현수' 기준) | D11: =SUMPRODUCT(MAX((H4:H51="김현수")*E4:E51)) | E11: ='출하실적'!AB64
