Workbook

Sheet 읽어보기
B2: 1급 실기 ③ 기타작업 — 차트 · 매크로 · 사용자 정의 함수
B4: 시트 안내
B5: 설비가동 — 콤보 차트·보조 축·추세선 연습용 자료 + 계산 문제 5개
B6: 양식 — 양식 컨트롤(단추·옵션 단추·스핀 단추)을 붙여 볼 자리
B7: 미션 — 해야 할 일 14가지 체크리스트
B8: 따라하기 — 14가지를 1단계·2단계… 로 (VBA 코드도 그대로 옮겨 쓸 수 있게)
B10: 매크로 · VBA 를 쓰기 전에
B11: ① 파일 → 옵션 → 리본 사용자 지정 → '개발 도구' 체크
B12: ② Alt + F11 로 VBE(코드 창)를 엽니다.
B13: ③ 삽입 → 모듈 에 코드를 씁니다. 워크시트에서 쓰는 함수는 Function ~ End Function.
B14: ④ 저장할 때 반드시 [Excel 매크로 사용 통합 문서 (*.xlsm)] 을 고릅니다.
B15: 이 파일은 .xlsx 입니다. 매크로·사용자 정의 함수를 넣은 뒤에는 xlsm 으로 '다른 이름으로 저장' 하세요.

Sheet 설비가동
A1: 설비 가동 · 보전 실적 (2026년)
A3: 월 | B3: 가동시간(h) | C3: 정지시간(h) | D3: 가동률 | E3: 보전비용(천원) | F3: 고장건수
A4: 1월 | B4: 612 | C4: 28 | D4: 0 | E4: 4200 | F4: 7 | AB4: =B4/(B4+C4)
A5: 2월 | B5: 578 | C5: 42 | E5: 5100 | F5: 11 | AB5: =B5/(B5+C5)
A6: 3월 | B6: 640 | C6: 19 | E6: 3300 | F6: 5 | AB6: =B6/(B6+C6)
A7: 4월 | B7: 604 | C7: 35 | E7: 4800 | F7: 9 | AB7: =B7/(B7+C7)
A8: 5월 | B8: 655 | C8: 14 | E8: 2900 | F8: 4 | AB8: =B8/(B8+C8)
A9: 6월 | B9: 618 | C9: 46 | E9: 6200 | F9: 13 | AB9: =B9/(B9+C9)
A10: 7월 | B10: 590 | C10: 52 | E10: 7100 | F10: 15 | AB10: =B10/(B10+C10)
A11: 8월 | B11: 505 | C11: 21 | E11: 3600 | F11: 6 | AB11: =B11/(B11+C11)
A12: 9월 | B12: 648 | C12: 17 | E12: 3100 | F12: 5 | AB12: =B12/(B12+C12)
A13: 10월 | B13: 662 | C13: 25 | E13: 4000 | F13: 8 | AB13: =B13/(B13+C13)
A14: 11월 | B14: 671 | C14: 12 | E14: 2600 | F14: 3 | AB14: =B14/(B14+C14)
A15: 12월 | B15: 596 | C15: 38 | E15: 5400 | F15: 10 | AB15: =B15/(B15+C15)
A17: 채점 → | D17: =SUMPRODUCT(--(ROUND($D$4:$D$15,4)=ROUND($AB$4:$AB$15,4)))&" / 12"
A18: D4 에 =B4/(B4+C4) 를 만들고 아래로 끌어 채우세요. 서식이 0.0% 이니 *100 을 하면 안 됩니다.
A20: ■ 계산 문제 5개
A21: 번호 ▶ 넣을 칸 | B21: 문제 — 무엇을 구하나 | D21: 답 | E21: 채점 | F21: 힌트
A22: 차트에 쓸 값 — ▶ 표시된 칸(D열)에
A23: 1 ▶D23 | B23: 한 해 보전비용[E4:E15] 합계. | D23: 0 | E23: =IF(NOT(_xlfn.ISFORMULA(D23)),"↖ 0 지우고 수식",IF(IFERROR(ROUND(D23,4)=ROUND(AB23,4),D23=AB23),"✔ 맞음","✘ 다시")) | F23: SUM | AB23: =SUM(E4:E15)
A24: 2 ▶D24 | B24: 고장건수[F4:F15] 가 가장 많았던 달의 이름. (예: 7월) | D24: 0 | E24: =IF(NOT(_xlfn.ISFORMULA(D24)),"↖ 0 지우고 수식",IF(IFERROR(ROUND(D24,4)=ROUND(AB24,4),D24=AB24),"✔ 맞음","✘ 다시")) | F24: INDEX 와 MATCH | AB24: =INDEX(A4:A15,MATCH(MAX(F4:F15),F4:F15,0))
A25: 3 ▶D25 | B25: 보전비용과 고장건수의 상관계수를 소수 셋째 자리까지. | D25: 0 | E25: =IF(NOT(_xlfn.ISFORMULA(D25)),"↖ 0 지우고 수식",IF(IFERROR(ROUND(D25,4)=ROUND(AB25,4),D25=AB25),"✔ 맞음","✘ 다시")) | F25: CORREL(범위1, 범위2) 를 ROUND 로 | AB25: =ROUND(CORREL(E4:E15,F4:F15),3)
A26: 4 ▶D26 | B26: 가동률이 95% 를 넘은 달의 수. (D열을 먼저 채우세요) | D26: 0 | E26: =IF(NOT(_xlfn.ISFORMULA(D26)),"↖ 0 지우고 수식",IF(IFERROR(ROUND(D26,4)=ROUND(AB26,4),D26=AB26),"✔ 맞음","✘ 다시")) | F26: SUMPRODUCT 로 두 값을 견줍니다 | AB26: =SUMPRODUCT((AB4:AB15>0.95)*1)
A27: 5 ▶D27 | B27: 정지시간[C4:C15] 상위 3개월의 합계. | D27: 0 | E27: =IF(NOT(_xlfn.ISFORMULA(D27)),"↖ 0 지우고 수식",IF(IFERROR(ROUND(D27,4)=ROUND(AB27,4),D27=AB27),"✔ 맞음","✘ 다시")) | F27: LARGE 세 번 | AB27: =LARGE(C4:C15,1)+LARGE(C4:C15,2)+LARGE(C4:C15,3)

Sheet 양식
A1: 양식 컨트롤 연습
A2: 개발 도구 → 삽입 → 양식 컨트롤 에서 꺼내 시트에 그립니다.
A4: 옵션 단추가 고른 번호 | E4: ① 옵션 단추 4개를 그리고, 컨트롤 서식 → 셀 연결에 $B$4 를 지정
A5: 고른 라인 이름 | E5: ② B5 에 INDEX 로 번호에 해당하는 라인 이름이 나오게 (=INDEX(B9:B12,B4))
A6: 스핀 단추가 고른 목표 가동률(%) | E6: ③ 스핀 단추를 그리고 셀 연결 $B$6, 최소 80 · 최대 100 · 증분 1
E7: ④ 단추를 하나 그려 '서식초기화' 매크로에 연결
A8: 번호 | B8: 라인
A9: 1 | B9: A라인(가공)
A10: 2 | B10: B라인(조립)
A11: 3 | B11: C라인(검사)
A12: 4 | B12: D라인(포장)

Sheet 미션
A1: 1급 ③ 기타작업 미션 14가지
A2: 12~14번을 하면 반드시 .xlsm 으로 저장해야 매크로가 남습니다.
A4: 번호 | B4: 미션 — 무엇을 하는가 | C4: 다 함 | D4: 어디서 (메뉴)
A5: 1 | B5: [설비가동 D4] 가동률 채우고 아래로 끌어 채우기. | C5: □ | D5: =B4/(B4+C4)
A6: 2 | B6: [설비가동] 보전비용 막대 + 고장건수 꺾은선(보조 축) 콤보 차트 만들기. | C6: □ | D6: 차트 종류 변경 → 콤보
A7: 3 | B7: [설비가동] 차트 제목 '월별 보전비용과 고장건수'. | C7: □ | D7: 차트 요소(+)
A8: 4 | B8: [설비가동] 보전비용 계열에 선형 추세선 넣기. | C8: □ | D8: 차트 요소 → 추세선
A9: 5 | B9: [설비가동] 추세선에 수식과 R² 표시하기. | C9: □ | D9: 추세선 서식
A10: 6 | B10: [설비가동] 고장건수가 가장 많은 달에만 데이터 레이블 달기. | C10: □ | D10: 그 점만 한 번 더 클릭
A11: 7 | B11: [설비가동] 보조 축 제목을 '건' 으로 달기. | C11: □ | D11: 차트 요소 → 축 제목
A12: 8 | B12: [설비가동] 차트 영역에 그림자/테두리 주기. | C12: □ | D12: 차트 영역 서식
A13: 9 | B13: [양식] 옵션 단추 4개 만들어 $B$4 에 연결. | C13: □ | D13: 개발 도구 → 삽입 → 양식 컨트롤
A14: 10 | B14: [양식 B5] INDEX 로 고른 라인 이름 나오게. | C14: □ | D14: =INDEX(B9:B12,B4)
A15: 11 | B15: [양식] 스핀 단추 만들어 $B$6 에 연결 (80~100). | C15: □ | D15: 컨트롤 서식
A16: 12 | B16: [설비가동] '가동률서식' 매크로 기록해 단추에 연결. | C16: □ | D16: 개발 도구 → 매크로 기록
... A18: 14 | B18: 파일을 .xlsm 으로 저장하기. | C18: □ | D18: 다른 이름으로 저장 → 형식

Sheet 따라하기
A1: 1급 ③ 기타작업 — 단계별로 따라 하기
A2: 차트는 범위를 잡는 것부터, 매크로는 개발 도구 탭을 켜는 것부터 시작합니다. VBA 코드는 그대로 옮겨 치면 됩니다.
A4: 미션 1 · 가동률 채우기
A5: 어디서 | B5: [설비가동] D4 → D15
A6: 1단계 | B6: D4 의 0 을 지우고 =B4/(B4+C4) 를 넣습니다. | C6: 가동시간 ÷ (가동+정지)
A7: 2단계 | B7: 채우기 핸들을 15행까지 끌어 내립니다.
A8: 3단계 | B8: 채점 줄이 12 / 12 인지 봅니다.
A9: 확인 | B9: 이렇게 되면 성공 — 95.6% 처럼 나옵니다
A11: 미션 2 · 콤보 차트 만들기
A12: 어디서 | B12: [설비가동] 삽입 → 차트
A13: 1단계 | B13: A3:A15 를 잡고, Ctrl 을 누른 채 E3:F15 도 함께 잡습니다. | C13: 떨어진 범위는 Ctrl 로 함께 잡습니다
A14: 2단계 | B14: 삽입 → [콤보 차트] → 사용자 지정 콤보. | C14: 차트 그룹 맨 오른쪽
A15: 3단계 | B15: 보전비용 = 묶은 세로 막대형, 고장건수 = 표식이 있는 꺾은선형 으로.
A16: 4단계 | B16: 고장건수 줄의 [보조 축] 에 체크하고 확인. | C16: ★ 단위가 다른 값(원과 건)을 함께 볼 때 씁니다
A17: 확인 | B17: 이렇게 되면 성공 — 막대 위로 선이 지나가고 오른쪽에 두 번째 축이 생깁니다
A19: 미션 3 · 제목 · 축 제목 달기
A20: 어디서 | B20: 차트 요소(+)
A21: 1단계 | B21: 차트 클릭 → [+] → [차트 제목] 체크.
A22: 2단계 | B22: 제목 글자를 '월별 보전비용과 고장건수' 로 고칩니다.
A23: 3단계 | B23: [+] → [축 제목] → [보조 세로] 체크.
A24: 4단계 | B24: 보조 축 제목을 '건' 으로 고칩니다. | C24: 왼쪽 축 제목은 '천원'
A25: 확인 | B25: 이렇게 되면 성공 — 제목과 두 축 이름이 붙습니다
A27: 미션 4 · 추세선 넣고 수식 보이기
A28: 어디서 | B28: 차트 → 보전비용 막대
A29: 1단계 | B29: 보전비용 막대 하나를 클릭합니다. | C29: 계열 전체가 선택됩니다
A30: 2단계 | B30: 오른쪽 클릭 → [추세선 추가]. | C30: 또는 차트 요소(+) → 추세선
A31: 3단계 | B31: 오른쪽 창에서 [선형] 을 고릅니다.
A32: 4단계 | B32: 맨 아래 [수식을 차트에 표시] 와 [R-제곱 값을 차트에 표시] 를 체크. | C32: R² 가 1 에 가까울수록 추세선이 잘 맞는다는 뜻
A33: 확인 | B33: 이렇게 되면 성공 — 점선 추세선과 y=... 수식이 차트에 나타납니다
A35: 미션 5 · 한 점에만 데이터 레이블
A36: 어디서 | B36: 차트 → 고장건수 꺾은선
A37: 1단계 | B37: 고장건수 선을 한 번 클릭합니다. | C37: 계열 전체 선택
A38: 2단계 | B38: 가장 높은 점(7월)을 한 번 더 클릭합니다. | C38: ★ 더블클릭이 아니라 '한 번씩 두 번'
A39: 3단계 | B39: 그 점만 선택된 것을 확인하고 오른쪽 클릭 → [데이터 레이블 추가].
A40: 4단계 | B40: 레이블을 끌어 보기 좋은 자리로 옮깁니다.
A41: 확인 | B41: 이렇게 되면 성공 — 7월 점 위에만 15 라는 숫자가 붙습니다
A43: 미션 6 · 차트 영역 꾸미기
A44: 어디서 | B44: 차트 영역 서식
A45: 1단계 | B45: 차트의 빈 곳(테두리 안쪽)을 오른쪽 클릭 → [차트 영역 서식].
A46: 2단계 | B46: [채우기 및 선] → 테두리 → 실선 + 둥근 모서리.
...

Sheet 계산 문제 정답
A1: 1급 ③ 기타작업 — 계산 문제 정답
A2: 먼저 스스로 만들어 본 뒤에 펼쳐 보세요. [넣을 칸] 이 그 답을 적을 자리이고, [정답값] 은 제대로 넣었을 때 나와야 하는 값입니다.
A4: 차트에 쓸 값 5개
A5: 번호 | B5: 넣을 칸 | C5: 무엇을 구하나 | D5: 정답 수식 | E5: 정답값 | F5: 왜 그런가 · 자주 하는 실수
A6: 1 | B6: 설비가동 D23 | C6: 한 해 보전비용[E4:E15] 합계. | D6: =SUM(E4:E15) | E6: ='설비가동'!AB23
A7: 2 | B7: 설비가동 D24 | C7: 고장건수[F4:F15] 가 가장 많았던 달의 이름. (예: 7월) | D7: =INDEX(A4:A15,MATCH(MAX(F4:F15),F4:F15,0)) | E7: ='설비가동'!AB24 | F7: 차트에서 그 점만 강조할 때 쓸 값입니다
A8: 3 | B8: 설비가동 D25 | C8: 보전비용과 고장건수의 상관계수를 소수 셋째 자리까지. | D8: =ROUND(CORREL(E4:E15,F4:F15),3) | E8: ='설비가동'!AB25 | F8: 1 에 가까울수록 '고장이 많은 달에 돈도 많이 들었다' 는 뜻입니다
A9: 4 | B9: 설비가동 D26 | C9: 가동률이 95% 를 넘은 달의 수. (D열을 먼저 채우세요) | D9: =SUMPRODUCT((D4:D15>0.95)*1) | E9: ='설비가동'!AB26
A10: 5 | B10: 설비가동 D27 | C10: 정지시간[C4:C15] 상위 3개월의 합계. | D10: =LARGE(C4:C15,1)+LARGE(C4:C15,2)+LARGE(C4:C15,3) | E10: ='설비가동'!AB27
