Workbook

Sheet 읽어보기
B2: 1급 실기 ① 계산작업 — 공정 품질검사 기록
B4: 검사 기록 30건입니다. 1급의 고비인 배열 수식 · 다중 조건 · 찾기참조 중첩을 집중해서 풉니다.
B6: 이 파일을 푸는 법
B7: ① 노란 칸에는 0 이 들어 있습니다. 그 0 을 지우고 = 로 시작하는 수식을 넣습니다.
B8: ② 문제 왼쪽의 ▶F40 같은 표시가 '답을 넣을 칸' 입니다.
B9: ③ 넣고 나면 오른쪽 [채점] 칸이 스스로 ✔ 맞음 / ✘ 다시 로 바뀝니다.
B11: 시트 안내
B12: 따라하기 — 배열 수식을 처음 넣어 보는 사람이 먼저 볼 것
B13: 품질검사 — 표의 노란 열 4개(H~K) + 아래쪽 집계 34문제
B14: DB조건 — 데이터베이스 함수 10문제 + 고급 필터용 수식 조건
B15: 함수사전 — 1급에 나오는 함수의 형식 · 살아 있는 예시 · 자주 하는 실수
B16: 정답·해설 — 넣을 칸 · 정답 수식 · 정답값 · 왜 그런지
... B24: SUMPRODUCT 를 쓰면 Ctrl+Shift+Enter 없이도 같은 계산이 됩니다. 다만 시험에서 문제가 함수를 지정했다면 그 함수를 써야 합니다.

Sheet 따라하기
A1: 1급 계산작업 — 먼저 이 네 가지
A2: 1급에서 가장 많이 막히는 곳이 배열 수식입니다. 아래 순서대로 한 번만 해 보면 감이 옵니다.
A4: 미션 1 · 배열 수식 넣기
A5: 어디서 | B5: [품질검사] 시트 집계 1번 칸
A6: 1단계 | B6: 집계 1번의 ▶ 표시가 가리키는 칸을 클릭하고 0 을 지웁니다. | C6: 번호 옆에 F40 처럼 주소가 적혀 있습니다
A7: 2단계 | B7: =SUM((C5:C34="가공")*F5:F34) 를 입력합니다. | C7: 중괄호 { } 는 치지 않습니다
A8: 3단계 | B8: ★ Enter 가 아니라 Ctrl + Shift + Enter 를 함께 누릅니다. | C8: 세 손가락을 동시에 누릅니다
A9: 4단계 | B9: 칸을 다시 클릭해 수식 줄을 봅니다. | C9: {=SUM((C5:C34="가공")*F5:F34)} 처럼 중괄호가 붙어 있으면 성공
A10: 확인 | B10: 이렇게 되면 성공 — 99 같은 숫자가 나오고 채점 칸이 ✔ 맞음 으로 바뀝니다
A12: 미션 2 · 조건을 곱하고 더하는 뜻 이해하기
A13: 어디서 | B13: [품질검사] 아무 빈 칸에서 연습
A14: 1단계 | B14: 빈 칸에 =(C5="가공") 을 넣고 Enter. | C14: TRUE 또는 FALSE 가 나옵니다
A15: 2단계 | B15: =(C5="가공")*1 을 넣어 봅니다. | C15: TRUE 는 1, FALSE 는 0 이 됩니다
A16: 3단계 | B16: =(C5="가공")*(F5>=10) 을 넣어 봅니다. | C16: 둘 다 참일 때만 1 — 곱하기가 '그리고'
A17: 4단계 | B17: =(C5="조립")+(C5="검사") 을 넣어 봅니다. | C17: 둘 중 하나면 1 — 더하기가 '또는'
A18: 확인 | B18: 이렇게 되면 성공 — 곱하기=그리고, 더하기=또는 이라는 것이 눈으로 확인됩니다
A20: 미션 3 · INDEX + MATCH 만들기
A21: 어디서 | B21: [품질검사] 찾기·참조 문제
A22: 1단계 | B22: 먼저 MATCH 만 써 봅니다 : =MATCH(MAX(F5:F34),F5:F34,0) | C22: 몇 번째 줄인지(숫자)가 나옵니다
A23: 2단계 | B23: 그 숫자를 INDEX 에 넣습니다 : =INDEX(B5:B34, 그 숫자) | C23: 그 자리의 로트번호가 나옵니다
A24: 3단계 | B24: 둘을 하나로 합칩니다 : =INDEX(B5:B34,MATCH(MAX(F5:F34),F5:F34,0)) | C24: 안쪽부터 계산됩니다
A25: 4단계 | B25: 범위 두 개(B5:B34 와 F5:F34)의 줄 수가 같은지 꼭 확인합니다. | C25: 한 줄이라도 어긋나면 엉뚱한 값이 나옵니다
A26: 확인 | B26: 이렇게 되면 성공 — 불량이 가장 많았던 로트번호가 나옵니다
A28: 미션 4 · 채점 칸 읽기 · 정답 보기
A29: 어디서 | B29: [품질검사] [채점] 열 · [정답·해설] 시트
A30: 1단계 | B30: 아직 수식이 없으면 ↖ 0 지우고 수식 이라고 나옵니다. | C30: 0 은 답이 아니라 '여기에 넣으라' 는 표시
A31: 2단계 | B31: 맞으면 ✔ 맞음(초록), 틀리면 ✘ 다시(빨강). | C31: 수식이 달라도 결과값이 같으면 맞음입니다
A32: 3단계 | B32: 배열 문제에서 #VALUE! 가 나오면 Ctrl+Shift+Enter 를 안 누른 것입니다. | C32: 수식 줄을 클릭한 뒤 다시 Ctrl+Shift+Enter
A33: 4단계 | B33: [정답·해설] 시트에 넣을 칸·정답 수식·정답값이 다 있습니다. | C33: 먼저 스스로 해 본 뒤에 보세요
A34: 확인 | B34: 이렇게 되면 성공 — 문제를 풀수록 초록 칸이 늘어납니다

Sheet 품질검사
A1: 2026년 3월 · 공정 품질검사 기록
A2: 노란 칸의 0 을 지우고 수식을 넣으세요. H 불량률 = 불량수÷검사수량 · I 등급(IFS) · J 규격판정(50.00±0.05) · K 로트월(로트번호 5번째부터 2글자)
A4: 검사일 | B4: 로트번호 | C4: 공정 | D4: 작업자 | E4: 검사수량 | F4: 불량수 | G4: 측정값(mm) | H4: 불량률 | I4: 등급 | J4: 규격판정 | K4: 로트월 | N4: 불량률 하한 | O4: 등급
A5: 46083 | B5: L26-0302-A | C5: 가공 | D5: 김현수 | E5: 480 | F5: 4 | G5: 50.02 | H5: 0 | I5: 0 | J5: 0 | K5: 0 | N5: 0 | O5: A | AB5: =F5/E5 | AC5: =_xlfn.IFS(F5/E5<1%,"A",F5/E5<3%,"B",F5/E5<5%,"C",TRUE,"D") | AD5: =IF(AND(G5>=49.95,G5<=50.05),"합격","불합격") | AE5: =MID(B5,5,2)
A6: 46083 | B6: L26-0302-B | C6: 조립 | D6: 박지훈 | E6: 320 | F6: 9 | G6: 49.97 | N6: 0.01 | O6: B | AB6: =F6/E6 | AC6: =_xlfn.IFS(F6/E6<1%,"A",F6/E6<3%,"B",F6/E6<5%,"C",TRUE,"D") | AD6: =IF(AND(G6>=49.95,G6<=50.05),"합격","불합격") | AE6: =MID(B6,5,2)
A7: 46084 | B7: L26-0303-A | C7: 가공 | D7: 이서연 | E7: 510 | F7: 16 | G7: 50.08 | N7: 0.03 | O7: C | AB7: =F7/E7 | AC7: =_xlfn.IFS(F7/E7<1%,"A",F7/E7<3%,"B",F7/E7<5%,"C",TRUE,"D") | AD7: =IF(AND(G7>=49.95,G7<=50.05),"합격","불합격") | AE7: =MID(B7,5,2)
A8: 46084 | B8: L26-0303-C | C8: 검사 | D8: 최민재 | E8: 260 | F8: 2 | G8: 49.99 | N8: 0.05 | O8: D | AB8: =F8/E8 | AC8: =_xlfn.IFS(F8/E8<1%,"A",F8/E8<3%,"B",F8/E8<5%,"C",TRUE,"D") | AD8: =IF(AND(G8>=49.95,G8<=50.05),"합격","불합격") | AE8: =MID(B8,5,2)
A9: 46085 | B9: L26-0304-A | C9: 가공 | D9: 김현수 | E9: 495 | F9: 7 | G9: 50.01 | N9: ↑ VLOOKUP 근사값(TRUE) 연습용 (N5:O8) | AB9: =F9/E9 | AC9: =_xlfn.IFS(F9/E9<1%,"A",F9/E9<3%,"B",F9/E9<5%,"C",TRUE,"D") | AD9: =IF(AND(G9>=49.95,G9<=50.05),"합격","불합격") | AE9: =MID(B9,5,2)
A10: 46085 | B10: L26-0304-B | C10: 조립 | D10: 박지훈 | E10: 340 | F10: 21 | G10: 49.91 | AB10: =F10/E10 | AC10: =_xlfn.IFS(F10/E10<1%,"A",F10/E10<3%,"B",F10/E10<5%,"C",TRUE,"D") | AD10: =IF(AND(G10>=49.95,G10<=50.05),"합격","불합격") | AE10: =MID(B10,5,2)
A11: 46086 | B11: L26-0305-C | C11: 포장 | D11: 정우진 | E11: 600 | F11: 3 | G11: 50 | N11: 규격 : 50.00 ± 0.05 mm | AB11: =F11/E11 | AC11: =_xlfn.IFS(F11/E11<1%,"A",F11/E11<3%,"B",F11/E11<5%,"C",TRUE,"D") | AD11: =IF(AND(G11>=49.95,G11<=50.05),"합격","불합격") | AE11: =MID(B11,5,2)
A12: 46086 | B12: L26-0305-A | C12: 가공 | D12: 이서연 | E12: 470 | F12: 12 | G12: 50.05 | AB12: =F12/E12 | AC12: =_xlfn.IFS(F12/E12<1%,"A",F12/E12<3%,"B",F12/E12<5%,"C",TRUE,"D") | AD12: =IF(AND(G12>=49.95,G12<=50.05),"합격","불합격") | AE12: =MID(B12,5,2)
A13: 46087 | B13: L26-0306-B | C13: 조립 | D13: 김현수 | E13: 355 | F13: 5 | G13: 49.96 | AB13: =F13/E13 | AC13: =_xlfn.IFS(F13/E13<1%,"A",F13/E13<3%,"B",F13/E13<5%,"C",TRUE,"D") | AD13: =IF(AND(G13>=49.95,G13<=50.05),"합격","불합격") | AE13: =MID(B13,5,2)
A14: 46087 | B14: L26-0306-C | C14: 검사 | D14: 최민재 | E14: 280 | F14: 14 | G14: 50.09 | AB14: =F14/E14 | AC14: =_xlfn.IFS(F14/E14<1%,"A",F14/E14<3%,"B",F14/E14<5%,"C",TRUE,"D") | AD14: =IF(AND(G14>=49.95,G14<=50.05),"합격","불합격") | AE14: =MID(B14,5,2)
A15: 46090 | B15: L26-0309-A | C15: 가공 | D15: 박지훈 | E15: 505 | F15: 6 | G15: 50.03 | AB15: =F15/E15 | AC15: =_xlfn.IFS(F15/E15<1%,"A",F15/E15<3%,"B",F15/E15<5%,"C",TRUE,"D") | AD15: =IF(AND(G15>=49.95,G15<=50.05),"합격","불합격") | AE15: =MID(B15,5,2)
A16: 46090 | B16: L26-0309-B | C16: 조립 | D16: 이서연 | E16: 310 | F16: 18 | G16: 49.88 | AB16: =F16/E16 | AC16: =_xlfn.IFS(F16/E16<1%,"A",F16/E16<3%,"B",F16/E16<5%,"C",TRUE,"D") | AD16: =IF(AND(G16>=49.95,G16<=50.05),"합격","불합격") | AE16: =MID(B16,5,2)
A17: 46091 | B17: L26-0310-C | C17: 포장 | D17: 정우진 | E17: 620 | F17: 8 | G17: 50.01 | AB17: =F17/E17 | AC17: =_xlfn.IFS(F17/E17<1%,"A",F17/E17<3%,"B",F17/E17<5%,"C",TRUE,"D") | AD17: =IF(AND(G17>=49.95,G17<=50.05),"합격","불합격") | AE17: =MID(B17,5,2)
A18: 46091 | B18: L26-0310-A | C18: 가공 | D18: 김현수 | E18: 488 | F18: 25 | G18: 50.12 | AB18: =F18/E18 | AC18: =_xlfn.IFS(F18/E18<1%,"A",F18/E18<3%,"B",F18/E18<5%,"C",TRUE,"D") | AD18: =IF(AND(G18>=49.95,G18<=50.05),"합격","불합격") | AE18: =MID(B18,5,2)
A19: 46092 | B19: L26-0311-B | C19: 조립 | D19: 최민재 | E19: 330 | F19: 11 | G19: 49.94 | AB19: =F19/E19 | AC19: =_xlfn.IFS(F19/E19<1%,"A",F19/E19<3%,"B",F19/E19<5%,"C",TRUE,"D") | AD19: =IF(AND(G19>=49.95,G19<=50.05),"합격","불합격") | AE19: =MID(B19,5,2)
A20: 46092 | B20: L26-0311-C | C20: 검사 | D20: 박지훈 | E20: 275 | F20: 1 | G20: 50 | AB20: =F20/E20 | AC20: =_xlfn.IFS(F20/E20<1%,"A",F20/E20<3%,"B",F20/E20<5%,"C",TRUE,"D") | AD20: =IF(AND(G20>=49.95,G20<=50.05),"합격","불합격") | AE20: =MID(B20,5,2)
A21: 46093 | B21: L26-0312-A | C21: 가공 | D21: 이서연 | E21: 512 | F21: 19 | G21: 50.06 | AB21: =F21/E21 | AC21: =_xlfn.IFS(F21/E21<1%,"A",F21/E21<3%,"B",F21/E21<5%,"C",TRUE,"D") | AD21: =IF(AND(G21>=49.95,G21<=50.05),"합격","불합격") | AE21: =MID(B21,5,2)
A22: 46093 | B22: L26-0312-B | C22: 조립 | D22: 김현수 | E22: 345 | F22: 7 | G22: 49.98 | AB22: =F22/E22 | AC22: =_xlfn.IFS(F22/E22<1%,"A",F22/E22<3%,"B",F22/E22<5%,"C",TRUE,"D") | AD22: =IF(AND(G22>=49.95,G22<=50.05),"합격","불합격") | AE22: =MID(B22,5,2)
A23: 46094 | B23: L26-0313-C | C23: 포장 | D23: 정우진 | E23: 590 | F23: 13 | G23: 50.04 | AB23: =F23/E23 | AC23: =_xlfn.IFS(F23/E23<1%,"A",F23/E23<3%,"B",F23/E23<5%,"C",TRUE,"D") | AD23: =IF(AND(G23>=49.95,G23<=50.05),"합격","불합격") | AE23: =MID(B23,5,2)
... A34: 46101 | B34: L26-0320-C | C34: 포장 | D34: 최민재 | E34: 608 | F34: 17 | G34: 50.1 | AB34: =F34/E34 | AC34: =_xlfn.IFS(F34/E34<1%,"A",F34/E34<3%,"B",F34/E34<5%,"C",TRUE,"D") | AD34: =IF(AND(G34>=49.95,G34<=50.05),"합격","불합격") | AE34: =MID(B34,5,2)
A36: 표 채점 → | H36: =SUMPRODUCT(--(ROUND($H$5:$H$34,4)=ROUND($AB$5:$AB$34,4)))&" / 30" | I36: =SUMPRODUCT(--($I$5:$I$34=$AC$5:$AC$34))&" / 30" | J36: =SUMPRODUCT(--($J$5:$J$34=$AD$5:$AD$34))&" / 30" | K36: =SUMPRODUCT(--($K$5:$K$34=$AE$5:$AE$34))&" / 30"
A37: 표 채점 — 노란 열마다 '맞은 칸 수 / 30' 으로 나옵니다. H5 에 수식을 만들고 H34 까지 끌어 내리면 30 / 30 이 됩니다.
A39: ■ 집계 문제 34개 — 번호 옆 ▶ 표시된 칸(F열)에 수식을 넣으세요
A40: 번호 ▶ 넣을 칸 | B40: 문제 — 무엇을 구하나 | F40: 답 | G40: 채점 | H40: 힌트 — 쓰는 함수
A41: 배열 수식 ① — 조건을 곱해서 한 번에 계산 (Ctrl+Shift+Enter 로 마칩니다)
A42: 1 ▶F42 | B42: '가공' 공정[C5:C34] 의 불량수[F5:F34] 합계를 배열 수식으로. | F42: 0 | G42: =IF(NOT(_xlfn.ISFORMULA(F42)),"↖ 0 지우고 수식",IF(IFERROR(ROUND(F42,4)=ROUND(AB42,4),F42=AB42),"✔ 맞음","✘ 다시")) | H42: SUM((조건)*범위) · 조건이 맞는 줄만 1 이 됩니다 | AB42: =SUMPRODUCT((C5:C34="가공")*F5:F34)
A43: 2 ▶F43 | B43: '가공' 이면서 불량수가 10 이상인 건수를 배열 수식으로. | F43: 0 | G43: =IF(NOT(_xlfn.ISFORMULA(F43)),"↖ 0 지우고 수식",IF(IFERROR(ROUND(F43,4)=ROUND(AB43,4),F43=AB43),"✔ 맞음","✘ 다시")) | H43: 조건 두 개를 곱하면 '그리고' | AB43: =SUMPRODUCT((C5:C34="가공")*(F5:F34>=10))
A44: 3 ▶F44 | B44: '조립' 또는 '검사' 인 건수를 배열 수식으로. | F44: 0 | G44: =IF(NOT(_xlfn.ISFORMULA(F44)),"↖ 0 지우고 수식",IF(IFERROR(ROUND(F44,4)=ROUND(AB44,4),F44=AB44),"✔ 맞음","✘ 다시")) | H44: 조건 두 개를 더하면 '또는' | AB44: =SUMPRODUCT((C5:C34="조립")+(C5:C34="검사"))
A45: 4 ▶F45 | B45: '조립' 공정의 검사수량[E5:E34] 평균을 배열 수식으로. | F45: 0 | G45: =IF(NOT(_xlfn.ISFORMULA(F45)),"↖ 0 지우고 수식",IF(IFERROR(ROUND(F45,4)=ROUND(AB45,4),F45=AB45),"✔ 맞음","✘ 다시")) | H45: AVERAGE(IF(조건, 범위)) | AB45: =AVERAGEIF(C5:C34,"조립",E5:E34)
A46: 5 ▶F46 | B46: 작업자 '김현수'[D5:D34] 의 최대 불량수를 배열 수식으로. | F46: 0 | G46: =IF(NOT(_xlfn.ISFORMULA(F46)),"↖ 0 지우고 수식",IF(IFERROR(ROUND(F46,4)=ROUND(AB46,4),F46=AB46),"✔ 맞음","✘ 다시")) | H46: MAX(IF(조건, 범위)) | AB46: =SUMPRODUCT(MAX((D5:D34="김현수")*F5:F34))
A47: 배열 수식 ② — SUMPRODUCT (Ctrl+Shift+Enter 없이도 됩니다)
A48: 6 ▶F48 | B48: '조립' 이면서 작업자가 '박지훈' 인 줄의 검사수량 합계. | F48: 0 | G48: =IF(NOT(_xlfn.ISFORMULA(F48)),"↖ 0 지우고 수식",IF(IFERROR(ROUND(F48,4)=ROUND(AB48,4),F48=AB48),"✔ 맞음","✘ 다시")) | H48: SUMPRODUCT((조건)*(조건)*범위) | AB48: =SUMPRODUCT((C5:C34="조립")*(D5:D34="박지훈")*E5:E34)
A49: 7 ▶F49 | B49: 검사수량이 400 이상이면서 불량수가 15 이상인 건수. | F49: 0 | G49: =IF(NOT(_xlfn.ISFORMULA(F49)),"↖ 0 지우고 수식",IF(IFERROR(ROUND(F49,4)=ROUND(AB49,4),F49=AB49),"✔ 맞음","✘ 다시")) | H49: SUMPRODUCT((조건)*(조건)) | AB49: =SUMPRODUCT((E5:E34>=400)*(F5:F34>=15))
A50: 8 ▶F50 | B50: 공정별 불량률을 따지려고, 전체 불량수 합계를 전체 검사수량 합계로 나눈 값. | F50: 0 | G50: =IF(NOT(_xlfn.ISFORMULA(F50)),"↖ 0 지우고 수식",IF(IFERROR(ROUND(F50,4)=ROUND(AB50,4),F50=AB50),"✔ 맞음","✘ 다시")) | H50: SUM 두 개를 나눕니다 | AB50: =SUM(F5:F34)/SUM(E5:E34)
A51: 다중 조건 — IFS · 중첩 IF · AND/OR
A52: 9 ▶F52 | B52: 불량률[F5/E5] 을 기준으로 등급을 매기시오. 1% 미만 "A", 3% 미만 "B", 5% 미만 "C", 그 밖 "D". | F52: 0 | G52: =IF(NOT(_xlfn.ISFORMULA(F52)),"↖ 0 지우고 수식",IF(IFERROR(ROUND(F52,4)=ROUND(AB52,4),F52=AB52),"✔ 맞음","✘ 다시")) | H52: IFS(조건1, 값1, 조건2, 값2, …, TRUE, 나머지) | AB52: =_xlfn.IFS(F5/E5<1%,"A",F5/E5<3%,"B",F5/E5<5%,"C",TRUE,"D")
A53: 10 ▶F53 | B53: 같은 것을 IF 를 겹쳐서 만드시오. (중첩 IF) | F53: 0 | G53: =IF(NOT(_xlfn.ISFORMULA(F53)),"↖ 0 지우고 수식",IF(IFERROR(ROUND(F53,4)=ROUND(AB53,4),F53=AB53),"✔ 맞음","✘ 다시")) | H53: IF(조건, 값, IF(조건, 값, IF(…))) | AB53: =IF(F5/E5<1%,"A",IF(F5/E5<3%,"B",IF(F5/E5<5%,"C","D")))
...

Sheet DB조건
A1: 데이터베이스 함수 · 조건 표 · 고급 필터 조건
A2: 조건 표의 머리글은 '품질검사' 시트 4행의 머리글과 글자가 완전히 같아야 합니다.
A4: 조건 표 ① A5:A6 — 가공 공정
A5: 공정
A6: 가공
A8: 조건 표 ② A9:A10 — 불량수 15 이상
A9: 불량수
A10: >=15
A12: 조건 표 ③ A13:B14 — 조립이면서 검사수량 330 이상
A13: 공정 | B13: 검사수량
A14: 조립 | B14: >=330
A16: 조건 표 ④ A17:A19 — 가공 또는 포장
A17: 공정
A18: 가공
A19: 포장
A21: 조건 표 ⑤ A22:A23 — 작업자가 김현수
A22: 작업자
A23: 김현수
A25: 조건 표 ⑥ (고급 필터용 수식 조건) A26:A27 — 검사수량이 전체 평균보다 많은 줄
A26: 조건 | C26: ※ 수식 조건은 머리글을 비워 두거나 원본에 없는 이름으로 씁니다
C27: A27 에 넣을 것 : =품질검사!E5>AVERAGE(품질검사!$E$5:$E$34)
A30: ■ 데이터베이스 함수 10문제 — ▶ 표시된 칸(F열)에
A31: 번호 ▶ 넣을 칸 | B31: 문제 — 무엇을 구하나 | F31: 답 | G31: 채점 | H31: 힌트 — 쓰는 함수
A32: 조건이 하나일 때
A33: 1 ▶F33 | B33: '가공' 공정의 불량수 합계. (조건 표 ① A5:A6) | F33: 0 | G33: =IF(NOT(_xlfn.ISFORMULA(F33)),"↖ 0 지우고 수식",IF(IFERROR(ROUND(F33,4)=ROUND(AB33,4),F33=AB33),"✔ 맞음","✘ 다시")) | H33: DSUM(전체 표, "필드", 조건 표) | AB33: =DSUM(품질검사!$A$4:$K$34,"불량수",A5:A6)
A34: 2 ▶F34 | B34: '가공' 공정의 평균 검사수량. (조건 표 ①) | F34: 0 | G34: =IF(NOT(_xlfn.ISFORMULA(F34)),"↖ 0 지우고 수식",IF(IFERROR(ROUND(F34,4)=ROUND(AB34,4),F34=AB34),"✔ 맞음","✘ 다시")) | H34: DAVERAGE | AB34: =DAVERAGE(품질검사!$A$4:$K$34,"검사수량",A5:A6)
A35: 3 ▶F35 | B35: '가공' 공정의 최대 측정값. (조건 표 ①) | F35: 0 | G35: =IF(NOT(_xlfn.ISFORMULA(F35)),"↖ 0 지우고 수식",IF(IFERROR(ROUND(F35,4)=ROUND(AB35,4),F35=AB35),"✔ 맞음","✘ 다시")) | H35: DMAX | AB35: =DMAX(품질검사!$A$4:$K$34,"측정값(mm)",A5:A6)
A36: 4 ▶F36 | B36: 불량수가 15 이상인 건수. (조건 표 ② A9:A10) | F36: 0 | G36: =IF(NOT(_xlfn.ISFORMULA(F36)),"↖ 0 지우고 수식",IF(IFERROR(ROUND(F36,4)=ROUND(AB36,4),F36=AB36),"✔ 맞음","✘ 다시")) | H36: DCOUNT | AB36: =DCOUNT(품질검사!$A$4:$K$34,"불량수",A9:A10)
A37: 5 ▶F37 | B37: 불량수가 15 이상인 줄 중 가장 적은 검사수량. (조건 표 ②) | F37: 0 | G37: =IF(NOT(_xlfn.ISFORMULA(F37)),"↖ 0 지우고 수식",IF(IFERROR(ROUND(F37,4)=ROUND(AB37,4),F37=AB37),"✔ 맞음","✘ 다시")) | H37: DMIN | AB37: =DMIN(품질검사!$A$4:$K$34,"검사수량",A9:A10)
A38: 조건이 둘 이상일 때
A39: 6 ▶F39 | B39: '조립' 이면서 검사수량 330 이상인 줄의 최대 불량수. (조건 표 ③ A13:B14) | F39: 0 | G39: =IF(NOT(_xlfn.ISFORMULA(F39)),"↖ 0 지우고 수식",IF(IFERROR(ROUND(F39,4)=ROUND(AB39,4),F39=AB39),"✔ 맞음","✘ 다시")) | H39: DMAX · 같은 줄 = 그리고 | AB39: =DMAX(품질검사!$A$4:$K$34,"불량수",A13:B14)
A40: 7 ▶F40 | B40: '조립' 이면서 검사수량 330 이상인 줄의 최소 측정값. (조건 표 ③) | F40: 0 | G40: =IF(NOT(_xlfn.ISFORMULA(F40)),"↖ 0 지우고 수식",IF(IFERROR(ROUND(F40,4)=ROUND(AB40,4),F40=AB40),"✔ 맞음","✘ 다시")) | H40: DMIN | AB40: =DMIN(품질검사!$A$4:$K$34,"측정값(mm)",A13:B14)
A41: 8 ▶F41 | B41: '가공' 또는 '포장' 인 줄의 검사수량 합계. (조건 표 ④ A17:A19) | F41: 0 | G41: =IF(NOT(_xlfn.ISFORMULA(F41)),"↖ 0 지우고 수식",IF(IFERROR(ROUND(F41,4)=ROUND(AB41,4),F41=AB41),"✔ 맞음","✘ 다시")) | H41: 줄을 달리 쓰면 '또는' | AB41: =DSUM(품질검사!$A$4:$K$34,"검사수량",A17:A19)
A42: 9 ▶F42 | B42: 작업자가 '김현수' 인 줄의 평균 불량수. (조건 표 ⑤ A22:A23) | F42: 0 | G42: =IF(NOT(_xlfn.ISFORMULA(F42)),"↖ 0 지우고 수식",IF(IFERROR(ROUND(F42,4)=ROUND(AB42,4),F42=AB42),"✔ 맞음","✘ 다시")) | H42: DAVERAGE | AB42: =DAVERAGE(품질검사!$A$4:$K$34,"불량수",A22:A23)
A43: 10 ▶F43 | B43: 작업자가 '김현수' 인 줄의 건수를 글자 필드로 세시오. (조건 표 ⑤) | F43: 0 | G43: =IF(NOT(_xlfn.ISFORMULA(F43)),"↖ 0 지우고 수식",IF(IFERROR(ROUND(F43,4)=ROUND(AB43,4),F43=AB43),"✔ 맞음","✘ 다시")) | H43: DCOUNTA | AB43: =DCOUNTA(품질검사!$A$4:$K$34,"로트번호",A22:A23)

Sheet 함수사전
A1: 1급 계산작업 함수 사전 — 형식 · 살아 있는 예시 · 자주 하는 실수
A2: [결과] 칸은 옆의 예시 수식을 진짜로 계산한 값입니다. 배열 예시는 SUMPRODUCT 로 바꿔 두어 그냥 계산됩니다.
A4: 함수 | B4: 하는 일 | C4: 쓰는 법 (형식) | D4: 이 파일 자료로 든 예시 | E4: 결과 | F4: 자주 하는 실수
A5: 배열 수식 — 1급의 고비
A6: SUM((조건)*범위) | B6: 조건에 맞는 줄만 더한다 | C6: {=SUM((조건)*범위)} | D6: =SUMPRODUCT((품질검사!C5:C34="가공")*품질검사!F5:F34) | E6: =SUMPRODUCT((품질검사!C5:C34="가공")*품질검사!F5:F34) | F6: Ctrl+Shift+Enter 로 마쳐야 한다 · 중괄호를 직접 치면 안 된다
A7: AVERAGE(IF()) | B7: 조건에 맞는 것만 평균 | C7: {=AVERAGE(IF(조건, 범위))} | D7: =AVERAGEIF(품질검사!C5:C34,"조립",품질검사!E5:E34) | E7: =AVERAGEIF(품질검사!C5:C34,"조립",품질검사!E5:E34) | F7: AVERAGEIF 로 바꿔 쓰면 배열이 아니어도 된다
A8: MAX(IF()) | B8: 조건에 맞는 것 중 최대 | C8: {=MAX(IF(조건, 범위))} | D8: =SUMPRODUCT(MAX((품질검사!D5:D34="김현수")*품질검사!F5:F34)) | E8: =SUMPRODUCT(MAX((품질검사!D5:D34="김현수")*품질검사!F5:F34))
A9: SUMPRODUCT | B9: 곱해서 더한다 (배열처럼) | C9: SUMPRODUCT((조건)*(조건)*범위) | D9: =SUMPRODUCT((품질검사!E5:E34>=400)*(품질검사!F5:F34>=15)) | E9: =SUMPRODUCT((품질검사!E5:E34>=400)*(품질검사!F5:F34>=15)) | F9: Ctrl+Shift+Enter 가 필요 없다
A10: 다중 조건
A11: IFS | B11: 여러 조건을 위에서부터 | C11: IFS(조건1, 값1, …, TRUE, 나머지) | D11: =IFS(품질검사!F5/품질검사!E5<1%,"A",TRUE,"B") | E11: =_xlfn.IFS(품질검사!F5/품질검사!E5<1%,"A",TRUE,"B") | F11: 마지막 TRUE 를 빼면 #N/A 가 난다
A12: COUNTIFS | B12: 조건 여러 개로 세기 | C12: COUNTIFS(범위1, 조건1, 범위2, 조건2) | D12: =COUNTIFS(품질검사!C5:C34,"가공",품질검사!F5:F34,">=10") | E12: =COUNTIFS(품질검사!C5:C34,"가공",품질검사!F5:F34,">=10")
A13: SUMIFS | B13: 조건 여러 개로 더하기 | C13: SUMIFS(더할범위, 범위1, 조건1, …) | D13: =SUMIFS(품질검사!F5:F34,품질검사!C5:C34,"가공") | E13: =SUMIFS(품질검사!F5:F34,품질검사!C5:C34,"가공") | F13: 더할 범위가 맨 앞 — SUMIF 와 순서가 다르다
A14: AVERAGEIFS | B14: 조건 여러 개로 평균 | C14: AVERAGEIFS(평균범위, 범위1, 조건1, …) | D14: =ROUND(AVERAGEIFS(품질검사!F5:F34,품질검사!C5:C34,"가공"),2) | E14: =ROUND(AVERAGEIFS(품질검사!F5:F34,품질검사!C5:C34,"가공"),2) | F14: 평균 낼 범위가 맨 앞
A15: 찾기 · 참조
A16: INDEX | B16: 몇 번째 자리의 값 | C16: INDEX(범위, 행, [열]) | D16: =INDEX(품질검사!A5:G34,3,4) | E16: =INDEX(품질검사!A5:G34,3,4)
A17: MATCH | B17: 몇 번째에 있는지 | C17: MATCH(찾을값, 범위, 0) | D17: =MATCH("L26-0312-A",품질검사!B5:B34,0) | E17: =MATCH("L26-0312-A",품질검사!B5:B34,0) | F17: 마지막 0 을 빼면 엉뚱한 자리
A18: VLOOKUP | B18: 세로 표에서 찾기 | C18: VLOOKUP(찾을값, 표, 열번호, FALSE/TRUE) | D18: =VLOOKUP(품질검사!F5/품질검사!E5,품질검사!$N$5:$O$8,2,TRUE) | E18: =VLOOKUP(품질검사!F5/품질검사!E5,품질검사!$N$5:$O$8,2,TRUE) | F18: TRUE(근사값)를 쓰려면 기준표 첫 열이 오름차순이어야 한다
A19: CHOOSE | B19: 번호로 고르기 | C19: CHOOSE(번호, 1번, 2번, …) | D19: =CHOOSE(MONTH(품질검사!A5),1,1,1,2,2,2,3,3,3,4,4,4) | E19: =CHOOSE(MONTH(품질검사!A5),1,1,1,2,2,2,3,3,3,4,4,4)
A20: 통계
A21: STDEV.S | B21: 표본 표준편차 | C21: STDEV.S(범위) | D21: =ROUND(STDEV.S(품질검사!G5:G34),4) | E21: =ROUND(_xlfn.STDEV.S(품질검사!G5:G34),4) | F21: 모집단 전체면 STDEV.P
A22: LARGE | B22: 몇 번째로 큰 값 | C22: LARGE(범위, 몇 번째) | D22: =LARGE(품질검사!E5:E34,3) | E22: =LARGE(품질검사!E5:E34,3)
A23: RANK.EQ | B23: 순위 | C23: RANK.EQ(값, 범위) | D23: =RANK.EQ(품질검사!F5,품질검사!$F$5:$F$34) | E23: =_xlfn.RANK.EQ(품질검사!F5,품질검사!$F$5:$F$34) | F23: 범위를 $ 로 고정
A24: MEDIAN | B24: 가운데 값 | C24: MEDIAN(범위) | D24: =MEDIAN(품질검사!E5:E34) | E24: =MEDIAN(품질검사!E5:E34)
A25: 문자열 · 날짜
A26: MID | B26: 가운데에서 뽑기 | C26: MID(글자, 시작, 개수) | D26: =MID(품질검사!B5,5,2) | E26: =MID(품질검사!B5,5,2) | F26: 시작 위치는 1부터
A27: FIND | B27: 몇 번째 글자인지 찾기 | C27: FIND("찾을글자", 글자) | D27: =FIND("-",품질검사!B5) | E27: =FIND("-",품질검사!B5) | F27: 없으면 #VALUE! — IFERROR 로 감싼다
A28: LEN | B28: 글자 수 | C28: LEN(글자) | D28: =LEN(품질검사!B5) | E28: =LEN(품질검사!B5)
A29: LOWER | B29: 소문자로 | C29: LOWER(글자) | D29: =LOWER(LEFT(품질검사!B5,3)) | E29: =LOWER(LEFT(품질검사!B5,3))
A30: DAYS | B30: 두 날짜 사이 일수 | C30: DAYS(늦은날, 이른날) | D30: =DAYS(품질검사!A34,품질검사!A5) | E30: =_xlfn.DAYS(품질검사!A34,품질검사!A5)
A31: WEEKDAY | B31: 요일 번호 | C31: WEEKDAY(날짜, 2) | D31: =WEEKDAY(품질검사!A5,2) | E31: =WEEKDAY(품질검사!A5,2) | F31: 2 를 빼면 일요일이 1
A32: 데이터베이스
A33: DSUM | B33: 조건 표로 더하기 | C33: DSUM(전체표, "필드", 조건표) | D33: =DSUM(품질검사!$A$4:$K$34,"불량수",DB조건!A5:A6) | E33: =DSUM(품질검사!$A$4:$K$34,"불량수",DB조건!A5:A6) | F33: 전체 표를 머리글부터 잡아야 한다
A34: DAVERAGE | B34: 조건 표로 평균 | C34: DAVERAGE(전체표, "필드", 조건표) | D34: =DAVERAGE(품질검사!$A$4:$K$34,"검사수량",DB조건!A5:A6) | E34: =DAVERAGE(품질검사!$A$4:$K$34,"검사수량",DB조건!A5:A6)
A35: DCOUNT | B35: 조건 표로 숫자 세기 | C35: DCOUNT(전체표, "필드", 조건표) | D35: =DCOUNT(품질검사!$A$4:$K$34,"불량수",DB조건!A9:A10) | E35: =DCOUNT(품질검사!$A$4:$K$34,"불량수",DB조건!A9:A10) | F35: 글자 필드는 DCOUNTA
A36: DMAX | B36: 조건 표로 최대 | C36: DMAX(전체표, "필드", 조건표) | D36: =DMAX(품질검사!$A$4:$K$34,"불량수",DB조건!A13:B14) | E36: =DMAX(품질검사!$A$4:$K$34,"불량수",DB조건!A13:B14)

Sheet 정답·해설
A1: 1급 ① 계산작업 정답 — 공정 품질검사
A2: 먼저 스스로 만들어 본 뒤에 펼쳐 보세요. [넣을 칸] 이 그 답을 적을 자리이고, [정답값] 은 제대로 넣었을 때 나와야 하는 값입니다.
A4: 표 안의 노란 열 (H5 에 만들어 H34 까지 끌어 채우기)
A5: 번호 | B5: 넣을 칸 | C5: 무엇을 구하나 | D5: 정답 수식 | E5: 정답값 | F5: 왜 그런가 · 자주 하는 실수
A6: 1 | B6: 품질검사 H5 | C6: 불량률 — 불량수÷검사수량 (서식 0.00%) | D6: =F5/E5 | E6: =품질검사!AB5 | F6: 수식에 *100 을 하지 않습니다
A7: 2 | B7: 품질검사 I5 | C7: 등급 — IFS 로 A·B·C·D | D7: =IFS(F5/E5<1%,"A",F5/E5<3%,"B",F5/E5<5%,"C",TRUE,"D") | E7: =품질검사!AC5 | F7: 마지막 TRUE 가 '나머지 전부'
A8: 3 | B8: 품질검사 J5 | C8: 규격판정 — 50.00±0.05 | D8: =IF(AND(G5>=49.95,G5<=50.05),"합격","불합격") | E8: =품질검사!AD5 | F8: AND 는 둘 다 참일 때만 참
A9: 4 | B9: 품질검사 K5 | C9: 로트월 — 로트번호 5번째부터 2글자 | D9: =MID(B5,5,2) | E9: =품질검사!AE5 | F9: L26-0302-A → 03
A11: 집계 문제 34개
A12: 번호 | B12: 넣을 칸 | C12: 무엇을 구하나 | D12: 정답 수식 | E12: 정답값 | F12: 왜 그런가 · 자주 하는 실수
A13: 1 | B13: 품질검사 F42 | C13: '가공' 공정[C5:C34] 의 불량수[F5:F34] 합계를 배열 수식으로. | D13: =SUM((C5:C34="가공")*F5:F34) | E13: ='품질검사'!AB42 | F13: 조건 (C5:C34="가공") 은 TRUE/FALSE 의 줄이 되고, 그것을 곱하면 TRUE=1, FALSE=0 이 됩니다
A14: 2 | B14: 품질검사 F43 | C14: '가공' 이면서 불량수가 10 이상인 건수를 배열 수식으로. | D14: =SUM((C5:C34="가공")*(F5:F34>=10)) | E14: ='품질검사'!AB43 | F14: 곱하기 = 그리고(AND), 더하기 = 또는(OR)
A15: 3 | B15: 품질검사 F44 | C15: '조립' 또는 '검사' 인 건수를 배열 수식으로. | D15: =SUM((C5:C34="조립")+(C5:C34="검사")) | E15: ='품질검사'!AB44 | F15: 둘 다 참인 줄이 있으면 2 가 되므로, 겹치지 않는 조건일 때만 씁니다
A16: 4 | B16: 품질검사 F45 | C16: '조립' 공정의 검사수량[E5:E34] 평균을 배열 수식으로. | D16: =AVERAGE(IF(C5:C34="조립",E5:E34)) | E16: ='품질검사'!AB45 | F16: IF 가 조건에 안 맞는 줄을 FALSE 로 만들고, AVERAGE 는 그것을 건너뜁니다
A17: 5 | B17: 품질검사 F46 | C17: 작업자 '김현수'[D5:D34] 의 최대 불량수를 배열 수식으로. | D17: =MAX(IF(D5:D34="김현수",F5:F34)) | E17: ='품질검사'!AB46 | F17: MIN(IF(...)) 로 최소도 같은 방법으로 구합니다
A18: 6 | B18: 품질검사 F48 | C18: '조립' 이면서 작업자가 '박지훈' 인 줄의 검사수량 합계. | D18: =SUMPRODUCT((C5:C34="조립")*(D5:D34="박지훈")*E5:E34) | E18: ='품질검사'!AB48 | F18: SUMPRODUCT 는 배열처럼 계산하면서도 그냥 Enter 로 끝납니다
A19: 7 | B19: 품질검사 F49 | C19: 검사수량이 400 이상이면서 불량수가 15 이상인 건수. | D19: =SUMPRODUCT((E5:E34>=400)*(F5:F34>=15)) | E19: ='품질검사'!AB49 | F19: COUNTIFS 로도 됩니다 — =COUNTIFS(E5:E34,">=400",F5:F34,">=15")
A20: 8 | B20: 품질검사 F50 | C20: 공정별 불량률을 따지려고, 전체 불량수 합계를 전체 검사수량 합계로 나눈 값. | D20: =SUM(F5:F34)/SUM(E5:E34) | E20: ='품질검사'!AB50 | F20: 줄마다의 불량률을 평균 내는 것과 다릅니다 — 전체를 한 덩어리로 봅니다
A21: 9 | B21: 품질검사 F52 | C21: 불량률[F5/E5] 을 기준으로 등급을 매기시오. 1% 미만 "A", 3% 미만 "B", 5% 미만 "C", 그 밖 "D". | D21: =IFS(F5/E5<1%,"A",F5/E5<3%,"B",F5/E5<5%,"C",TRUE,"D") | E21: ='품질검사'!AB52 | F21: IFS 는 위에서부터 처음 맞는 조건에서 멈춥니다. 마지막 TRUE 가 '나머지 전부'
A22: 10 | B22: 품질검사 F53 | C22: 같은 것을 IF 를 겹쳐서 만드시오. (중첩 IF) | D22: =IF(F5/E5<1%,"A",IF(F5/E5<3%,"B",IF(F5/E5<5%,"C","D"))) | E22: ='품질검사'!AB53 | F22: IFS 를 못 쓰는 낮은 버전에서도 되는 방법입니다
A23: 11 | B23: 품질검사 F54 | C23: 측정값[G5] 이 49.95 이상 50.05 이하이면 "합격", 아니면 "불합격". | D23: =IF(AND(G5>=49.95,G5<=50.05),"합격","불합격") | E23: ='품질검사'!AB54 | F23: 규격 50.00 ± 0.05 를 뜻합니다
A24: 12 | B24: 품질검사 F55 | C24: 공정[C5] 이 "가공" 이거나 불량수[F5] 가 20 이상이면 "중점관리", 아니면 빈칸. | D24: =IF(OR(C5="가공",F5>=20),"중점관리","") | E24: ='품질검사'!AB55
A25: 13 | B25: 품질검사 F57 | C25: 불량수가 가장 많았던 줄의 로트번호[B5:B34]. | D25: =INDEX(B5:B34,MATCH(MAX(F5:F34),F5:F34,0)) | E25: ='품질검사'!AB57 | F25: VLOOKUP 은 찾는 열보다 왼쪽을 못 가져옵니다. 그럴 때 INDEX+MATCH
A26: 14 | B26: 품질검사 F58 | C26: 검사수량이 가장 많았던 줄의 작업자[D5:D34]. | D26: =INDEX(D5:D34,MATCH(MAX(E5:E34),E5:E34,0)) | E26: ='품질검사'!AB58
A27: 15 | B27: 품질검사 F59 | C27: 로트번호 "L26-0312-A" 는 위에서 몇 번째 줄인가. | D27: =MATCH("L26-0312-A",B5:B34,0) | E27: ='품질검사'!AB59 | F27: 마지막 0 은 '정확히 일치'. 빼면 엉뚱한 자리를 찾습니다
A28: 16 | B28: 품질검사 F60 | C28: 불량률[F5/E5] 로 등급 기준표[N5:O8] 에서 등급을 찾아오시오. (근사값) | D28: =VLOOKUP(F5/E5,$N$5:$O$8,2,TRUE) | E28: ='품질검사'!AB60 | F28: 근사값을 쓰려면 기준표 첫 열이 반드시 오름차순이어야 합니다
A29: 17 | B29: 품질검사 F61 | C29: INDEX 로 표의 3번째 줄, 4번째 열(작업자)의 값을 꺼내시오. (범위 A5:G34) | D29: =INDEX(A5:G34,3,4) | E29: ='품질검사'!AB61 | F29: 행과 열을 둘 다 주면 표 안의 한 칸을 콕 집습니다
A30: 18 | B30: 품질검사 F63 | C30: 측정값[G5:G34] 의 표본 표준편차를 소수 넷째 자리까지. | D30: =ROUND(STDEV.S(G5:G34),4) | E30: ='품질검사'!AB63 | F30: STDEV.S 는 표본, STDEV.P 는 모집단 전체일 때
A31: 19 | B31: 품질검사 F64 | C31: 검사수량 상위 3건의 합계. | D31: =SUM(LARGE(E5:E34,{1,2,3})) | E31: ='품질검사'!AB64 | F31: {1,2,3} 은 '1등·2등·3등을 한꺼번에' 라는 뜻의 배열 상수입니다
A32: 20 | B32: 품질검사 F65 | C32: 첫 줄 불량수[F5] 는 전체에서 몇 등인가. (큰 값이 1등) | D32: =RANK.EQ(F5,$F$5:$F$34) | E32: ='품질검사'!AB65
A33: 21 | B33: 품질검사 F66 | C33: '가공' 이면서 불량수 10 이상인 건수를 COUNTIFS 로. | D33: =COUNTIFS(C5:C34,"가공",F5:F34,">=10") | E33: ='품질검사'!AB66 | F33: 배열 수식 2번과 같은 답이 나와야 합니다
A34: 22 | B34: 품질검사 F67 | C34: '가공' 이면서 검사수량 500 이상인 줄의 평균 불량수를 소수 둘째 자리까지. | D34: =ROUND(AVERAGEIFS(F5:F34,C5:C34,"가공",E5:E34,">=500"),2) | E34: ='품질검사'!AB67 | F34: AVERAGEIFS 는 '평균 낼 범위' 가 맨 앞에 옵니다 — AVERAGEIF 와 순서가 다릅니다
A35: 23 | B35: 품질검사 F68 | C35: 측정값[G5:G34] 중 규격(49.95~50.05)을 벗어난 건수. | D35: =COUNTIF(G5:G34,">50.05")+COUNTIF(G5:G34,"<49.95") | E35: ='품질검사'!AB68 | F35: 배열로는 =SUM((G5:G34>50.05)+(G5:G34<49.95))
A36: 24 | B36: 품질검사 F70 | C36: 로트번호[B5] 의 5번째부터 2글자. (검사한 달) | D36: =MID(B5,5,2) | E36: ='품질검사'!AB70 | F36: L26-0302-A → L(1) 2(2) 6(3) -(4) 0(5) 3(6) 이므로 5번째부터 2글자 = 03
A37: 25 | B37: 품질검사 F71 | C37: 로트번호[B5] 의 맨 끝 한 글자. (라인 A/B/C) | D37: =RIGHT(B5,1) | E37: ='품질검사'!AB71
A38: 26 | B38: 품질검사 F72 | C38: 로트번호[B5] 에서 붙임표(-) 가 처음 나오는 자리. | D38: =FIND("-",B5) | E38: ='품질검사'!AB72 | F38: FIND 는 대소문자를 가리고, SEARCH 는 안 가립니다
A39: 27 | B39: 품질검사 F73 | C39: 로트번호[B5] 의 글자 수. | D39: =LEN(B5) | E39: ='품질검사'!AB73
A40: 28 | B40: 품질검사 F74 | C40: 공정[C5] 과 작업자[D5] 를 가공-김현수 처럼 이어 붙이시오. | D40: =C5&"-"&D5 | E40: ='품질검사'!AB74
A41: 29 | B41: 품질검사 F75 | C41: 로트번호[B5] 앞 3글자를 소문자로. | D41: =LOWER(LEFT(B5,3)) | E41: ='품질검사'!AB75
A42: 30 | B42: 품질검사 F77 | C42: 검사일[A5] 이 몇 분기인가. (1~4) | D42: =ROUNDUP(MONTH(A5)/3,0) | E42: ='품질검사'!AB77 | F42: =CHOOSE(MONTH(A5),1,1,1,2,2,2,3,3,3,4,4,4) 로도 됩니다
...
