Workbook

Sheet 읽어보기
B2: 2급 실기 ② 기본작업 — 자재 입출고 대장
B4: 실기 1번 문제(기본작업)에서 나오는 것들을 이 한 장에서 연습합니다. 자료는 40건입니다.
B6: 시트 안내
B7: 자재입출고 — 40건. H열 금액이 비어 있고, 표 아래에 계산 문제 6개가 있습니다.
B8: 미션 — 해야 할 일 14가지 체크리스트 (□ 칸에 v 를 쳐 가며)
B9: 따라하기 — 미션 14가지를 1단계·2단계… 로 풀어 쓴 것 (이것이 정답입니다)
B10: 고급필터 — 조건 범위를 직접 만들어 결과를 뽑아내는 자리
B11: 목록 — 데이터 유효성 검사에서 쓸 목록
B13: 기본작업에서 늘 나오는 것
B14: ① 제목 만들기(병합하고 가운데 맞춤) ② 사용자 지정 표시 형식 ③ 조건부 서식
B15: ④ 고급 필터 ⑤ 데이터 유효성 검사 ⑥ 틀 고정 ⑦ 셀 서식·테두리 ⑧ 이름 정의
B16: 고급 필터의 조건 범위는 '머리글 글자가 원본과 똑같아야' 동작합니다. 여기서 가장 많이 틀립니다.

Sheet 자재입출고
A3: 입출고일 | B3: 전표번호 | C3: 자재코드 | D3: 자재명 | E3: 구분 | F3: 수량 | G3: 단가 | H3: 금액 | I3: 창고 | J3: 담당자
A4: 46083 | B4: IN-2601 | C4: BR-01 | D4: 베어링 6204 | E4: 입고 | F4: 25 | G4: 3200 | H4: 0 | I4: 1창고 | J4: 김현수 | AB4: =F4*G4
A5: 46083 | B5: OT-2601 | C5: SM-45 | D5: SM45C 환봉 | E5: 출고 | F5: 6 | G5: 18500 | I5: 2창고 | J5: 박지훈 | AB5: =F5*G5
A6: 46084 | B6: IN-2602 | C6: HS-12 | D6: 유압호스 1/2 | E6: 입고 | F6: 40 | G6: 7400 | I6: 3창고 | J6: 이서연 | AB6: =F6*G6
A7: 46084 | B7: OT-2602 | C7: LG-30 | D7: 리니어 가이드 | E7: 출고 | F7: 9 | G7: 96000 | I7: 1창고 | J7: 최민재 | AB7: =F7*G7
A8: 46085 | B8: IN-2603 | C8: VB-08 | D8: 밸브블록 | E8: 입고 | F8: 12 | G8: 33000 | I8: 2창고 | J8: 김현수 | AB8: =F8*G8
A9: 46085 | B9: OT-2603 | C9: GR-02 | D9: 감속기어 | E9: 출고 | F9: 120 | G9: 45000 | I9: 3창고 | J9: 박지훈 | AB9: =F9*G9
A10: 46086 | B10: IN-2604 | C10: SH-03 | D10: 구동축 | E10: 입고 | F10: 30 | G10: 78000 | I10: 1창고 | J10: 이서연 | AB10: =F10*G10
A11: 46086 | B11: OT-2604 | C11: BT-05 | D11: 타이밍벨트 | E11: 출고 | F11: 9 | G11: 8600 | I11: 2창고 | J11: 최민재 | AB11: =F11*G11
A12: 46088 | B12: IN-2605 | C12: BR-01 | D12: 베어링 6204 | E12: 입고 | F12: 120 | G12: 3200 | I12: 3창고 | J12: 김현수 | AB12: =F12*G12
A13: 46088 | B13: OT-2605 | C13: SM-45 | D13: SM45C 환봉 | E13: 출고 | F13: 6 | G13: 18500 | I13: 1창고 | J13: 박지훈 | AB13: =F13*G13
A14: 46089 | B14: IN-2606 | C14: HS-12 | D14: 유압호스 1/2 | E14: 입고 | F14: 12 | G14: 7400 | I14: 2창고 | J14: 이서연 | AB14: =F14*G14
A15: 46089 | B15: OT-2606 | C15: LG-30 | D15: 리니어 가이드 | E15: 출고 | F15: 95 | G15: 96000 | I15: 3창고 | J15: 최민재 | AB15: =F15*G15
A16: 46090 | B16: IN-2607 | C16: VB-08 | D16: 밸브블록 | E16: 입고 | F16: 6 | G16: 33000 | I16: 1창고 | J16: 김현수 | AB16: =F16*G16
... A43: 46106 | B43: OT-2620 | C43: BT-05 | D43: 타이밍벨트 | E43: 출고 | F43: 120 | G43: 8600 | I43: 1창고 | J43: 최민재 | AB43: =F43*G43
A45: 금액 채점 → | H45: =SUMPRODUCT(--($H$4:$H$43=$AB$4:$AB$43))&" / 40"
A46: H4 에 =F4*G4 를 만들고 H43 까지 끌어 내리면 40 / 40 이 됩니다.
A48: ■ 계산 문제 6개
A49: 번호 ▶ 넣을 칸 | B49: 문제 — 무엇을 구하나 | F49: 답 | G49: 채점 | H49: 힌트
A50: 표를 읽는 연습 — 아래 ▶ 표시된 칸(F열)에 수식을 넣으세요
A51: 1 ▶F51 | B51: 입고(E열이 "입고")인 자재의 수량[F4:F43] 합계. | F51: 0 | G51: =IF(NOT(_xlfn.ISFORMULA(F51)),"↖ 0 지우고 수식",IF(IFERROR(ROUND(F51,4)=ROUND(AB51,4),F51=AB51),"✔ 맞음","✘ 다시")) | H51: SUMIF(조건범위, "입고", 더할범위) | AB51: =SUMIF($E$4:$E$43,"입고",$F$4:$F$43)
A52: 2 ▶F52 | B52: 출고 건수. | F52: 0 | G52: =IF(NOT(_xlfn.ISFORMULA(F52)),"↖ 0 지우고 수식",IF(IFERROR(ROUND(F52,4)=ROUND(AB52,4),F52=AB52),"✔ 맞음","✘ 다시")) | H52: COUNTIF(범위, "출고") | AB52: =COUNTIF(E4:E43,"출고")
A53: 3 ▶F53 | B53: 1창고에서 오간 수량의 합계. | F53: 0 | G53: =IF(NOT(_xlfn.ISFORMULA(F53)),"↖ 0 지우고 수식",IF(IFERROR(ROUND(F53,4)=ROUND(AB53,4),F53=AB53),"✔ 맞음","✘ 다시")) | H53: SUMIF · 창고는 I열 | AB53: =SUMIF($I$4:$I$43,"1창고",$F$4:$F$43)
A54: 4 ▶F54 | B54: 단가[G4:G43] 가 가장 비싼 자재의 단가. | F54: 0 | G54: =IF(NOT(_xlfn.ISFORMULA(F54)),"↖ 0 지우고 수식",IF(IFERROR(ROUND(F54,4)=ROUND(AB54,4),F54=AB54),"✔ 맞음","✘ 다시")) | H54: MAX | AB54: =MAX(G4:G43)
A55: 5 ▶F55 | B55: 담당자가 "김현수" 인 건수. | F55: 0 | G55: =IF(NOT(_xlfn.ISFORMULA(F55)),"↖ 0 지우고 수식",IF(IFERROR(ROUND(F55,4)=ROUND(AB55,4),F55=AB55),"✔ 맞음","✘ 다시")) | H55: COUNTIF · 담당자는 J열 | AB55: =COUNTIF(J4:J43,"김현수")
A56: 6 ▶F56 | B56: 전표번호[B4] 의 앞 2글자. (IN / OT 로 입출고 구분) | F56: 0 | G56: =IF(NOT(_xlfn.ISFORMULA(F56)),"↖ 0 지우고 수식",IF(IFERROR(ROUND(F56,4)=ROUND(AB56,4),F56=AB56),"✔ 맞음","✘ 다시")) | H56: LEFT | AB56: =LEFT(B4,2)

Sheet 고급필터
A1: 고급 필터 연습 — 조건 범위를 여기에 만드세요
A2: 머리글은 '자재입출고' 시트 3행의 머리글과 글자·띄어쓰기까지 똑같아야 합니다. 노란 칸에 직접 써 넣으세요.
A4: 조건 ① 출고이면서 수량이 30 이상
F5: → 머리글 두 칸(구분·수량)을 5행에, 조건을 6행 같은 줄에 나란히 → 그리고(AND)
A8: 조건 ② 1창고 이거나 3창고
F9: → 머리글 한 칸(창고), 조건을 9행·10행 서로 다른 줄에 → 또는(OR)
A13: 조건 ③ 자재코드가 S 로 시작
F14: → 조건 칸에 S* 라고 씁니다. * 는 '뒤에 뭐가 오든', ? 는 글자 하나
A17: 조건 ④ 담당자가 이서연이면서 입고
F18: → 머리글은 담당자·구분. 두 조건을 같은 줄에
A22: 결과를 붙일 자리 (A25 부터)
A23: 데이터 → 고급 → '다른 장소에 복사' → 목록 범위 / 조건 범위 / 복사 위치 를 차례로 지정합니다.

Sheet 목록
A1: 데이터 유효성 검사용 목록
A3: 구분 | B3: 창고 | C3: 담당자
A4: 입고 | B4: 1창고 | C4: 김현수
A5: 출고 | B5: 2창고 | C5: 박지훈
B6: 3창고 | C6: 이서연
C7: 최민재
A9: 쓰는 법
A10: 데이터 → 데이터 유효성 검사 → 제한 대상 '목록' → 원본에 =목록!$A$4:$A$5

Sheet 미션
A1: 2급 ② 기본작업 미션 14가지
A2: 다 한 미션은 □ 칸에 v 를 쳐 두세요. 어떻게 하는지는 [따라하기] 시트에 단계별로 있습니다.
A4: 번호 | B4: 미션 — 무엇을 하는가 | C4: 다 함 | D4: 어디서 (메뉴)
A5: 1 | B5: [자재입출고 H4] 금액을 =F4*G4 로 만들고 H43 까지 채우기. 천 단위 쉼표. | C5: □ | D5: 홈 → 쉼표 스타일
A6: 2 | B6: [자재입출고 1~2행] 제목 '3월 자재 입출고 대장' 만들기. A1:J2 병합·가운데·16pt 굵게. | C6: □ | D6: 홈 → 병합하고 가운데 맞춤
A7: 3 | B7: [자재입출고 B열] 전표번호 뒤에 '호' 가 붙어 보이게. 값은 그대로. | C7: □ | D7: Ctrl+1 → 사용자 지정
A8: 4 | B8: [자재입출고 F열] 수량 뒤에 'EA' 가 붙어 보이게. | C8: □ | D8: Ctrl+1 → 사용자 지정
A9: 5 | B9: [자재입출고 A열] 날짜를 03-02(월) 처럼 요일까지 보이게. | C9: □ | D9: Ctrl+1 → 사용자 지정
A10: 6 | B10: [자재입출고] 수량이 100 이상인 행 전체를 연한 파랑으로. | C10: □ | D10: 조건부 서식 → 수식 사용
A11: 7 | B11: [자재입출고] '출고' 인 행의 글자를 빨강 굵게. | C11: □ | D11: 조건부 서식 → 수식 사용
A12: 8 | B12: [자재입출고 H열] 금액 상위 5개 칸에 색 채우기. | C12: □ | D12: 조건부 서식 → 상위/하위 규칙
A13: 9 | B13: [자재입출고 G열] 단가에 데이터 막대 넣기. | C13: □ | D13: 조건부 서식 → 데이터 막대
A14: 10 | B14: [고급필터] 조건 ①②③④ 를 만들기. | C14: □ | D14: 머리글을 원본과 똑같이
A15: 11 | B15: [고급필터] 조건 ① 의 결과를 A25 부터 뽑아내기. | C15: □ | D15: 데이터 → 고급 → 다른 장소에 복사
A16: 12 | B16: [자재입출고 E열] '입고/출고' 만 고를 수 있게 하기. | C16: □ | D16: 데이터 → 데이터 유효성 검사
... A18: 14 | B18: [자재입출고 F4:F43] 범위에 '수량' 이라는 이름 붙이고 아무 빈 칸에서 =SUM(수량) 써 보기. | C18: □ | D18: 수식 → 이름 정의

Sheet 따라하기
A1: 2급 ② 기본작업 — 단계별로 따라 하기
A2: 미션 14가지를 순서대로 풀어 쓴 것입니다. 한 미션씩 따라 하고 [미션] 시트의 □ 에 v 를 치세요.
A4: 미션 1 · 금액 채우고 쉼표 붙이기
A5: 어디서 | B5: [자재입출고] H4 → H43
A6: 1단계 | B6: H4 의 0 을 지우고 =F4*G4 를 입력하고 Enter. | C6: 수량 × 단가
A7: 2단계 | B7: H4 를 다시 클릭하고 오른쪽 아래 작은 네모를 두 번 클릭. | C7: 자료가 있는 데까지 한 번에 채워집니다
A8: 3단계 | B8: H4:H43 를 잡고 홈 탭의 쉼표 스타일(,) 을 누릅니다. | C8: 또는 Ctrl+1 → 숫자 → 1000 단위 구분 기호
A9: 4단계 | B9: 표 아래 [금액 채점] 칸이 40 / 40 인지 봅니다. | C9: 다르면 중간에 빠진 줄이 있는 것입니다
A10: 확인 | B10: 이렇게 되면 성공 — H열이 모두 채워지고 금액 채점이 40 / 40
A12: 미션 2 · 제목 만들기
A13: 어디서 | B13: [자재입출고] 1~2행
A14: 1단계 | B14: 3행 머리글 위에 빈 줄이 두 줄 있습니다. A1 을 클릭해 제목을 칩니다. | C14: 3월 자재 입출고 대장
A15: 2단계 | B15: A1:J2 를 드래그해 잡습니다. | C15: 열 A 부터 J 까지, 행 1~2
A16: 3단계 | B16: 홈 → [병합하고 가운데 맞춤] 을 누릅니다. | C16: 단추 그림은 'a' 가 가운데 모인 모양입니다
A17: 4단계 | B17: 글꼴 크기를 16, 굵게(Ctrl+B) 로 바꿉니다. | C17: 행 높이는 행 머리 경계를 끌어 늘립니다
A18: 확인 | B18: 이렇게 되면 성공 — 표 위에 가운데 정렬된 큰 제목이 한 칸처럼 자리잡습니다
A20: 미션 3 · 전표번호 뒤에 '호' 붙이기 (표시 형식)
A21: 어디서 | B21: [자재입출고] B4:B43
A22: 1단계 | B22: B4:B43 를 잡습니다. | C22: 머리글(B3)은 빼고 잡습니다
A23: 2단계 | B23: Ctrl+1 (셀 서식) → [표시 형식] 탭 → 맨 아래 [사용자 지정]. | C23: 오른쪽 '형식' 칸에 직접 씁니다
A24: 3단계 | B24: 형식 칸에 @"호" 라고 칩니다. | C24: @ 는 "원래 글자" 라는 뜻입니다
A25: 4단계 | B25: 확인을 누릅니다. | C25: IN-2601호 처럼 보이지만 값은 IN-2601 그대로입니다
A26: 확인 | B26: 이렇게 되면 성공 — 화면에는 '호' 가 붙어 보이고, 셀을 클릭하면 수식 줄에는 원래 값만 있습니다
A28: 미션 4 · 수량 뒤에 'EA', 날짜에 요일 붙이기
A29: 어디서 | B29: [자재입출고] F열 · A열
A30: 1단계 | B30: F4:F43 를 잡고 Ctrl+1 → 사용자 지정.
A31: 2단계 | B31: 형식 칸에 #,##0"EA" 라고 칩니다. | C31: 숫자 서식 뒤에 글자를 붙이는 방식
A32: 3단계 | B32: A4:A43 를 잡고 Ctrl+1 → 사용자 지정.
A33: 4단계 | B33: 형식 칸에 mm-dd(aaa) 라고 칩니다. | C33: aaa = 월·화·수 / aaaa = 월요일
A34: 확인 | B34: 이렇게 되면 성공 — 수량이 120EA, 날짜가 03-02(월) 처럼 보입니다
A36: 미션 5 · 수량 100 이상인 행 전체 칠하기
A37: 어디서 | B37: [자재입출고] 조건부 서식
A38: 1단계 | B38: A4:J43 를 잡습니다. (머리글은 빼고) | C38: 반드시 표 전체를 잡아야 행 전체가 칠해집니다
A39: 2단계 | B39: 홈 → 조건부 서식 → 새 규칙 → [수식을 사용하여…]. | C39: 맨 아래 항목입니다
A40: 3단계 | B40: 수식 칸에 =$F4>=100 을 씁니다. | C40: ★ 열만 $ 로 고정($F4). $F$4 로 하면 첫 줄만 봅니다
A41: 4단계 | B41: [서식] → 채우기 → 연한 파랑 → 확인 → 확인.
A42: 확인 | B42: 이렇게 되면 성공 — 수량이 100 이상인 줄만 통째로 파랗게 칠해집니다
A44: 미션 6 · '출고' 행 글자를 빨강 굵게
A45: 어디서 | B45: [자재입출고] 조건부 서식
A46: 1단계 | B46: A4:J43 를 잡습니다.
...

Sheet 계산 문제 정답
A1: 2급 ② 기본작업 — 계산 문제 정답
A2: 먼저 스스로 만들어 본 뒤에 펼쳐 보세요. [넣을 칸] 이 그 답을 적을 자리이고, [정답값] 은 제대로 넣었을 때 나와야 하는 값입니다.
A4: 표 아래 계산 문제 6개
A5: 번호 | B5: 넣을 칸 | C5: 무엇을 구하나 | D5: 정답 수식 | E5: 정답값 | F5: 왜 그런가 · 자주 하는 실수
A6: 1 | B6: 자재입출고 F51 | C6: 입고(E열이 "입고")인 자재의 수량[F4:F43] 합계. | D6: =SUMIF($E$4:$E$43,"입고",$F$4:$F$43) | E6: ='자재입출고'!AB51 | F6: 입고만 골라 더합니다
A7: 2 | B7: 자재입출고 F52 | C7: 출고 건수. | D7: =COUNTIF(E4:E43,"출고") | E7: ='자재입출고'!AB52
A8: 3 | B8: 자재입출고 F53 | C8: 1창고에서 오간 수량의 합계. | D8: =SUMIF($I$4:$I$43,"1창고",$F$4:$F$43) | E8: ='자재입출고'!AB53
A9: 4 | B9: 자재입출고 F54 | C9: 단가[G4:G43] 가 가장 비싼 자재의 단가. | D9: =MAX(G4:G43) | E9: ='자재입출고'!AB54
A10: 5 | B10: 자재입출고 F55 | C10: 담당자가 "김현수" 인 건수. | D10: =COUNTIF(J4:J43,"김현수") | E10: ='자재입출고'!AB55
A11: 6 | B11: 자재입출고 F56 | C11: 전표번호[B4] 의 앞 2글자. (IN / OT 로 입출고 구분) | D11: =LEFT(B4,2) | E11: ='자재입출고'!AB56 | F11: IN 은 입고, OT 는 출고를 뜻합니다
