Workbook

Sheet 읽어보기
B2: 2급 실기 ① 계산작업 — 생산일보로 함수 연습하기
B4: 라인별 하루 생산 실적 25일치입니다. 노란 칸을 함수로 채우면 됩니다.
B6: 이 파일을 푸는 법 — 세 가지만 기억하세요
B7: ① 노란 칸에는 0 이 들어 있습니다. 그 0 을 지우고 = 로 시작하는 수식을 넣습니다.
B8: ② 문제 왼쪽의 ▶F40 같은 표시가 '답을 넣을 칸' 입니다. 그 칸에 넣으세요.
B9: ③ 넣고 나면 오른쪽 [채점] 칸이 스스로 ✔ 맞음 / ✘ 다시 로 바뀝니다.
B11: 시트 안내
B12: 따라하기 — 수식을 처음 넣어 보는 사람이 먼저 볼 것 (4가지 기본 동작)
B13: 생산일보 — 표의 노란 열 5개(J~N) + 아래쪽 집계 39문제
B14: DB함수 — 조건 표를 만들어 쓰는 DSUM·DAVERAGE·DCOUNT·DMAX·DMIN 10문제
B15: 함수사전 — 이 파일에 나오는 함수 50여 개의 형식·예시·자주 하는 실수
B16: 정답·해설 — 어느 칸에 무엇을 넣어야 하는지 · 정답값 · 왜 그런지
... B25: 값이 0 으로만 보이면 Ctrl + Alt + F9 (전체 다시 계산). 채점 칸이 ↖ 0 지우고 수식 이라고 하면 아직 수식이 안 들어간 것입니다.

Sheet 따라하기
A1: 처음이라면 — 이 네 가지만 해 보고 시작하세요
A2: 엑셀이 처음이어도 괜찮습니다. 아래 네 가지를 따라 해 보면 나머지 문제도 같은 방식입니다.
A4: 미션 1 · 노란 칸에 수식 넣기
A5: 어디서 | B5: [생산일보] 시트 J5 칸
A6: 1단계 | B6: J5 칸을 한 번 클릭합니다. 그 칸에 0 이 들어 있습니다. | C6: 클릭한 칸의 주소는 화면 왼쪽 위 '이름 상자' 에 나옵니다
A7: 2단계 | B7: Delete 키를 눌러 0 을 지웁니다. | C7: 지우지 않고 바로 = 를 쳐도 덮어써집니다
A8: 3단계 | B8: = 를 치고 F5/E5*100 이라고 입력합니다. | C8: F5 는 키보드로 쳐도 되고, 마우스로 F5 칸을 눌러도 됩니다
A9: 4단계 | B9: Enter 를 누릅니다. | C9: 102.4 처럼 숫자가 나오면 성공입니다
A10: 확인 | B10: 이렇게 되면 성공 — J5 에 102.4 가 나오고, 다시 J5 를 클릭하면 위쪽 수식 줄에 =F5/E5*100 이 보입니다
A12: 미션 2 · 만든 수식을 아래로 끌어 채우기
A13: 어디서 | B13: [생산일보] 시트 J5 → J29
A14: 1단계 | B14: J5 칸을 클릭합니다. | C14: 칸 테두리가 굵게 표시됩니다
A15: 2단계 | B15: 칸 오른쪽 아래 모서리의 작은 네모(채우기 핸들) 위에 마우스를 올립니다. | C15: 마우스 모양이 굵은 십자(+)로 바뀝니다
A16: 3단계 | B16: 그 상태로 J29 까지 아래로 끌어 내립니다. | C16: 두 번 클릭하면 자료가 있는 데까지 한 번에 채워집니다
A17: 4단계 | B17: J6, J7 을 눌러 수식이 F6/E6, F7/E7 로 바뀌었는지 봅니다. | C17: 줄마다 자기 줄을 가리킵니다 — 이것이 상대참조입니다
A18: 확인 | B18: 이렇게 되면 성공 — J5 부터 J29 까지 값이 채워지고, 표 아래 [표 채점] 줄이 25 / 25 가 됩니다
A20: 미션 3 · $ 로 고정하기 (F4 키)
A21: 어디서 | B21: [생산일보] 시트 M5 칸 — 단가 찾아오기
A22: 1단계 | B22: M5 에 =VLOOKUP(C5, 까지 입력합니다. | C22: 쉼표까지 치고 잠깐 멈춥니다
A23: 2단계 | B23: 마우스로 오른쪽 단가표 P5:R8 을 드래그합니다. | C23: 수식에 P5:R8 이 들어갑니다
A24: 3단계 | B24: 바로 F4 키를 한 번 누릅니다. | C24: P5:R8 이 $P$5:$R$8 로 바뀝니다 — 끌어 내려도 표가 안 움직입니다
A25: 4단계 | B25: ,3,FALSE) 를 마저 치고 Enter. | C25: 3 = 표의 세 번째 열(단가), FALSE = 정확히 일치
A26: 확인 | B26: 이렇게 되면 성공 — M5 에 12,000 이 나오고, 아래로 끌어도 모든 줄이 제 단가를 찾아옵니다
A28: 미션 4 · 채점 칸 읽는 법
A29: 어디서 | B29: [생산일보] 시트 집계 문제의 [채점] 열
A30: 1단계 | B30: 아직 수식을 안 넣었으면 ↖ 0 지우고 수식 이라고 나옵니다. | C30: 0 은 답이 아니라 '여기에 넣으라' 는 표시입니다
A31: 2단계 | B31: 수식을 넣어 값이 맞으면 ✔ 맞음 (초록) | C31: 수식이 달라도 결과값이 같으면 맞음입니다
A32: 3단계 | B32: 값이 다르면 ✘ 다시 (빨강) | C32: 범위를 한 줄 덜 잡았는지 먼저 확인해 보세요
A33: 4단계 | B33: 그래도 모르겠으면 [정답·해설] 시트를 엽니다. | C33: 넣을 칸 · 정답 수식 · 정답값이 모두 적혀 있습니다
A34: 확인 | B34: 이렇게 되면 성공 — 문제를 풀수록 초록 칸이 늘어납니다

Sheet 생산일보
A1: 2026년 3~4월 · 라인별 생산일보
A2: 노란 칸의 0 을 지우고 수식을 넣으세요. J 달성률(%) = 생산수량÷계획수량×100 · K 판정 · L 불량률(%) = 불량수÷생산수량×100 · M 단가(오른쪽 P5:R8 에서 찾기) · N 생산금액 = 생산수량×단가
A4: 일자 | B4: 라인 | C4: 제품코드 | D4: 제품명 | E4: 계획수량 | F4: 생산수량 | G4: 불량수 | H4: 작업시간 | I4: 비고 | J4: 달성률(%) | K4: 판정 | L4: 불량률(%) | M4: 단가 | N4: 생산금액 | P4: 제품코드 | Q4: 제품명 | R4: 단가
A5: 46083 | B5: A | C5: BR-01 | D5: 베어링유닛 | E5: 500 | F5: 512 | G5: 7 | H5: 7.5 | I5: 야간 | J5: 0 | K5: 0 | L5: 0 | M5: 0 | N5: 0 | P5: BR-01 | Q5: 베어링유닛 | R5: 12000 | AB5: =ROUND(F5/E5*100,1) | AC5: =IF(F5>=E5,"달성","미달") | AD5: =ROUND(G5/F5*100,2) | AE5: =VLOOKUP(C5,$P$5:$R$8,3,FALSE) | AF5: =F5*AE5
A6: 46084 | B6: B | C6: GR-02 | D6: 감속기어 | E6: 300 | F6: 288 | G6: 12 | H6: 8 | P6: GR-02 | Q6: 감속기어 | R6: 45000 | AB6: =ROUND(F6/E6*100,1) | AC6: =IF(F6>=E6,"달성","미달") | AD6: =ROUND(G6/F6*100,2) | AE6: =VLOOKUP(C6,$P$5:$R$8,3,FALSE) | AF6: =F6*AE6
A7: 46085 | B7: A | C7: BR-01 | D7: 베어링유닛 | E7: 500 | F7: 476 | G7: 15 | H7: 7.8 | I7: 설비점검 | P7: SH-03 | Q7: 구동축 | R7: 78000 | AB7: =ROUND(F7/E7*100,1) | AC7: =IF(F7>=E7,"달성","미달") | AD7: =ROUND(G7/F7*100,2) | AE7: =VLOOKUP(C7,$P$5:$R$8,3,FALSE) | AF7: =F7*AE7
A8: 46086 | B8: C | C8: SH-03 | D8: 구동축 | E8: 200 | F8: 205 | G8: 3 | H8: 8 | P8: VL-04 | Q8: 밸브블록 | R8: 33000 | AB8: =ROUND(F8/E8*100,1) | AC8: =IF(F8>=E8,"달성","미달") | AD8: =ROUND(G8/F8*100,2) | AE8: =VLOOKUP(C8,$P$5:$R$8,3,FALSE) | AF8: =F8*AE8
A9: 46087 | B9: B | C9: VL-04 | D9: 밸브블록 | E9: 400 | F9: 415 | G9: 9 | H9: 7.2 | I9: 잔업 | P9: ↑ VLOOKUP 이 찾아볼 표 (P5:R8) | AB9: =ROUND(F9/E9*100,1) | AC9: =IF(F9>=E9,"달성","미달") | AD9: =ROUND(G9/F9*100,2) | AE9: =VLOOKUP(C9,$P$5:$R$8,3,FALSE) | AF9: =F9*AE9
A10: 46090 | B10: A | C10: GR-02 | D10: 감속기어 | E10: 300 | F10: 300 | G10: 5 | H10: 8 | AB10: =ROUND(F10/E10*100,1) | AC10: =IF(F10>=E10,"달성","미달") | AD10: =ROUND(G10/F10*100,2) | AE10: =VLOOKUP(C10,$P$5:$R$8,3,FALSE) | AF10: =F10*AE10
A11: 46091 | B11: C | C11: SH-03 | D11: 구동축 | E11: 200 | F11: 188 | G11: 11 | H11: 7.6 | I11: 자재지연 | AB11: =ROUND(F11/E11*100,1) | AC11: =IF(F11>=E11,"달성","미달") | AD11: =ROUND(G11/F11*100,2) | AE11: =VLOOKUP(C11,$P$5:$R$8,3,FALSE) | AF11: =F11*AE11
A12: 46092 | B12: B | C12: BR-01 | D12: 베어링유닛 | E12: 500 | F12: 534 | G12: 6 | H12: 8 | AB12: =ROUND(F12/E12*100,1) | AC12: =IF(F12>=E12,"달성","미달") | AD12: =ROUND(G12/F12*100,2) | AE12: =VLOOKUP(C12,$P$5:$R$8,3,FALSE) | AF12: =F12*AE12
A13: 46093 | B13: A | C13: VL-04 | D13: 밸브블록 | E13: 400 | F13: 372 | G13: 18 | H13: 7.4 | I13: 금형교체 | AB13: =ROUND(F13/E13*100,1) | AC13: =IF(F13>=E13,"달성","미달") | AD13: =ROUND(G13/F13*100,2) | AE13: =VLOOKUP(C13,$P$5:$R$8,3,FALSE) | AF13: =F13*AE13
A14: 46094 | B14: C | C14: GR-02 | D14: 감속기어 | E14: 300 | F14: 316 | G14: 4 | H14: 8 | AB14: =ROUND(F14/E14*100,1) | AC14: =IF(F14>=E14,"달성","미달") | AD14: =ROUND(G14/F14*100,2) | AE14: =VLOOKUP(C14,$P$5:$R$8,3,FALSE) | AF14: =F14*AE14
A15: 46097 | B15: B | C15: SH-03 | D15: 구동축 | E15: 200 | F15: 196 | G15: 8 | H15: 7.9 | AB15: =ROUND(F15/E15*100,1) | AC15: =IF(F15>=E15,"달성","미달") | AD15: =ROUND(G15/F15*100,2) | AE15: =VLOOKUP(C15,$P$5:$R$8,3,FALSE) | AF15: =F15*AE15
A16: 46098 | B16: A | C16: BR-01 | D16: 베어링유닛 | E16: 500 | F16: 498 | G16: 10 | H16: 8 | I16: 야간 | AB16: =ROUND(F16/E16*100,1) | AC16: =IF(F16>=E16,"달성","미달") | AD16: =ROUND(G16/F16*100,2) | AE16: =VLOOKUP(C16,$P$5:$R$8,3,FALSE) | AF16: =F16*AE16
A17: 46099 | B17: C | C17: VL-04 | D17: 밸브블록 | E17: 400 | F17: 424 | G17: 2 | H17: 7.7 | AB17: =ROUND(F17/E17*100,1) | AC17: =IF(F17>=E17,"달성","미달") | AD17: =ROUND(G17/F17*100,2) | AE17: =VLOOKUP(C17,$P$5:$R$8,3,FALSE) | AF17: =F17*AE17
A18: 46100 | B18: B | C18: GR-02 | D18: 감속기어 | E18: 300 | F18: 275 | G18: 14 | H18: 8 | I18: 설비점검 | AB18: =ROUND(F18/E18*100,1) | AC18: =IF(F18>=E18,"달성","미달") | AD18: =ROUND(G18/F18*100,2) | AE18: =VLOOKUP(C18,$P$5:$R$8,3,FALSE) | AF18: =F18*AE18
A19: 46101 | B19: A | C19: SH-03 | D19: 구동축 | E19: 200 | F19: 212 | G19: 5 | H19: 7.3 | AB19: =ROUND(F19/E19*100,1) | AC19: =IF(F19>=E19,"달성","미달") | AD19: =ROUND(G19/F19*100,2) | AE19: =VLOOKUP(C19,$P$5:$R$8,3,FALSE) | AF19: =F19*AE19
A20: 46104 | B20: C | C20: BR-01 | D20: 베어링유닛 | E20: 500 | F20: 545 | G20: 9 | H20: 8 | AB20: =ROUND(F20/E20*100,1) | AC20: =IF(F20>=E20,"달성","미달") | AD20: =ROUND(G20/F20*100,2) | AE20: =VLOOKUP(C20,$P$5:$R$8,3,FALSE) | AF20: =F20*AE20
A21: 46105 | B21: A | C21: VL-04 | D21: 밸브블록 | E21: 400 | F21: 388 | G21: 21 | H21: 7.6 | I21: 품질이상 | AB21: =ROUND(F21/E21*100,1) | AC21: =IF(F21>=E21,"달성","미달") | AD21: =ROUND(G21/F21*100,2) | AE21: =VLOOKUP(C21,$P$5:$R$8,3,FALSE) | AF21: =F21*AE21
A22: 46106 | B22: B | C22: SH-03 | D22: 구동축 | E22: 200 | F22: 199 | G22: 1 | H22: 7.8 | AB22: =ROUND(F22/E22*100,1) | AC22: =IF(F22>=E22,"달성","미달") | AD22: =ROUND(G22/F22*100,2) | AE22: =VLOOKUP(C22,$P$5:$R$8,3,FALSE) | AF22: =F22*AE22
A23: 46107 | B23: C | C23: GR-02 | D23: 감속기어 | E23: 300 | F23: 322 | G23: 6 | H23: 8 | I23: 잔업 | AB23: =ROUND(F23/E23*100,1) | AC23: =IF(F23>=E23,"달성","미달") | AD23: =ROUND(G23/F23*100,2) | AE23: =VLOOKUP(C23,$P$5:$R$8,3,FALSE) | AF23: =F23*AE23
A24: 46108 | B24: A | C24: BR-01 | D24: 베어링유닛 | E24: 500 | F24: 463 | G24: 17 | H24: 7.1 | I24: 자재지연 | AB24: =ROUND(F24/E24*100,1) | AC24: =IF(F24>=E24,"달성","미달") | AD24: =ROUND(G24/F24*100,2) | AE24: =VLOOKUP(C24,$P$5:$R$8,3,FALSE) | AF24: =F24*AE24
A25: 46111 | B25: B | C25: VL-04 | D25: 밸브블록 | E25: 400 | F25: 431 | G25: 8 | H25: 8 | AB25: =ROUND(F25/E25*100,1) | AC25: =IF(F25>=E25,"달성","미달") | AD25: =ROUND(G25/F25*100,2) | AE25: =VLOOKUP(C25,$P$5:$R$8,3,FALSE) | AF25: =F25*AE25
A26: 46112 | B26: C | C26: SH-03 | D26: 구동축 | E26: 200 | F26: 184 | G26: 13 | H26: 7.5 | I26: 설비점검 | AB26: =ROUND(F26/E26*100,1) | AC26: =IF(F26>=E26,"달성","미달") | AD26: =ROUND(G26/F26*100,2) | AE26: =VLOOKUP(C26,$P$5:$R$8,3,FALSE) | AF26: =F26*AE26
A27: 46113 | B27: A | C27: GR-02 | D27: 감속기어 | E27: 300 | F27: 308 | G27: 4 | H27: 8 | AB27: =ROUND(F27/E27*100,1) | AC27: =IF(F27>=E27,"달성","미달") | AD27: =ROUND(G27/F27*100,2) | AE27: =VLOOKUP(C27,$P$5:$R$8,3,FALSE) | AF27: =F27*AE27
A28: 46114 | B28: B | C28: BR-01 | D28: 베어링유닛 | E28: 500 | F28: 521 | G28: 11 | H28: 8 | AB28: =ROUND(F28/E28*100,1) | AC28: =IF(F28>=E28,"달성","미달") | AD28: =ROUND(G28/F28*100,2) | AE28: =VLOOKUP(C28,$P$5:$R$8,3,FALSE) | AF28: =F28*AE28
A29: 46115 | B29: C | C29: VL-04 | D29: 밸브블록 | E29: 400 | F29: 396 | G29: 7 | H29: 7.9 | I29: 야간 | AB29: =ROUND(F29/E29*100,1) | AC29: =IF(F29>=E29,"달성","미달") | AD29: =ROUND(G29/F29*100,2) | AE29: =VLOOKUP(C29,$P$5:$R$8,3,FALSE) | AF29: =F29*AE29
A31: 표 채점 → | J31: =SUMPRODUCT(--(ROUND($J$5:$J$29,1)=ROUND($AB$5:$AB$29,1)))&" / 25" | K31: =SUMPRODUCT(--($K$5:$K$29=$AC$5:$AC$29))&" / 25" | L31: =SUMPRODUCT(--(ROUND($L$5:$L$29,2)=ROUND($AD$5:$AD$29,2)))&" / 25" | M31: =SUMPRODUCT(--($M$5:$M$29=$AE$5:$AE$29))&" / 25" | N31: =SUMPRODUCT(--($N$5:$N$29=$AF$5:$AF$29))&" / 25"
A32: 표 채점 — 노란 열마다 '맞은 칸 수 / 25' 로 나옵니다. J5 에 수식을 만들고 J29 까지 끌어 내리면 25 / 25 가 됩니다.
A34: ■ 집계 문제 39개 — 번호 옆 ▶ 표시된 칸(F열)에 수식을 넣으세요
A35: 번호 ▶ 넣을 칸 | B35: 문제 — 무엇을 구하나 | F35: 답 | G35: 채점 | H35: 힌트 — 쓰는 함수
A36: 논리 — IF · AND · OR · IFERROR
A37: 1 ▶F37 | B37: 생산수량[F5]이 계획수량[E5] 이상이면 "달성", 아니면 "미달" 이라고 나오게 하시오. | F37: 0 | G37: =IF(NOT(_xlfn.ISFORMULA(F37)),"↖ 0 지우고 수식",IF(IFERROR(ROUND(F37,4)=ROUND(AB37,4),F37=AB37),"✔ 맞음","✘ 다시")) | H37: IF(조건, 참일 때, 거짓일 때) · 글자는 "큰따옴표" | AB37: =IF(F5>=E5,"달성","미달")
A38: 2 ▶F38 | B38: 생산수량[F5]이 500 이상이면서 불량수[G5]가 10 미만이면 "우수", 아니면 "보통". | F38: 0 | G38: =IF(NOT(_xlfn.ISFORMULA(F38)),"↖ 0 지우고 수식",IF(IFERROR(ROUND(F38,4)=ROUND(AB38,4),F38=AB38),"✔ 맞음","✘ 다시")) | H38: 조건이 두 개 다 맞아야 → AND(조건1, 조건2) | AB38: =IF(AND(F5>=500,G5<10),"우수","보통")
A39: 3 ▶F39 | B39: 라인[B5]이 "A" 이거나 작업시간[H5]이 8 이상이면 "확인", 아니면 빈칸. | F39: 0 | G39: =IF(NOT(_xlfn.ISFORMULA(F39)),"↖ 0 지우고 수식",IF(IFERROR(ROUND(F39,4)=ROUND(AB39,4),F39=AB39),"✔ 맞음","✘ 다시")) | H39: 둘 중 하나만 맞아도 → OR(조건1, 조건2) · 빈칸은 "" | AB39: =IF(OR(B5="A",H5>=8),"확인","")
A40: 4 ▶F40 | B40: 불량수[G5]를 생산수량[F5]으로 나누되, 오류가 나면 "-" 가 나오게 하시오. | F40: 0 | G40: =IF(NOT(_xlfn.ISFORMULA(F40)),"↖ 0 지우고 수식",IF(IFERROR(ROUND(F40,4)=ROUND(AB40,4),F40=AB40),"✔ 맞음","✘ 다시")) | H40: IFERROR(수식, 오류일 때 보여 줄 것) | AB40: =IFERROR(G5/F5,"-")
A41: 통계 — SUM · AVERAGE · MAX · MIN · LARGE · SMALL · MEDIAN · RANK.EQ
A42: 5 ▶F42 | B42: 3월~4월 전체 생산수량[F5:F29] 의 합계. | F42: 0 | G42: =IF(NOT(_xlfn.ISFORMULA(F42)),"↖ 0 지우고 수식",IF(IFERROR(ROUND(F42,4)=ROUND(AB42,4),F42=AB42),"✔ 맞음","✘ 다시")) | H42: SUM(범위) | AB42: =SUM(F5:F29)
A43: 6 ▶F43 | B43: 전체 생산수량[F5:F29] 의 평균을 정수로 반올림해서. | F43: 0 | G43: =IF(NOT(_xlfn.ISFORMULA(F43)),"↖ 0 지우고 수식",IF(IFERROR(ROUND(F43,4)=ROUND(AB43,4),F43=AB43),"✔ 맞음","✘ 다시")) | H43: ROUND 안에 AVERAGE 를 넣습니다 · 자릿수 0 | AB43: =ROUND(AVERAGE(F5:F29),0)
...

Sheet DB함수
A1: 데이터베이스 함수 — 조건 표를 따로 만들어 쓰는 함수
A2: D 로 시작하는 함수는 (전체 표, "필드 이름", 조건 표) 세 가지를 받습니다. 조건 표의 머리글은 '생산일보' 시트 4행의 머리글과 글자가 똑같아야 합니다.
A4: 조건 표 ① A5:A6 — A라인만
A5: 라인
A6: A
A8: 조건 표 ② A9:A10 — 불량수 10 이상
A9: 불량수
A10: >=10
A12: 조건 표 ③ A13:B14 — B라인이면서 생산수량 300 이상
A13: 라인 | B13: 생산수량
A14: B | B14: >=300
A16: 조건 표 ④ A17:A19 — A라인 또는 C라인
A17: 라인
A18: A
A19: C
A21: 조건 표 ⑤ A22:A23 — 제품명이 감속기어
A22: 제품명
A23: 감속기어
A25: ■ 데이터베이스 함수 10문제 — ▶ 표시된 칸(F열)에
A26: 번호 ▶ 넣을 칸 | B26: 문제 — 무엇을 구하나 | F26: 답 | G26: 채점 | H26: 힌트 — 쓰는 함수
A27: 조건이 하나일 때
A28: 1 ▶F28 | B28: A라인의 생산수량 합계. (조건 표 ① A5:A6 을 쓰시오) | F28: 0 | G28: =IF(NOT(_xlfn.ISFORMULA(F28)),"↖ 0 지우고 수식",IF(IFERROR(ROUND(F28,4)=ROUND(AB28,4),F28=AB28),"✔ 맞음","✘ 다시")) | H28: DSUM(전체 표, "필드 이름", 조건 표) | AB28: =DSUM(생산일보!$A$4:$N$29,"생산수량",A5:A6)
A29: 2 ▶F29 | B29: A라인의 평균 불량수. (조건 표 ①) | F29: 0 | G29: =IF(NOT(_xlfn.ISFORMULA(F29)),"↖ 0 지우고 수식",IF(IFERROR(ROUND(F29,4)=ROUND(AB29,4),F29=AB29),"✔ 맞음","✘ 다시")) | H29: DAVERAGE | AB29: =DAVERAGE(생산일보!$A$4:$N$29,"불량수",A5:A6)
A30: 3 ▶F30 | B30: A라인의 최대 생산수량. (조건 표 ①) | F30: 0 | G30: =IF(NOT(_xlfn.ISFORMULA(F30)),"↖ 0 지우고 수식",IF(IFERROR(ROUND(F30,4)=ROUND(AB30,4),F30=AB30),"✔ 맞음","✘ 다시")) | H30: DMAX | AB30: =DMAX(생산일보!$A$4:$N$29,"생산수량",A5:A6)
A31: 4 ▶F31 | B31: 불량수가 10 이상인 날의 건수. (조건 표 ② A9:A10) | F31: 0 | G31: =IF(NOT(_xlfn.ISFORMULA(F31)),"↖ 0 지우고 수식",IF(IFERROR(ROUND(F31,4)=ROUND(AB31,4),F31=AB31),"✔ 맞음","✘ 다시")) | H31: DCOUNT — 숫자가 든 필드를 세야 합니다 | AB31: =DCOUNT(생산일보!$A$4:$N$29,"불량수",A9:A10)
A32: 5 ▶F32 | B32: 불량수가 10 이상인 날 중 가장 적은 생산수량. (조건 표 ②) | F32: 0 | G32: =IF(NOT(_xlfn.ISFORMULA(F32)),"↖ 0 지우고 수식",IF(IFERROR(ROUND(F32,4)=ROUND(AB32,4),F32=AB32),"✔ 맞음","✘ 다시")) | H32: DMIN | AB32: =DMIN(생산일보!$A$4:$N$29,"생산수량",A9:A10)
A33: 조건이 둘일 때 — 같은 줄이면 '그리고', 다른 줄이면 '또는'
A34: 6 ▶F34 | B34: B라인이면서 생산수량 300 이상인 날의 최소 작업시간. (조건 표 ③ A13:B14) | F34: 0 | G34: =IF(NOT(_xlfn.ISFORMULA(F34)),"↖ 0 지우고 수식",IF(IFERROR(ROUND(F34,4)=ROUND(AB34,4),F34=AB34),"✔ 맞음","✘ 다시")) | H34: DMIN · 조건 두 개가 같은 줄 = 그리고 | AB34: =DMIN(생산일보!$A$4:$N$29,"작업시간",A13:B14)
A35: 7 ▶F35 | B35: B라인이면서 생산수량 300 이상인 날의 생산수량 합계. (조건 표 ③) | F35: 0 | G35: =IF(NOT(_xlfn.ISFORMULA(F35)),"↖ 0 지우고 수식",IF(IFERROR(ROUND(F35,4)=ROUND(AB35,4),F35=AB35),"✔ 맞음","✘ 다시")) | H35: DSUM | AB35: =DSUM(생산일보!$A$4:$N$29,"생산수량",A13:B14)
A36: 8 ▶F36 | B36: A라인 또는 C라인인 날의 생산수량 합계. (조건 표 ④ A17:A19) | F36: 0 | G36: =IF(NOT(_xlfn.ISFORMULA(F36)),"↖ 0 지우고 수식",IF(IFERROR(ROUND(F36,4)=ROUND(AB36,4),F36=AB36),"✔ 맞음","✘ 다시")) | H36: 조건을 줄을 달리해 쓰면 '또는' | AB36: =DSUM(생산일보!$A$4:$N$29,"생산수량",A17:A19)
A37: 9 ▶F37 | B37: 제품명이 "감속기어" 인 날의 평균 생산수량. (조건 표 ⑤ A22:A23) | F37: 0 | G37: =IF(NOT(_xlfn.ISFORMULA(F37)),"↖ 0 지우고 수식",IF(IFERROR(ROUND(F37,4)=ROUND(AB37,4),F37=AB37),"✔ 맞음","✘ 다시")) | H37: DAVERAGE | AB37: =DAVERAGE(생산일보!$A$4:$N$29,"생산수량",A22:A23)
A38: 10 ▶F38 | B38: 제품명이 "감속기어" 인 날의 기록 건수. (글자 필드를 세시오) | F38: 0 | G38: =IF(NOT(_xlfn.ISFORMULA(F38)),"↖ 0 지우고 수식",IF(IFERROR(ROUND(F38,4)=ROUND(AB38,4),F38=AB38),"✔ 맞음","✘ 다시")) | H38: DCOUNTA — 글자도 셉니다 | AB38: =DCOUNTA(생산일보!$A$4:$N$29,"제품명",A22:A23)
A40: 전체 표 범위는 머리글 줄부터 잡습니다 → 생산일보!$A$4:$N$29. 조건 표는 머리글 한 줄 + 조건 줄로 이루어집니다.

Sheet 함수사전
A1: 이 파일에 나오는 함수 사전 — 형식 · 살아 있는 예시 · 자주 하는 실수
A2: [결과] 칸은 옆의 예시 수식을 진짜로 계산한 값입니다. 클릭해서 안을 들여다보세요.
A4: 함수 | B4: 하는 일 | C4: 쓰는 법 (형식) | D4: 이 파일 자료로 든 예시 | E4: 결과 | F4: 자주 하는 실수
A5: 논리
A6: IF | B6: 조건에 따라 둘 중 하나를 보여 준다 | C6: IF(조건, 참일 때, 거짓일 때) | D6: =IF(생산일보!F5>=500,"많음","적음") | E6: =IF(생산일보!F5>=500,"많음","적음") | F6: 글자에 큰따옴표를 안 붙여 #NAME? 가 난다
A7: AND | B7: 모두 참일 때만 참 | C7: AND(조건1, 조건2, …) | D7: =AND(생산일보!F5>=500,생산일보!G5<10) | E7: =AND(생산일보!F5>=500,생산일보!G5<10) | F7: IF 없이 혼자 쓰면 TRUE/FALSE 만 나온다
A8: OR | B8: 하나라도 참이면 참 | C8: OR(조건1, 조건2, …) | D8: =OR(생산일보!B5="A",생산일보!H5>=8) | E8: =OR(생산일보!B5="A",생산일보!H5>=8)
A9: NOT | B9: 참·거짓을 뒤집는다 | C9: NOT(조건) | D9: =NOT(생산일보!F5>=500) | E9: =NOT(생산일보!F5>=500)
A10: IFERROR | B10: 오류가 나면 대신 보여 줄 것 | C10: IFERROR(수식, 오류일 때) | D10: =IFERROR(생산일보!G5/0,"계산불가") | E10: =IFERROR(생산일보!G5/0,"계산불가") | F10: 오류가 아닌 값까지 바꾸지는 않는다
A11: 통계
A12: SUM | B12: 다 더한다 | C12: SUM(범위) | D12: =SUM(생산일보!F5:F29) | E12: =SUM(생산일보!F5:F29) | F12: 범위에 글자가 섞이면 그것은 빼고 더한다
A13: AVERAGE | B13: 평균 | C13: AVERAGE(범위) | D13: =ROUND(AVERAGE(생산일보!F5:F29),0) | E13: =ROUND(AVERAGE(생산일보!F5:F29),0) | F13: 빈 칸은 빼고 계산한다(0 으로 치지 않는다)
A14: MAX | B14: 가장 큰 값 | C14: MAX(범위) | D14: =MAX(생산일보!F5:F29) | E14: =MAX(생산일보!F5:F29)
A15: MIN | B15: 가장 작은 값 | C15: MIN(범위) | D15: =MIN(생산일보!G5:G29) | E15: =MIN(생산일보!G5:G29)
A16: LARGE | B16: 몇 번째로 큰 값 | C16: LARGE(범위, 몇 번째) | D16: =LARGE(생산일보!F5:F29,3) | E16: =LARGE(생산일보!F5:F29,3) | F16: 두 번째 인수를 빠뜨리면 오류
A17: SMALL | B17: 몇 번째로 작은 값 | C17: SMALL(범위, 몇 번째) | D17: =SMALL(생산일보!G5:G29,2) | E17: =SMALL(생산일보!G5:G29,2)
A18: MEDIAN | B18: 가운데 값 | C18: MEDIAN(범위) | D18: =MEDIAN(생산일보!F5:F29) | E18: =MEDIAN(생산일보!F5:F29)
A19: RANK.EQ | B19: 순위 | C19: RANK.EQ(값, 범위, [0=큰값이1등]) | D19: =RANK.EQ(생산일보!F5,생산일보!$F$5:$F$29) | E19: =_xlfn.RANK.EQ(생산일보!F5,생산일보!$F$5:$F$29) | F19: 범위를 $ 로 고정하지 않고 끌어 채우면 순위가 뒤죽박죽
A20: STDEV.S | B20: 표본 표준편차 | C20: STDEV.S(범위) | D20: =ROUND(STDEV.S(생산일보!F5:F29),1) | E20: =ROUND(_xlfn.STDEV.S(생산일보!F5:F29),1)
A21: 개수 세기
A22: COUNT | B22: 숫자가 든 칸 수 | C22: COUNT(범위) | D22: =COUNT(생산일보!H5:H29) | E22: =COUNT(생산일보!H5:H29) | F22: 글자는 세지 않는다
A23: COUNTA | B23: 비어 있지 않은 칸 수 | C23: COUNTA(범위) | D23: =COUNTA(생산일보!B5:B29) | E23: =COUNTA(생산일보!B5:B29)
A24: COUNTBLANK | B24: 비어 있는 칸 수 | C24: COUNTBLANK(범위) | D24: =COUNTBLANK(생산일보!I5:I29) | E24: =COUNTBLANK(생산일보!I5:I29)
A25: COUNTIF | B25: 조건에 맞는 칸 수 | C25: COUNTIF(범위, 조건) | D25: =COUNTIF(생산일보!G5:G29,">=10") | E25: =COUNTIF(생산일보!G5:G29,">=10") | F25: >=10 을 큰따옴표 없이 쓰면 오류
A26: 조건부 집계
A27: SUMIF | B27: 조건에 맞는 것만 더한다 | C27: SUMIF(조건범위, 조건, 더할범위) | D27: =SUMIF(생산일보!$B$5:$B$29,"A",생산일보!$F$5:$F$29) | E27: =SUMIF(생산일보!$B$5:$B$29,"A",생산일보!$F$5:$F$29) | F27: 두 범위의 크기가 다르면 엉뚱한 값
A28: AVERAGEIF | B28: 조건에 맞는 것만 평균 | C28: AVERAGEIF(조건범위, 조건, 평균범위) | D28: =ROUND(AVERAGEIF(생산일보!$B$5:$B$29,"A",생산일보!$G$5:$G$29),2) | E28: =ROUND(AVERAGEIF(생산일보!$B$5:$B$29,"A",생산일보!$G$5:$G$29),2)
A29: 수학 · 반올림
A30: ROUND | B30: 반올림 | C30: ROUND(값, 자릿수) | D30: =ROUND(생산일보!H5,0) | E30: =ROUND(생산일보!H5,0) | F30: 자릿수 0=정수, 1=소수첫째, -1=십의자리
A31: ROUNDUP | B31: 무조건 올림 | C31: ROUNDUP(값, 자릿수) | D31: =ROUNDUP(AVERAGE(생산일보!F5:F29),-1) | E31: =ROUNDUP(AVERAGE(생산일보!F5:F29),-1)
A32: ROUNDDOWN | B32: 무조건 버림 | C32: ROUNDDOWN(값, 자릿수) | D32: =ROUNDDOWN(SUM(생산일보!H5:H29),0) | E32: =ROUNDDOWN(SUM(생산일보!H5:H29),0)
A33: TRUNC | B33: 소수점을 자른다 | C33: TRUNC(값, [자릿수]) | D33: =TRUNC(생산일보!H5) | E33: =TRUNC(생산일보!H5) | F33: 음수에서 INT 와 결과가 다르다
A34: INT | B34: 소수점을 버려 정수로 | C34: INT(값) | D34: =INT(SUM(생산일보!F5:F29)/500) | E34: =INT(SUM(생산일보!F5:F29)/500) | F34: 음수는 더 작은 쪽으로 간다
A35: MOD | B35: 나머지 | C35: MOD(값, 나누는 수) | D35: =MOD(SUM(생산일보!F5:F29),500) | E35: =MOD(SUM(생산일보!F5:F29),500)
A36: ABS | B36: 절댓값 | C36: ABS(값) | D36: =ABS(생산일보!F5-생산일보!E5) | E36: =ABS(생산일보!F5-생산일보!E5)
A37: POWER | B37: 거듭제곱 | C37: POWER(값, 지수) | D37: =POWER(2,10) | E37: =POWER(2,10) | F37: = 2^10 과 같다
A38: 문자열
A39: LEFT | B39: 왼쪽에서 몇 글자 | C39: LEFT(글자, 개수) | D39: =LEFT(생산일보!C5,2) | E39: =LEFT(생산일보!C5,2)
A40: RIGHT | B40: 오른쪽에서 몇 글자 | C40: RIGHT(글자, 개수) | D40: =RIGHT(생산일보!C5,2) | E40: =RIGHT(생산일보!C5,2)
A41: MID | B41: 가운데에서 뽑기 | C41: MID(글자, 시작, 개수) | D41: =MID(생산일보!C5,4,2) | E41: =MID(생산일보!C5,4,2) | F41: 시작 위치는 1부터 센다
...

Sheet 정답·해설
A1: 2급 ① 계산작업 정답 — 생산일보
A2: 먼저 스스로 만들어 본 뒤에 펼쳐 보세요. [넣을 칸] 이 그 답을 적을 자리이고, [정답값] 은 제대로 넣었을 때 나와야 하는 값입니다.
A4: 표 안의 노란 열 (J5 에 만들어 J29 까지 끌어 채우기)
A5: 번호 | B5: 넣을 칸 | C5: 무엇을 구하나 | D5: 정답 수식 | E5: 정답값 | F5: 왜 그런가 · 자주 하는 실수
A6: 1 | B6: 생산일보 J5 | C6: 달성률(%) — 생산수량÷계획수량×100, 소수 첫째 자리 | D6: =ROUND(F5/E5*100,1) | E6: =생산일보!AB5
A7: 2 | B7: 생산일보 K5 | C7: 판정 — 계획 이상이면 달성 | D7: =IF(F5>=E5,"달성","미달") | E7: =생산일보!AC5
A8: 3 | B8: 생산일보 L5 | C8: 불량률(%) — 불량수÷생산수량×100, 소수 둘째 자리 | D8: =ROUND(G5/F5*100,2) | E8: =생산일보!AD5
A9: 4 | B9: 생산일보 M5 | C9: 단가 — 단가표에서 찾아오기 | D9: =VLOOKUP(C5,$P$5:$R$8,3,FALSE) | E9: =생산일보!AE5
A10: 5 | B10: 생산일보 N5 | C10: 생산금액 — 생산수량×단가 | D10: =F5*M5 | E10: =생산일보!AF5
A12: 집계 문제 39개
A13: 번호 | B13: 넣을 칸 | C13: 무엇을 구하나 | D13: 정답 수식 | E13: 정답값 | F13: 왜 그런가 · 자주 하는 실수
A14: 1 | B14: 생산일보 F37 | C14: 생산수량[F5]이 계획수량[E5] 이상이면 "달성", 아니면 "미달" 이라고 나오게 하시오. | D14: =IF(F5>=E5,"달성","미달") | E14: ='생산일보'!AB37 | F14: F5(512) 가 E5(500) 보다 크므로 달성. 큰따옴표를 빠뜨리면 #NAME? 가 납니다
A15: 2 | B15: 생산일보 F38 | C15: 생산수량[F5]이 500 이상이면서 불량수[G5]가 10 미만이면 "우수", 아니면 "보통". | D15: =IF(AND(F5>=500,G5<10),"우수","보통") | E15: ='생산일보'!AB38 | F15: AND 는 둘 다 참일 때만 참. 조건을 그냥 나란히 쓰면 안 되고 AND( ) 로 묶습니다
A16: 3 | B16: 생산일보 F39 | C16: 라인[B5]이 "A" 이거나 작업시간[H5]이 8 이상이면 "확인", 아니면 빈칸. | D16: =IF(OR(B5="A",H5>=8),"확인","") | E16: ='생산일보'!AB39 | F16: 빈칸은 큰따옴표 두 개("")를 붙여 씁니다. 그냥 비워 두면 0 이 나옵니다
A17: 4 | B17: 생산일보 F40 | C17: 불량수[G5]를 생산수량[F5]으로 나누되, 오류가 나면 "-" 가 나오게 하시오. | D17: =IFERROR(G5/F5,"-") | E17: ='생산일보'!AB40 | F17: 생산수량이 0 인 날 #DIV/0! 이 뜨는 것을 막아 줍니다
A18: 5 | B18: 생산일보 F42 | C18: 3월~4월 전체 생산수량[F5:F29] 의 합계. | D18: =SUM(F5:F29) | E18: ='생산일보'!AB42 | F18: 범위는 드래그로 잡아도 되고 F5:F29 라고 쳐도 됩니다
A19: 6 | B19: 생산일보 F43 | C19: 전체 생산수량[F5:F29] 의 평균을 정수로 반올림해서. | D19: =ROUND(AVERAGE(F5:F29),0) | E19: ='생산일보'!AB43 | F19: ROUND(값, 0) 이 정수 자리. 1 이면 소수 첫째 자리, -1 이면 십의 자리
A20: 7 | B20: 생산일보 F44 | C20: 하루 최대 생산수량[F5:F29]. | D20: =MAX(F5:F29) | E20: ='생산일보'!AB44 | F20: 가장 큰 값 하나를 뽑습니다
A21: 8 | B21: 생산일보 F45 | C21: 하루 최소 불량수[G5:G29]. | D21: =MIN(G5:G29) | E21: ='생산일보'!AB45
A22: 9 | B22: 생산일보 F46 | C22: 생산수량이 세 번째로 많은 날의 수량. | D22: =LARGE(F5:F29,3) | E22: ='생산일보'!AB46 | F22: LARGE(범위,1) 은 MAX 와 같습니다
A23: 10 | B23: 생산일보 F47 | C23: 불량수가 두 번째로 적은 날의 불량수. | D23: =SMALL(G5:G29,2) | E23: ='생산일보'!AB47 | F23: SMALL(범위,1) 은 MIN 과 같습니다
A24: 11 | B24: 생산일보 F48 | C24: 생산수량[F5:F29] 의 중앙값(가운데 값). | D24: =MEDIAN(F5:F29) | E24: ='생산일보'!AB48 | F24: 평균과 달리 크게 벗어난 값에 덜 흔들립니다
A25: 12 | B25: 생산일보 F49 | C25: 3월 2일 생산수량[F5]은 전체에서 몇 등인가? (큰 값이 1등) | D25: =RANK.EQ(F5,$F$5:$F$29) | E25: ='생산일보'!AB49 | F25: 아래로 끌어 채울 것을 생각해 범위는 반드시 $F$5:$F$29 로 고정합니다
A26: 13 | B26: 생산일보 F51 | C26: 라인[B5:B29] 에 글자가 적힌 칸의 개수 = 기록된 날 수. | D26: =COUNTA(B5:B29) | E26: ='생산일보'!AB51 | F26: COUNT 는 숫자만 셉니다. 글자를 세려면 COUNTA
A27: 14 | B27: 생산일보 F52 | C27: 작업시간[H5:H29] 중 숫자가 들어 있는 칸의 개수. | D27: =COUNT(H5:H29) | E27: ='생산일보'!AB52
A28: 15 | B28: 생산일보 F53 | C28: 비고[I5:I29] 중 비어 있는 칸의 개수. | D28: =COUNTBLANK(I5:I29) | E28: ='생산일보'!AB53 | F28: 아무것도 안 적힌 날이 며칠인지 셉니다
A29: 16 | B29: 생산일보 F54 | C29: 불량수[G5:G29] 가 10 이상인 날의 수. | D29: =COUNTIF(G5:G29,">=10") | E29: ='생산일보'!AB54 | F29: >= 와 숫자를 함께 큰따옴표로 묶습니다. COUNTIF(G5:G29,>=10) 은 오류
A30: 17 | B30: 생산일보 F56 | C30: A라인의 생산수량 합계. (라인은 B5:B29, 생산수량은 F5:F29) | D30: =SUMIF($B$5:$B$29,"A",$F$5:$F$29) | E30: ='생산일보'!AB56 | F30: 범위 두 개의 크기가 같아야 합니다. 조건 "A" 는 큰따옴표
A31: 18 | B31: 생산일보 F57 | C31: A라인의 평균 불량수를 소수 둘째 자리까지. | D31: =ROUND(AVERAGEIF($B$5:$B$29,"A",$G$5:$G$29),2) | E31: ='생산일보'!AB57 | F31: AVERAGEIF 는 조건에 맞는 것만 평균 냅니다
A32: 19 | B32: 생산일보 F58 | C32: 생산수량[F5:F29] 이 500 이상인 날의 불량수 합계. | D32: =SUMIF($F$5:$F$29,">=500",$G$5:$G$29) | E32: ='생산일보'!AB58 | F32: 조건은 생산수량에서 보고, 더하는 것은 불량수입니다
A33: 20 | B33: 생산일보 F59 | C33: 제품명[D5:D29] 이 "베어링유닛" 인 날의 생산수량 합계. | D33: =SUMIF($D$5:$D$29,"베어링유닛",$F$5:$F$29) | E33: ='생산일보'!AB59 | F33: 조건 칸(예: D5)을 가리켜 =SUMIF($D$5:$D$29,D5,$F$5:$F$29) 라고 해도 됩니다
A34: 21 | B34: 생산일보 F60 | C34: B라인이 나온 날의 수. | D34: =COUNTIF(B5:B29,"B") | E34: ='생산일보'!AB60
A35: 22 | B35: 생산일보 F62 | C35: 평균 생산수량을 십의 자리까지 올림. (예: 412 → 420) | D35: =ROUNDUP(AVERAGE(F5:F29),-1) | E35: ='생산일보'!AB62 | F35: -1 은 십의 자리, -2 는 백의 자리까지 맞춥니다
A36: 23 | B36: 생산일보 F63 | C36: 총 작업시간[H5:H29] 의 합계에서 소수점을 버린 값. | D36: =ROUNDDOWN(SUM(H5:H29),0) | E36: ='생산일보'!AB63 | F36: ROUNDDOWN 은 무조건 버림, ROUND 는 반올림입니다
A37: 24 | B37: 생산일보 F64 | C37: 총 생산수량을 500 으로 나눈 나머지. (500개들이 상자에 담고 남는 수) | D37: =MOD(SUM(F5:F29),500) | E37: ='생산일보'!AB64 | F37: MOD 는 나머지, INT 는 몫입니다
A38: 25 | B38: 생산일보 F65 | C38: 총 생산수량을 500 으로 나눈 몫. (상자 개수) | D38: =INT(SUM(F5:F29)/500) | E38: ='생산일보'!AB65 | F38: INT 는 음수에서는 더 작은 쪽으로 갑니다(-2.3 → -3)
A39: 26 | B39: 생산일보 F67 | C39: 제품코드[C5] 의 앞 2글자. (품목 구분) | D39: =LEFT(C5,2) | E39: ='생산일보'!AB67 | F39: BR-01 → BR
A40: 27 | B40: 생산일보 F68 | C40: 제품코드[C5] 의 뒤 2글자. (일련번호) | D40: =RIGHT(C5,2) | E40: ='생산일보'!AB68 | F40: BR-01 → 01
A41: 28 | B41: 생산일보 F69 | C41: 제품코드[C5] 의 4번째 글자부터 2글자. | D41: =MID(C5,4,2) | E41: ='생산일보'!AB69 | F41: B(1) R(2) -(3) 0(4) 1(5) 이므로 4번째부터 2글자 = 01
A42: 29 | B42: 생산일보 F70 | C42: 제품코드[C5] 가 모두 몇 글자인가. | D42: =LEN(C5) | E42: ='생산일보'!AB70 | F42: 붙임표(-)도 한 글자로 셉니다
...
