Workbook

Sheet 읽어보기
B2: 2급 실기 ③ 분석작업 — 설비 점검 이력
B4: 부분합 · 피벗 테이블 · 목표값 찾기 · 시나리오 · 정렬 · 통합 을 연습합니다. 자료는 60건입니다.
B6: 시트 안내
B7: 점검이력 — 60건의 설비 점검 기록 (부분합·피벗·정렬용) + 계산 문제 6개
B8: 원가모형 — 목표값 찾기와 시나리오를 걸어 볼 작은 계산 모형
B9: 미션 — 해야 할 일 12가지 체크리스트
B10: 따라하기 — 12가지를 1단계·2단계… 로 풀어 쓴 것 (이것이 정답입니다)
B12: 꼭 기억할 것
B13: 부분합은 반드시 '그 기준으로 먼저 정렬' 한 다음에 넣습니다. 정렬을 안 하면 같은 공정이 흩어집니다.
B14: 피벗 테이블은 원본 표 안에 셀 하나만 클릭해 두고 삽입 → 피벗 테이블.
B15: 목표값 찾기는 '답을 정해 놓고 입력값을 거꾸로 찾는' 기능입니다. 값을 바꿀 셀은 반드시 숫자가 든 칸이어야 합니다.

Sheet 점검이력
A3: 점검일 | B3: 설비명 | C3: 공정 | D3: 점검구분 | E3: 점검자 | F3: 이상건수 | G3: 수리비용 | H3: 정지시간(분)
A4: 46083 | B4: CNC-01 | C4: 가공 | D4: 정기 | E4: 김현수 | F4: 1 | G4: 35000 | H4: 25
A5: 46083 | B5: CNC-02 | C5: 가공 | D5: 정기 | E5: 박지훈 | F5: 0 | G5: 0 | H5: 0
A6: 46084 | B6: MCT-01 | C6: 가공 | D6: 수시 | E6: 이서연 | F6: 0 | G6: 0 | H6: 0
A7: 46084 | B7: ROB-01 | C7: 조립 | D7: 정기 | E7: 최민재 | F7: 1 | G7: 120000 | H7: 40
A8: 46085 | B8: ROB-02 | C8: 조립 | D8: 정기 | E8: 김현수 | F8: 1 | G8: 62000 | H8: 40
A9: 46085 | B9: CNV-01 | C9: 조립 | D9: 수시 | E9: 박지훈 | F9: 0 | G9: 0 | H9: 0
A10: 46086 | B10: VIS-01 | C10: 검사 | D10: 정기 | E10: 이서연 | F10: 3 | G10: 186000 | H10: 45
A11: 46086 | B11: VIS-02 | C11: 검사 | D11: 정기 | E11: 최민재 | F11: 4 | G11: 192000 | H11: 60
A12: 46087 | B12: PKG-01 | C12: 포장 | D12: 수시 | E12: 김현수 | F12: 1 | G12: 120000 | H12: 40
A13: 46087 | B13: PKG-02 | C13: 포장 | D13: 정기 | E13: 박지훈 | F13: 5 | G13: 240000 | H13: 75
A14: 46088 | B14: CNC-01 | C14: 가공 | D14: 정기 | E14: 이서연 | F14: 4 | G14: 140000 | H14: 160
A15: 46088 | B15: CNC-02 | C15: 가공 | D15: 수시 | E15: 최민재 | F15: 1 | G15: 120000 | H15: 60
... A63: 46112 | B63: PKG-02 | C63: 포장 | D63: 수시 | E63: 최민재 | F63: 0 | G63: 0 | H63: 0
A65: 60건입니다. 부분합을 넣기 전에 반드시 [공정] 기준으로 정렬하세요.
A67: ■ 계산 문제 6개
A68: 번호 ▶ 넣을 칸 | B68: 문제 — 무엇을 구하나 | E68: 답 | F68: 채점 | G68: 힌트
A69: 표를 읽는 연습 — ▶ 표시된 칸(E열)에
A70: 1 ▶E70 | B70: 전체 수리비용[G4:G63] 의 합계. | E70: 0 | F70: =IF(NOT(_xlfn.ISFORMULA(E70)),"↖ 0 지우고 수식",IF(IFERROR(ROUND(E70,4)=ROUND(AB70,4),E70=AB70),"✔ 맞음","✘ 다시")) | G70: SUM | AB70: =SUM(G4:G63)
A71: 2 ▶E71 | B71: '가공' 공정의 수리비용 합계. | E71: 0 | F71: =IF(NOT(_xlfn.ISFORMULA(E71)),"↖ 0 지우고 수식",IF(IFERROR(ROUND(E71,4)=ROUND(AB71,4),E71=AB71),"✔ 맞음","✘ 다시")) | G71: SUMIF · 공정은 C열 | AB71: =SUMIF($C$4:$C$63,"가공",$G$4:$G$63)
A72: 3 ▶E72 | B72: 이상건수가 0 인 점검 건수. (이상 없음) | E72: 0 | F72: =IF(NOT(_xlfn.ISFORMULA(E72)),"↖ 0 지우고 수식",IF(IFERROR(ROUND(E72,4)=ROUND(AB72,4),E72=AB72),"✔ 맞음","✘ 다시")) | G72: COUNTIF(범위, 0) | AB72: =COUNTIF(F4:F63,0)
A73: 4 ▶E73 | B73: '수시' 점검의 평균 정지시간을 소수 첫째 자리까지. | E73: 0 | F73: =IF(NOT(_xlfn.ISFORMULA(E73)),"↖ 0 지우고 수식",IF(IFERROR(ROUND(E73,4)=ROUND(AB73,4),E73=AB73),"✔ 맞음","✘ 다시")) | G73: AVERAGEIF 를 ROUND 로 감싸기 | AB73: =ROUND(AVERAGEIF($D$4:$D$63,"수시",$H$4:$H$63),1)
A74: 5 ▶E74 | B74: 가장 큰 수리비용. | E74: 0 | F74: =IF(NOT(_xlfn.ISFORMULA(E74)),"↖ 0 지우고 수식",IF(IFERROR(ROUND(E74,4)=ROUND(AB74,4),E74=AB74),"✔ 맞음","✘ 다시")) | G74: MAX | AB74: =MAX(G4:G63)
A75: 6 ▶E75 | B75: 수리비용이 두 번째로 큰 값. | E75: 0 | F75: =IF(NOT(_xlfn.ISFORMULA(E75)),"↖ 0 지우고 수식",IF(IFERROR(ROUND(E75,4)=ROUND(AB75,4),E75=AB75),"✔ 맞음","✘ 다시")) | G75: LARGE(범위, 2) | AB75: =LARGE(G4:G63,2)

Sheet 원가모형
A1: 목표값 찾기 · 시나리오용 원가 모형
A2: 파란 칸은 직접 넣은 숫자, 초록 칸은 수식입니다. 초록 칸을 클릭해 안을 확인하세요.
A4: 월 생산수량(개) | B4: 5000
A5: 개당 재료비(원) | B5: 3200
A6: 개당 가공비(원) | B6: 1450
A7: 월 고정비(원) | B7: 12000000
A8: 불량률 | B8: 0.03
A10: 양품 수량 | B10: =ROUND(B4*(1-B8),0)
A11: 총 변동비 | B11: =B4*(B5+B6)
A12: 총 원가 | B12: =B11+B7
A13: 양품 1개당 원가 | B13: =ROUND(B12/B10,0)
A15: → 목표값 찾기 : [B13] 이 6,000 이 되려면 [B4] 는 몇 개?
A16: → 시나리오 : [B8] 이 1% / 3% / 6% 일 때 [B13] 이 얼마가 되는지 요약표로
A17: → 목표값 찾기를 하면 B4 값이 바뀝니다. 해 보기 전 원래 값 5000 을 적어 두세요.

Sheet 미션
A1: 2급 ③ 분석작업 미션 12가지
A2: 부분합·피벗은 '어느 메뉴에서 무엇을 고르는지' 가 전부입니다. [따라하기] 시트를 보며 한 번씩 해 보세요.
A4: 번호 | B4: 미션 — 무엇을 하는가 | C4: 다 함 | D4: 어디서 (메뉴)
A5: 1 | B5: [점검이력] 공정(C열) 기준 오름차순 정렬. | C5: □ | D5: 데이터 → 정렬
A6: 2 | B6: [점검이력] 공정별 이상건수·수리비용 합계 부분합. | C6: □ | D6: 데이터 → 부분합
A7: 3 | B7: [점검이력] 공정별 평균 정지시간 부분합을 하나 더 덧붙이기. | C7: □ | D7: '새로운 값으로 대치' 해제
A8: 4 | B8: [점검이력] 부분합 화면을 2단계만 보이게 접기. | C8: □ | D8: 왼쪽 1 2 3 단추
A9: 5 | B9: [점검이력] 부분합을 모두 없애고 원래 표로 되돌리기. | C9: □ | D9: 데이터 → 부분합 → 모두 제거
A10: 6 | B10: [점검이력] 새 시트에 피벗 — 행 공정, 열 점검구분, 값 수리비용 합계. | C10: □ | D10: 삽입 → 피벗 테이블
A11: 7 | B11: [점검이력] 그 피벗에 값 하나 더 — 이상건수 '평균'. | C11: □ | D11: 값 필드 설정
A12: 8 | B12: [점검이력] 피벗 숫자에 천 단위 쉼표 넣기. | C12: □ | D12: 값 필드 설정 → 표시 형식
A13: 9 | B13: [점검이력] 공정 오름차순 + 같은 공정 안에서 수리비용 내림차순 정렬. | C13: □ | D13: 데이터 → 정렬 → 기준 추가
A14: 10 | B14: [점검이력] 점검자가 '김현수' 인 줄만 보이게 자동 필터. | C14: □ | D14: 데이터 → 필터
A15: 11 | B15: [원가모형] [B13] 이 6,000 이 되려면 [B4] 는 몇 개인지 구하기. | C15: □ | D15: 데이터 → 가상 분석 → 목표값 찾기
A16: 12 | B16: [원가모형] [B8] 이 1%·3%·6% 일 때 [B13] 을 시나리오 요약으로. | C16: □ | D16: 데이터 → 가상 분석 → 시나리오 관리자

Sheet 따라하기
A1: 2급 ③ 분석작업 — 단계별로 따라 하기
A2: 미션 12가지를 순서대로 풀어 쓴 것입니다. 부분합 → 피벗 순서로 할 때는 부분합을 먼저 지워야 합니다.
A4: 미션 1 · 정렬 먼저 하기
A5: 어디서 | B5: [점검이력] 데이터 탭
A6: 1단계 | B6: C열(공정)의 아무 칸이나 하나 클릭합니다. | C6: 범위를 통째로 잡을 필요 없습니다
A7: 2단계 | B7: 데이터 → 정렬 및 필터의 [ㄱ→ㅎ] 단추를 누릅니다. | C7: 오름차순입니다
A8: 3단계 | B8: 가공·검사·조립·포장 끼리 모였는지 봅니다. | C8: ★ 이걸 안 하면 부분합이 같은 공정을 여러 번 만듭니다
A9: 확인 | B9: 이렇게 되면 성공 — 같은 공정끼리 붙어 있습니다
A11: 미션 2 · 공정별 부분합 넣기
A12: 어디서 | B12: [점검이력] 데이터 → 부분합
A13: 1단계 | B13: 표 안의 아무 칸을 클릭하고 데이터 → 부분합. | C13: 개요 그룹에 있습니다
A14: 2단계 | B14: [그룹화할 항목] 을 공정 으로 고릅니다. | C14: 방금 정렬한 기준과 같아야 합니다
A15: 3단계 | B15: [사용할 함수] 를 합계 로 둡니다.
A16: 4단계 | B16: [부분합 계산 항목] 에서 이상건수 와 수리비용 에만 체크하고 확인. | C16: 다른 체크는 모두 풉니다
A17: 확인 | B17: 이렇게 되면 성공 — 공정이 바뀌는 자리마다 '가공 요약' 같은 줄이 생기고 맨 아래에 총합계가 붙습니다
A19: 미션 3 · 부분합 하나 더 덧붙이기
A20: 어디서 | B20: [점검이력] 데이터 → 부분합
A21: 1단계 | B21: 다시 데이터 → 부분합 을 누릅니다.
A22: 2단계 | B22: [사용할 함수] 를 평균 으로 바꿉니다.
A23: 3단계 | B23: [부분합 계산 항목] 은 정지시간(분) 에만 체크.
A24: 4단계 | B24: ★ [새로운 값으로 대치] 체크를 반드시 해제하고 확인. | C24: 이걸 켜 두면 앞의 합계가 사라집니다
A25: 확인 | B25: 이렇게 되면 성공 — 한 공정마다 '요약' 줄이 두 개(합계·평균) 생깁니다
A27: 미션 4 · 부분합 접었다 펴기 · 없애기
A28: 어디서 | B28: [점검이력] 화면 왼쪽 1 2 3 단추
A29: 1단계 | B29: 화면 왼쪽 끝 위의 2 를 누릅니다. | C29: 요약 줄만 남고 자세한 줄이 접힙니다
A30: 2단계 | B30: 3 을 누르면 다시 다 보입니다. | C30: 1 은 총합계만
A31: 3단계 | B31: 없앨 때는 데이터 → 부분합 → [모두 제거]. | C31: 삭제 키로 지우면 안 됩니다
A32: 4단계 | B32: 표가 원래대로 돌아왔는지 봅니다. | C32: 다음 미션(피벗)을 하려면 부분합을 지워야 합니다
A33: 확인 | B33: 이렇게 되면 성공 — 표가 60줄 원래 모습으로 돌아옵니다
A35: 미션 5 · 피벗 테이블 만들기
A36: 어디서 | B36: [점검이력] 삽입 → 피벗 테이블
A37: 1단계 | B37: 표 안의 아무 칸을 클릭하고 삽입 → 피벗 테이블 → 확인. | C37: 범위는 저절로 잡힙니다. 새 워크시트에 만듭니다
A38: 2단계 | B38: 오른쪽 필드 목록에서 공정 을 [행] 으로 끌어 놓습니다.
A39: 3단계 | B39: 점검구분 을 [열] 로 끌어 놓습니다.
A40: 4단계 | B40: 수리비용 을 [값] 으로 끌어 놓습니다. | C40: 숫자는 자동으로 '합계' 가 됩니다
A41: 확인 | B41: 이렇게 되면 성공 — 공정 × 정기/수시 의 수리비용 표가 만들어집니다
A43: 미션 6 · 피벗에 값 하나 더 · 쉼표 넣기
A44: 어디서 | B44: 피벗 테이블 안
A45: 1단계 | B45: 이상건수 를 [값] 으로 한 번 더 끌어 놓습니다.
A46: 2단계 | B46: [값] 칸의 '합계: 이상건수' 를 클릭 → 값 필드 설정.
...

Sheet 계산 문제 정답
A1: 2급 ③ 분석작업 — 계산 문제 정답
A2: 먼저 스스로 만들어 본 뒤에 펼쳐 보세요. [넣을 칸] 이 그 답을 적을 자리이고, [정답값] 은 제대로 넣었을 때 나와야 하는 값입니다.
A4: 표 아래 계산 문제 6개
A5: 번호 | B5: 넣을 칸 | C5: 무엇을 구하나 | D5: 정답 수식 | E5: 정답값 | F5: 왜 그런가 · 자주 하는 실수
A6: 1 | B6: 점검이력 E70 | C6: 전체 수리비용[G4:G63] 의 합계. | D6: =SUM(G4:G63) | E6: ='점검이력'!AB70
A7: 2 | B7: 점검이력 E71 | C7: '가공' 공정의 수리비용 합계. | D7: =SUMIF($C$4:$C$63,"가공",$G$4:$G$63) | E7: ='점검이력'!AB71
A8: 3 | B8: 점검이력 E72 | C8: 이상건수가 0 인 점검 건수. (이상 없음) | D8: =COUNTIF(F4:F63,0) | E8: ='점검이력'!AB72
A9: 4 | B9: 점검이력 E73 | C9: '수시' 점검의 평균 정지시간을 소수 첫째 자리까지. | D9: =ROUND(AVERAGEIF($D$4:$D$63,"수시",$H$4:$H$63),1) | E9: ='점검이력'!AB73
A10: 5 | B10: 점검이력 E74 | C10: 가장 큰 수리비용. | D10: =MAX(G4:G63) | E10: ='점검이력'!AB74
A11: 6 | B11: 점검이력 E75 | C11: 수리비용이 두 번째로 큰 값. | D11: =LARGE(G4:G63,2) | E11: ='점검이력'!AB75
